Workbook

Sheet Pen trt 
A1: Pen | B1: Treatment
A2: 1 | B2: 1
A3: 2 | B3: 9
A4: 3 | B4: 17
A5: 4 | B5: 25
A6: 5 | B6: 28
A7: 6 | B7: 4
A8: 7 | B8: 12
A9: 8 | B9: 20
A10: 9 | B10: 32
A11: 10 | B11: 8
A12: 11 | B12: 16
A13: 12 | B13: 24
... A193: 192 | B193: 29

Sheet Egg Data
C1: 46238 | J1: 46239 | Q1: 46240 | X1: 46241 | AE1: 46242 | AL1: 46243 | AS1: 46244 | AZ1: 94W | BH1: 46245 | BO1: 46246 | BV1: 46247 | CC1: 46248 | CJ1: 46249 | CQ1: 46250 | CX1: 46251 | DE1: 95W | DM1: 46252 | DT1: 46253 | EA1: 46254 | EH1: 46255 | EO1: 46256 | EV1: 46257 | FC1: 46258 | FJ1: 96W | FR1: 46259 | FY1: 46260 | GF1: 46261 | GM1: 46262 | GT1: 46263 | HA1: 46264 | HH1: 46265 | HO1: 97W | HW1: 46266 | ID1: 46267 | IK1: 46268 | IR1: 46269 | IY1: 46270 | JF1: 46271 | JM1: 46272 | JT1: 98W | KB1: 46273 | KI1: 46274 | KP1: 46275 | KW1: 46276 | LD1: 46277 | LK1: 46278 | LR1: 46279 | LY1: 99W | MG1: 46280 | MN1: 46281 | MU1: 46282 | NB1: 46283 | NI1: 46284 | NP1: 46285 | NW1: 46286 | OD1: 100W | OL1: 46287 | OS1: 46288 | OZ1: 46289 | PG1: 46290 | PN1: 46291 | PU1: 46292 | QB1: 46293 | QI1: 101W | QQ1: 46294 | QX1: 46295 | RE1: 46296 | RL1: 46297 | RS1: 46298 | RZ1: 46299 | SG1: 46300 | SN1: 102W | SV1: 46301 | TC1: 46302 | TJ1: 46303 | TQ1: 46304 | TX1: 46305 | UE1: 46306 | UL1: 46307 | US1: 103W
C2: 94W | J2: 94W | Q2: 94W | X2: 94W | AE2: 94W | AL2: 94W | AS2: 94W | BH2: 95W | BO2: 95W | BV2: 95W | CC2: 95W | CJ2: 95W | CQ2: 95W | CX2: 95W | DM2: 96W | DT2: 96W | EA2: 96W | EH2: 96W | EO2: 96W | EV2: 96W | FC2: 96W | FR2: 97W | FY2: 97W | GF2: 97W | GM2: 97W | GT2: 97W | HA2: 97W | HH2: 97W | HW2: 98W | ID2: 98W | IK2: 98W | IR2: 98W | IY2: 98W | JF2: 98W | JM2: 98W | KB2: 99W | KI2: 99W | KP2: 99W | KW2: 99W | LD2: 99W | LK2: 99W | LR2: 99W | MG2: 100W | MN2: 100W | MU2: 100W | NB2: 100W | NI2: 100W | NP2: 100W | NW2: 100W | OL2: 101W | OS2: 101W | OZ2: 101W | PG2: 101W | PN2: 101W | PU2: 101W | QB2: 101W | QQ2: 102W | QX2: 102W | RE2: 102W | RL2: 102W | RS2: 102W | RZ2: 102W | SG2: 102W | SV2: 103W | TC2: 103W | TJ2: 103W | TQ2: 103W | TX2: 103W | UE2: 103W | UL2: 103W
A3: Pen Number | B3: Treatment Number | C3: Number of Eggs | D3: Weight | E3: Average Weight | F3: Non Layer | G3: Number of Rejects | H3: Reason | J3: Number of Eggs | K3: Weight | L3: Average Weight | M3: Non Layer | N3: Number of Rejects | O3: Reason | Q3: Number of Eggs | R3: Weight | S3: Average Weight | T3: Non Layer | U3: Number of Rejects | V3: Reason | X3: Number of Eggs | Y3: Weight | Z3: Average Weight | AA3: Non Layer | AB3: Number of Rejects | AC3: Reason | AE3: Number of Eggs | AF3: Weight | AG3: Average Weight | AH3: Non Layer | AI3: Number of Rejects | AJ3: Reason | AL3: Number of Eggs | AM3: Weight | AN3: Average Weight | AO3: Non Layer | AP3: Number of Rejects | AQ3: Reason | AS3: Number of Eggs | AT3: Weight | AU3: Average Weight | AV3: Non Layer | AW3: Number of Rejects | AX3: Reason | AZ3: Bird # | BA3: Number of Eggs | BB3: Ave eggs | BC3: Weight | BD3: Average Weight | BE3: Number of Rejects | BF3: %HDE_ | BH3: Number of Eggs | BI3: Weight | BJ3: Average Weight | BK3: Non Layer | BL3: Number of Rejects | BM3: Reason | BO3: Number of Eggs | BP3: Weight | BQ3: Average Weight | BR3: Non Layer | BS3: Number of Rejects | BT3: Reason | BV3: Number of Eggs | BW3: Weight | BX3: Average Weight | BY3: Non Layer | BZ3: Number of Rejects | CA3: Reason | CC3: Number of Eggs | CD3: Weight | CE3: Average Weight | CF3: Non Layer | CG3: Number of Rejects | CH3: Reason | CJ3: Number of Eggs | CK3: Weight | CL3: Average Weight | CM3: Non Layer | CN3: Number of Rejects | CO3: Reason | CQ3: Number of Eggs | CR3: Weight | CS3: Average Weight | CT3: Non Layer | CU3: Number of Rejects | CV3: Reason | CX3: Number of Eggs | CY3: Weight | CZ3: Average Weight | DA3: Non Layer | DB3: Number of Rejects | DC3: Reason | DE3: Bird # | DF3: Number of Eggs | DG3: Ave eggs | DH3: Weight | DI3: Average Weight | DJ3: Number of Rejects | DK3: %HDE_ | DM3: Number of Eggs | DN3: Weight | DO3: Average Weight | DP3: Non Layer | DQ3: Number of Rejects | DR3: Reason | DT3: Number of Eggs | DU3: Weight | DV3: Average Weight | DW3: Non Layer | DX3: Number of Rejects | DY3: Reason | EA3: Number of Eggs | EB3: Weight | EC3: Average Weight | ED3: Non Layer | EE3: Number of Rejects | EF3: Reason | EH3: Number of Eggs | EI3: Weight | EJ3: Average Weight | EK3: Non Layer | EL3: Number of Rejects | EM3: Reason | EO3: Number of Eggs | EP3: Weight | EQ3: Average Weight | ER3: Non Layer | ES3: Number of Rejects | ET3: Reason | EV3: Number of Eggs | EW3: Weight | EX3: Average Weight | EY3: Non Layer | EZ3: Number of Rejects | FA3: Reason | FC3: Number of Eggs | FD3: Weight | FE3: Average Weight | FF3: Non Layer | FG3: Number of Rejects | FH3: Reason | FJ3: Bird # | FK3: Number of Eggs | FL3: Ave eggs | FM3: Weight | FN3: Average Weight | FO3: Number of Rejects | FP3: %HDE_ | FR3: Number of Eggs | FS3: Weight | FT3: Average Weight | FU3: Non Layer | FV3: Number of Rejects | FW3: Reason | FY3: Number of Eggs | FZ3: Weight | GA3: Average Weight | GB3: Non Layer | GC3: Number of Rejects | GD3: Reason | GF3: Number of Eggs | GG3: Weight | GH3: Average Weight | GI3: Non Layer | GJ3: Number of Rejects | GK3: Reason | GM3: Number of Eggs | GN3: Weight | GO3: Average Weight | GP3: Non Layer | GQ3: Number of Rejects | GR3: Reason | GT3: Number of Eggs | GU3: Weight | GV3: Average Weight | GW3: Non Layer | GX3: Number of Rejects | GY3: Reason | HA3: Number of Eggs | HB3: Weight | HC3: Average Weight | HD3: Non Layer | HE3: Number of Rejects | HF3: Reason | HH3: Number of Eggs | HI3: Weight | HJ3: Average Weight | HK3: Non Layer | HL3: Number of Rejects | HM3: Reason | HO3: Bird # | HP3: Number of Eggs | HQ3: Ave eggs | HR3: Weight | HS3: Average Weight | HT3: Number of Rejects | HU3: %HDE_ | HW3: Number of Eggs | HX3: Weight | HY3: Average Weight | HZ3: Non Layer | IA3: Number of Rejects | IB3: Reason | ID3: Number of Eggs | IE3: Weight | IF3: Average Weight | IG3: Non Layer | IH3: Number of Rejects | II3: Reason | IK3: Number of Eggs | IL3: Weight | IM3: Average Weight | IN3: Non Layer | IO3: Number of Rejects | IP3: Reason | IR3: Number of Eggs | IS3: Weight | IT3: Average Weight | IU3: Non Layer | IV3: Number of Rejects | IW3: Reason | IY3: Number of Eggs | IZ3: Weight | JA3: Average Weight | JB3: Non Layer | JC3: Number of Rejects | JD3: Reason | JF3: Number of Eggs | JG3: Weight | JH3: Average Weight | JI3: Non Layer | JJ3: Number of Rejects | JK3: Reason | JM3: Number of Eggs | JN3: Weight | JO3: Average Weight | JP3: Non Layer | JQ3: Number of Rejects | JR3: Reason | JT3: Bird # | JU3: Number of Eggs | JV3: Ave eggs | JW3: Weight | JX3: Average Weight | JY3: Number of Rejects | JZ3: %HDE_ | KB3: Number of Eggs | KC3: Weight | KD3: Average Weight | KE3: Non Layer | KF3: Number of Rejects | KG3: Reason | KI3: Number of Eggs | KJ3: Weight | KK3: Average Weight | KL3: Non Layer | KM3: Number of Rejects | KN3: Reason | KP3: Number of Eggs | KQ3: Weight | KR3: Average Weight | KS3: Non Layer | KT3: Number of Rejects | KU3: Reason | KW3: Number of Eggs | KX3: Weight | KY3: Average Weight | KZ3: Non Layer | LA3: Number of Rejects | LB3: Reason | LD3: Number of Eggs | LE3: Weight | LF3: Average Weight | LG3: Non Layer | LH3: Number of Rejects | LI3: Reason | LK3: Number of Eggs | LL3: Weight | LM3: Average Weight | LN3: Non Layer | LO3: Number of Rejects | LP3: Reason | LR3: Number of Eggs | LS3: Weight | LT3: Average Weight | LU3: Non Layer | LV3: Number of Rejects | LW3: Reason | LY3: Bird # | LZ3: Number of Eggs | MA3: Ave eggs | MB3: Weight | MC3: Average Weight | MD3: Number of Rejects | ME3: %HDE_ | MG3: Number of Eggs | MH3: Weight | MI3: Average Weight | MJ3: Non Layer | MK3: Number of Rejects | ML3: Reason | MN3: Number of Eggs | MO3: Weight | MP3: Average Weight | MQ3: Non Layer | MR3: Number of Rejects | MS3: Reason | MU3: Number of Eggs | MV3: Weight | MW3: Average Weight | MX3: Non Layer | MY3: Number of Rejects | MZ3: Reason | NB3: Number of Eggs | NC3: Weight | ND3: Average Weight | NE3: Non Layer | NF3: Number of Rejects | NG3: Reason | NI3: Number of Eggs | NJ3: Weight | NK3: Average Weight | NL3: Non Layer | NM3: Number of Rejects | NN3: Reason | NP3: Number of Eggs | NQ3: Weight | NR3: Average Weight | NS3: Non Layer | NT3: Number of Rejects | NU3: Reason | NW3: Number of Eggs | NX3: Weight | NY3: Average Weight | NZ3: Non Layer | OA3: Number of Rejects | OB3: Reason | OD3: Bird # | OE3: Number of Eggs | OF3: Ave eggs | OG3: Weight | OH3: Average Weight | OI3: Number of Rejects | OJ3: %HDE_ | OL3: Number of Eggs | OM3: Weight | ON3: Average Weight | OO3: Non Layer | OP3: Number of Rejects | OQ3: Reason | OS3: Number of Eggs | OT3: Weight | OU3: Average Weight | OV3: Non Layer | OW3: Number of Rejects | OX3: Reason | OZ3: Number of Eggs | PA3: Weight | PB3: Average Weight | PC3: Non Layer | PD3: Number of Rejects | PE3: Reason | PG3: Number of Eggs | PH3: Weight | PI3: Average Weight | PJ3: Non Layer | PK3: Number of Rejects | PL3: Reason | PN3: Number of Eggs | PO3: Weight | PP3: Average Weight | PQ3: Non Layer | PR3: Number of Rejects | PS3: Reason | PU3: Number of Eggs | PV3: Weight | PW3: Average Weight | PX3: Non Layer | PY3: Number of Rejects | PZ3: Reason | QB3: Number of Eggs | QC3: Weight | QD3: Average Weight | QE3: Non Layer | QF3: Number of Rejects | QG3: Reason | QI3: Bird # | QJ3: Number of Eggs | QK3: Ave eggs | QL3: Weight | QM3: Average Weight | QN3: Number of Rejects | QO3: %HDE_ | QQ3: Number of Eggs | QR3: Weight | QS3: Average Weight | QT3: Non Layer | QU3: Number of Rejects | QV3: Reason | QX3: Number of Eggs | QY3: Weight | QZ3: Average Weight | RA3: Non Layer | RB3: Number of Rejects | RC3: Reason | RE3: Number of Eggs | RF3: Weight | RG3: Average Weight | RH3: Non Layer | RI3: Number of Rejects | RJ3: Reason | RL3: Number of Eggs | RM3: Weight | RN3: Average Weight | RO3: Non Layer | RP3: Number of Rejects | RQ3: Reason | RS3: Number of Eggs | RT3: Weight | RU3: Average Weight | RV3: Non Layer | RW3: Number of Rejects | RX3: Reason | RZ3: Number of Eggs | SA3: Weight | SB3: Average Weight | SC3: Non Layer | SD3: Number of Rejects | SE3: Reason | SG3: Number of Eggs | SH3: Weight | SI3: Average Weight | SJ3: Non Layer | SK3: Number of Rejects | SL3: Reason | SN3: Bird # | SO3: Number of Eggs | SP3: Ave eggs | SQ3: Weight | SR3: Average Weight | SS3: Number of Rejects | ST3: %HDE_ | SV3: Number of Eggs | SW3: Weight | SX3: Average Weight | SY3: Non Layer | SZ3: Number of Rejects | TA3: Reason | TC3: Number of Eggs | TD3: Weight | TE3: Average Weight | TF3: Non Layer | TG3: Number of Rejects | TH3: Reason | TJ3: Number of Eggs | TK3: Weight | TL3: Average Weight | TM3: Non Layer | TN3: Number of Rejects | TO3: Reason | TQ3: Number of Eggs | TR3: Weight | TS3: Average Weight | TT3: Non Layer | TU3: Number of Rejects | TV3: Reason | TX3: Number of Eggs | TY3: Weight | TZ3: Average Weight | UA3: Non Layer | UB3: Number of Rejects | UC3: Reason | UE3: Number of Eggs | UF3: Weight | UG3: Average Weight | UH3: Non Layer | UI3: Number of Rejects | UJ3: Reason | UL3: Number of Eggs | UM3: Weight | UN3: Average Weight | UO3: Non Layer | UP3: Number of Rejects | UQ3: Reason | US3: Bird # | UT3: Number of Eggs | UU3: Ave eggs | UV3: Weight | UW3: Average Weight | UX3: Number of Rejects | UY3: %HDE_
A4: 1 | B4: 1 | BA4: =C4+J4+Q4+X4+AE4+AL4+AS4 | BB4: =IFERROR(BA4/AZ4/7,"") | BC4: =D4+K4+R4+Y4+AF4+AM4+AT4 | BD4: =IFERROR(BC4/BA4,"") | BE4: =G4+N4+U4+AB4+AI4+AP4+AW4 | BF4: =IFERROR(BA4/AZ4/7,"") | DF4: =BH4+BO4+BV4+CC4+CJ4+CQ4+CX4 | DG4: =IFERROR(DF4/DE4/7,"") | DH4: =BI4+BP4+BW4+CD4+CK4+CR4+CY4 | DI4: =IFERROR(DH4/DF4,"") | DJ4: =BL4+BS4+BZ4+CG4+CN4+CU4+DB4 | DK4: =IFERROR(DF4/DE4/7,"") | FK4: =DM4+DT4+EA4+EH4+EO4+EV4+FC4 | FL4: =IFERROR(FK4/FJ4/7,"") | FM4: =DN4+DU4+EB4+EI4+EP4+EW4+FD4 | FN4: =IFERROR(FM4/FK4,"") | FO4: =DQ4+DX4+EE4+EL4+ES4+EZ4+FG4 | FP4: =IFERROR(FK4/FJ4/7,"") | HP4: =FR4+FY4+GF4+GM4+GT4+HA4+HH4 | HQ4: =IFERROR(HP4/HO4/7,"") | HR4: =FS4+FZ4+GG4+GN4+GU4+HB4+HI4 | HS4: =IFERROR(HR4/HP4,"") | HT4: =FV4+GC4+GJ4+GQ4+GX4+HE4+HL4 | HU4: =IFERROR(HP4/HO4/7,"") | JU4: =HW4+ID4+IK4+IR4+IY4+JF4+JM4 | JV4: =IFERROR(JU4/JT4/7,"") | JW4: =HX4+IE4+IL4+IS4+IZ4+JG4+JN4 | JX4: =IFERROR(JW4/JU4,"") | JY4: =IA4+IH4+IO4+IV4+JC4+JJ4+JQ4 | JZ4: =IFERROR(JU4/JT4/7,"") | LZ4: =KB4+KI4+KP4+KW4+LD4+LK4+LR4 | MA4: =IFERROR(LZ4/LY4/7,"") | MB4: =KC4+KJ4+KQ4+KX4+LE4+LL4+LS4 | MC4: =IFERROR(MB4/LZ4,"") | MD4: =KF4+KM4+KT4+LA4+LH4+LO4+LV4 | ME4: =IFERROR(LZ4/LY4/7,"") | OE4: =MG4+MN4+MU4+NB4+NI4+NP4+NW4 | OF4: =IFERROR(OE4/OD4/7,"") | OG4: =MH4+MO4+MV4+NC4+NJ4+NQ4+NX4 | OH4: =IFERROR(OG4/OE4,"") | OI4: =MK4+MR4+MY4+NF4+NM4+NT4+OA4 | OJ4: =IFERROR(OE4/OD4/7,"") | QJ4: =OL4+OS4+OZ4+PG4+PN4+PU4+QB4 | QK4: =IFERROR(QJ4/QI4/7,"") | QL4: =OM4+OT4+PA4+PH4+PO4+PV4+QC4 | QM4: =IFERROR(QL4/QJ4,"") | QN4: =OP4+OW4+PD4+PK4+PR4+PY4+QF4 | QO4: =IFERROR(QJ4/QI4/7,"") | SO4: =QQ4+QX4+RE4+RL4+RS4+RZ4+SG4 | SP4: =IFERROR(SO4/SN4/7,"") | SQ4: =QR4+QY4+RF4+RM4+RT4+SA4+SH4 | SR4: =IFERROR(SQ4/SO4,"") | SS4: =QU4+RB4+RI4+RP4+RW4+SD4+SK4 | ST4: =IFERROR(SO4/SN4/7,"") | UT4: =SV4+TC4+TJ4+TQ4+TX4+UE4+UL4 | UU4: =IFERROR(UT4/US4/7,"") | UV4: =SW4+TD4+TK4+TR4+TY4+UF4+UM4 | UW4: =IFERROR(UV4/UT4,"") | UX4: =SZ4+TG4+TN4+TU4+UB4+UI4+UP4 | UY4: =IFERROR(UT4/US4/7,"")
A5: 2 | B5: 9 | BA5: =C5+J5+Q5+X5+AE5+AL5+AS5 | BB5: =IFERROR(BA5/AZ5/7,"") | BC5: =D5+K5+R5+Y5+AF5+AM5+AT5 | BD5: =IFERROR(BC5/BA5,"") | BE5: =G5+N5+U5+AB5+AI5+AP5+AW5 | BF5: =IFERROR(BA5/AZ5/7,"") | DF5: =BH5+BO5+BV5+CC5+CJ5+CQ5+CX5 | DG5: =IFERROR(DF5/DE5/7,"") | DH5: =BI5+BP5+BW5+CD5+CK5+CR5+CY5 | DI5: =IFERROR(DH5/DF5,"") | DJ5: =BL5+BS5+BZ5+CG5+CN5+CU5+DB5 | DK5: =IFERROR(DF5/DE5/7,"") | FK5: =DM5+DT5+EA5+EH5+EO5+EV5+FC5 | FL5: =IFERROR(FK5/FJ5/7,"") | FM5: =DN5+DU5+EB5+EI5+EP5+EW5+FD5 | FN5: =IFERROR(FM5/FK5,"") | FO5: =DQ5+DX5+EE5+EL5+ES5+EZ5+FG5 | FP5: =IFERROR(FK5/FJ5/7,"") | HP5: =FR5+FY5+GF5+GM5+GT5+HA5+HH5 | HQ5: =IFERROR(HP5/HO5/7,"") | HR5: =FS5+FZ5+GG5+GN5+GU5+HB5+HI5 | HS5: =IFERROR(HR5/HP5,"") | HT5: =FV5+GC5+GJ5+GQ5+GX5+HE5+HL5 | HU5: =IFERROR(HP5/HO5/7,"") | JU5: =HW5+ID5+IK5+IR5+IY5+JF5+JM5 | JV5: =IFERROR(JU5/JT5/7,"") | JW5: =HX5+IE5+IL5+IS5+IZ5+JG5+JN5 | JX5: =IFERROR(JW5/JU5,"") | JY5: =IA5+IH5+IO5+IV5+JC5+JJ5+JQ5 | JZ5: =IFERROR(JU5/JT5/7,"") | LZ5: =KB5+KI5+KP5+KW5+LD5+LK5+LR5 | MA5: =IFERROR(LZ5/LY5/7,"") | MB5: =KC5+KJ5+KQ5+KX5+LE5+LL5+LS5 | MC5: =IFERROR(MB5/LZ5,"") | MD5: =KF5+KM5+KT5+LA5+LH5+LO5+LV5 | ME5: =IFERROR(LZ5/LY5/7,"") | OE5: =MG5+MN5+MU5+NB5+NI5+NP5+NW5 | OF5: =IFERROR(OE5/OD5/7,"") | OG5: =MH5+MO5+MV5+NC5+NJ5+NQ5+NX5 | OH5: =IFERROR(OG5/OE5,"") | OI5: =MK5+MR5+MY5+NF5+NM5+NT5+OA5 | OJ5: =IFERROR(OE5/OD5/7,"") | QJ5: =OL5+OS5+OZ5+PG5+PN5+PU5+QB5 | QK5: =IFERROR(QJ5/QI5/7,"") | QL5: =OM5+OT5+PA5+PH5+PO5+PV5+QC5 | QM5: =IFERROR(QL5/QJ5,"") | QN5: =OP5+OW5+PD5+PK5+PR5+PY5+QF5 | QO5: =IFERROR(QJ5/QI5/7,"") | SO5: =QQ5+QX5+RE5+RL5+RS5+RZ5+SG5 | SP5: =IFERROR(SO5/SN5/7,"") | SQ5: =QR5+QY5+RF5+RM5+RT5+SA5+SH5 | SR5: =IFERROR(SQ5/SO5,"") | SS5: =QU5+RB5+RI5+RP5+RW5+SD5+SK5 | ST5: =IFERROR(SO5/SN5/7,"") | UT5: =SV5+TC5+TJ5+TQ5+TX5+UE5+UL5 | UU5: =IFERROR(UT5/US5/7,"") | UV5: =SW5+TD5+TK5+TR5+TY5+UF5+UM5 | UW5: =IFERROR(UV5/UT5,"") | UX5: =SZ5+TG5+TN5+TU5+UB5+UI5+UP5 | UY5: =IFERROR(UT5/US5/7,"")
A6: 3 | B6: 17 | BA6: =C6+J6+Q6+X6+AE6+AL6+AS6 | BB6: =IFERROR(BA6/AZ6/7,"") | BC6: =D6+K6+R6+Y6+AF6+AM6+AT6 | BD6: =IFERROR(BC6/BA6,"") | BE6: =G6+N6+U6+AB6+AI6+AP6+AW6 | BF6: =IFERROR(BA6/AZ6/7,"") | DF6: =BH6+BO6+BV6+CC6+CJ6+CQ6+CX6 | DG6: =IFERROR(DF6/DE6/7,"") | DH6: =BI6+BP6+BW6+CD6+CK6+CR6+CY6 | DI6: =IFERROR(DH6/DF6,"") | DJ6: =BL6+BS6+BZ6+CG6+CN6+CU6+DB6 | DK6: =IFERROR(DF6/DE6/7,"") | FK6: =DM6+DT6+EA6+EH6+EO6+EV6+FC6 | FL6: =IFERROR(FK6/FJ6/7,"") | FM6: =DN6+DU6+EB6+EI6+EP6+EW6+FD6 | FN6: =IFERROR(FM6/FK6,"") | FO6: =DQ6+DX6+EE6+EL6+ES6+EZ6+FG6 | FP6: =IFERROR(FK6/FJ6/7,"") | HP6: =FR6+FY6+GF6+GM6+GT6+HA6+HH6 | HQ6: =IFERROR(HP6/HO6/7,"") | HR6: =FS6+FZ6+GG6+GN6+GU6+HB6+HI6 | HS6: =IFERROR(HR6/HP6,"") | HT6: =FV6+GC6+GJ6+GQ6+GX6+HE6+HL6 | HU6: =IFERROR(HP6/HO6/7,"") | JU6: =HW6+ID6+IK6+IR6+IY6+JF6+JM6 | JV6: =IFERROR(JU6/JT6/7,"") | JW6: =HX6+IE6+IL6+IS6+IZ6+JG6+JN6 | JX6: =IFERROR(JW6/JU6,"") | JY6: =IA6+IH6+IO6+IV6+JC6+JJ6+JQ6 | JZ6: =IFERROR(JU6/JT6/7,"") | LZ6: =KB6+KI6+KP6+KW6+LD6+LK6+LR6 | MA6: =IFERROR(LZ6/LY6/7,"") | MB6: =KC6+KJ6+KQ6+KX6+LE6+LL6+LS6 | MC6: =IFERROR(MB6/LZ6,"") | MD6: =KF6+KM6+KT6+LA6+LH6+LO6+LV6 | ME6: =IFERROR(LZ6/LY6/7,"") | OE6: =MG6+MN6+MU6+NB6+NI6+NP6+NW6 | OF6: =IFERROR(OE6/OD6/7,"") | OG6: =MH6+MO6+MV6+NC6+NJ6+NQ6+NX6 | OH6: =IFERROR(OG6/OE6,"") | OI6: =MK6+MR6+MY6+NF6+NM6+NT6+OA6 | OJ6: =IFERROR(OE6/OD6/7,"") | QJ6: =OL6+OS6+OZ6+PG6+PN6+PU6+QB6 | QK6: =IFERROR(QJ6/QI6/7,"") | QL6: =OM6+OT6+PA6+PH6+PO6+PV6+QC6 | QM6: =IFERROR(QL6/QJ6,"") | QN6: =OP6+OW6+PD6+PK6+PR6+PY6+QF6 | QO6: =IFERROR(QJ6/QI6/7,"") | SO6: =QQ6+QX6+RE6+RL6+RS6+RZ6+SG6 | SP6: =IFERROR(SO6/SN6/7,"") | SQ6: =QR6+QY6+RF6+RM6+RT6+SA6+SH6 | SR6: =IFERROR(SQ6/SO6,"") | SS6: =QU6+RB6+RI6+RP6+RW6+SD6+SK6 | ST6: =IFERROR(SO6/SN6/7,"") | UT6: =SV6+TC6+TJ6+TQ6+TX6+UE6+UL6 | UU6: =IFERROR(UT6/US6/7,"") | UV6: =SW6+TD6+TK6+TR6+TY6+UF6+UM6 | UW6: =IFERROR(UV6/UT6,"") | UX6: =SZ6+TG6+TN6+TU6+UB6+UI6+UP6 | UY6: =IFERROR(UT6/US6/7,"")
A7: 4 | B7: 25 | BA7: =C7+J7+Q7+X7+AE7+AL7+AS7 | BB7: =IFERROR(BA7/AZ7/7,"") | BC7: =D7+K7+R7+Y7+AF7+AM7+AT7 | BD7: =IFERROR(BC7/BA7,"") | BE7: =G7+N7+U7+AB7+AI7+AP7+AW7 | BF7: =IFERROR(BA7/AZ7/7,"") | DF7: =BH7+BO7+BV7+CC7+CJ7+CQ7+CX7 | DG7: =IFERROR(DF7/DE7/7,"") | DH7: =BI7+BP7+BW7+CD7+CK7+CR7+CY7 | DI7: =IFERROR(DH7/DF7,"") | DJ7: =BL7+BS7+BZ7+CG7+CN7+CU7+DB7 | DK7: =IFERROR(DF7/DE7/7,"") | FK7: =DM7+DT7+EA7+EH7+EO7+EV7+FC7 | FL7: =IFERROR(FK7/FJ7/7,"") | FM7: =DN7+DU7+EB7+EI7+EP7+EW7+FD7 | FN7: =IFERROR(FM7/FK7,"") | FO7: =DQ7+DX7+EE7+EL7+ES7+EZ7+FG7 | FP7: =IFERROR(FK7/FJ7/7,"") | HP7: =FR7+FY7+GF7+GM7+GT7+HA7+HH7 | HQ7: =IFERROR(HP7/HO7/7,"") | HR7: =FS7+FZ7+GG7+GN7+GU7+HB7+HI7 | HS7: =IFERROR(HR7/HP7,"") | HT7: =FV7+GC7+GJ7+GQ7+GX7+HE7+HL7 | HU7: =IFERROR(HP7/HO7/7,"") | JU7: =HW7+ID7+IK7+IR7+IY7+JF7+JM7 | JV7: =IFERROR(JU7/JT7/7,"") | JW7: =HX7+IE7+IL7+IS7+IZ7+JG7+JN7 | JX7: =IFERROR(JW7/JU7,"") | JY7: =IA7+IH7+IO7+IV7+JC7+JJ7+JQ7 | JZ7: =IFERROR(JU7/JT7/7,"") | LZ7: =KB7+KI7+KP7+KW7+LD7+LK7+LR7 | MA7: =IFERROR(LZ7/LY7/7,"") | MB7: =KC7+KJ7+KQ7+KX7+LE7+LL7+LS7 | MC7: =IFERROR(MB7/LZ7,"") | MD7: =KF7+KM7+KT7+LA7+LH7+LO7+LV7 | ME7: =IFERROR(LZ7/LY7/7,"") | OE7: =MG7+MN7+MU7+NB7+NI7+NP7+NW7 | OF7: =IFERROR(OE7/OD7/7,"") | OG7: =MH7+MO7+MV7+NC7+NJ7+NQ7+NX7 | OH7: =IFERROR(OG7/OE7,"") | OI7: =MK7+MR7+MY7+NF7+NM7+NT7+OA7 | OJ7: =IFERROR(OE7/OD7/7,"") | QJ7: =OL7+OS7+OZ7+PG7+PN7+PU7+QB7 | QK7: =IFERROR(QJ7/QI7/7,"") | QL7: =OM7+OT7+PA7+PH7+PO7+PV7+QC7 | QM7: =IFERROR(QL7/QJ7,"") | QN7: =OP7+OW7+PD7+PK7+PR7+PY7+QF7 | QO7: =IFERROR(QJ7/QI7/7,"") | SO7: =QQ7+QX7+RE7+RL7+RS7+RZ7+SG7 | SP7: =IFERROR(SO7/SN7/7,"") | SQ7: =QR7+QY7+RF7+RM7+RT7+SA7+SH7 | SR7: =IFERROR(SQ7/SO7,"") | SS7: =QU7+RB7+RI7+RP7+RW7+SD7+SK7 | ST7: =IFERROR(SO7/SN7/7,"") | UT7: =SV7+TC7+TJ7+TQ7+TX7+UE7+UL7 | UU7: =IFERROR(UT7/US7/7,"") | UV7: =SW7+TD7+TK7+TR7+TY7+UF7+UM7 | UW7: =IFERROR(UV7/UT7,"") | UX7: =SZ7+TG7+TN7+TU7+UB7+UI7+UP7 | UY7: =IFERROR(UT7/US7/7,"")
A8: 5 | B8: 28 | BA8: =C8+J8+Q8+X8+AE8+AL8+AS8 | BB8: =IFERROR(BA8/AZ8/7,"") | BC8: =D8+K8+R8+Y8+AF8+AM8+AT8 | BD8: =IFERROR(BC8/BA8,"") | BE8: =G8+N8+U8+AB8+AI8+AP8+AW8 | BF8: =IFERROR(BA8/AZ8/7,"") | DF8: =BH8+BO8+BV8+CC8+CJ8+CQ8+CX8 | DG8: =IFERROR(DF8/DE8/7,"") | DH8: =BI8+BP8+BW8+CD8+CK8+CR8+CY8 | DI8: =IFERROR(DH8/DF8,"") | DJ8: =BL8+BS8+BZ8+CG8+CN8+CU8+DB8 | DK8: =IFERROR(DF8/DE8/7,"") | FK8: =DM8+DT8+EA8+EH8+EO8+EV8+FC8 | FL8: =IFERROR(FK8/FJ8/7,"") | FM8: =DN8+DU8+EB8+EI8+EP8+EW8+FD8 | FN8: =IFERROR(FM8/FK8,"") | FO8: =DQ8+DX8+EE8+EL8+ES8+EZ8+FG8 | FP8: =IFERROR(FK8/FJ8/7,"") | HP8: =FR8+FY8+GF8+GM8+GT8+HA8+HH8 | HQ8: =IFERROR(HP8/HO8/7,"") | HR8: =FS8+FZ8+GG8+GN8+GU8+HB8+HI8 | HS8: =IFERROR(HR8/HP8,"") | HT8: =FV8+GC8+GJ8+GQ8+GX8+HE8+HL8 | HU8: =IFERROR(HP8/HO8/7,"") | JU8: =HW8+ID8+IK8+IR8+IY8+JF8+JM8 | JV8: =IFERROR(JU8/JT8/7,"") | JW8: =HX8+IE8+IL8+IS8+IZ8+JG8+JN8 | JX8: =IFERROR(JW8/JU8,"") | JY8: =IA8+IH8+IO8+IV8+JC8+JJ8+JQ8 | JZ8: =IFERROR(JU8/JT8/7,"") | LZ8: =KB8+KI8+KP8+KW8+LD8+LK8+LR8 | MA8: =IFERROR(LZ8/LY8/7,"") | MB8: =KC8+KJ8+KQ8+KX8+LE8+LL8+LS8 | MC8: =IFERROR(MB8/LZ8,"") | MD8: =KF8+KM8+KT8+LA8+LH8+LO8+LV8 | ME8: =IFERROR(LZ8/LY8/7,"") | OE8: =MG8+MN8+MU8+NB8+NI8+NP8+NW8 | OF8: =IFERROR(OE8/OD8/7,"") | OG8: =MH8+MO8+MV8+NC8+NJ8+NQ8+NX8 | OH8: =IFERROR(OG8/OE8,"") | OI8: =MK8+MR8+MY8+NF8+NM8+NT8+OA8 | OJ8: =IFERROR(OE8/OD8/7,"") | QJ8: =OL8+OS8+OZ8+PG8+PN8+PU8+QB8 | QK8: =IFERROR(QJ8/QI8/7,"") | QL8: =OM8+OT8+PA8+PH8+PO8+PV8+QC8 | QM8: =IFERROR(QL8/QJ8,"") | QN8: =OP8+OW8+PD8+PK8+PR8+PY8+QF8 | QO8: =IFERROR(QJ8/QI8/7,"") | SO8: =QQ8+QX8+RE8+RL8+RS8+RZ8+SG8 | SP8: =IFERROR(SO8/SN8/7,"") | SQ8: =QR8+QY8+RF8+RM8+RT8+SA8+SH8 | SR8: =IFERROR(SQ8/SO8,"") | SS8: =QU8+RB8+RI8+RP8+RW8+SD8+SK8 | ST8: =IFERROR(SO8/SN8/7,"") | UT8: =SV8+TC8+TJ8+TQ8+TX8+UE8+UL8 | UU8: =IFERROR(UT8/US8/7,"") | UV8: =SW8+TD8+TK8+TR8+TY8+UF8+UM8 | UW8: =IFERROR(UV8/UT8,"") | UX8: =SZ8+TG8+TN8+TU8+UB8+UI8+UP8 | UY8: =IFERROR(UT8/US8/7,"")
A9: 6 | B9: 4 | BA9: =C9+J9+Q9+X9+AE9+AL9+AS9 | BB9: =IFERROR(BA9/AZ9/7,"") | BC9: =D9+K9+R9+Y9+AF9+AM9+AT9 | BD9: =IFERROR(BC9/BA9,"") | BE9: =G9+N9+U9+AB9+AI9+AP9+AW9 | BF9: =IFERROR(BA9/AZ9/7,"") | DF9: =BH9+BO9+BV9+CC9+CJ9+CQ9+CX9 | DG9: =IFERROR(DF9/DE9/7,"") | DH9: =BI9+BP9+BW9+CD9+CK9+CR9+CY9 | DI9: =IFERROR(DH9/DF9,"") | DJ9: =BL9+BS9+BZ9+CG9+CN9+CU9+DB9 | DK9: =IFERROR(DF9/DE9/7,"") | FK9: =DM9+DT9+EA9+EH9+EO9+EV9+FC9 | FL9: =IFERROR(FK9/FJ9/7,"") | FM9: =DN9+DU9+EB9+EI9+EP9+EW9+FD9 | FN9: =IFERROR(FM9/FK9,"") | FO9: =DQ9+DX9+EE9+EL9+ES9+EZ9+FG9 | FP9: =IFERROR(FK9/FJ9/7,"") | HP9: =FR9+FY9+GF9+GM9+GT9+HA9+HH9 | HQ9: =IFERROR(HP9/HO9/7,"") | HR9: =FS9+FZ9+GG9+GN9+GU9+HB9+HI9 | HS9: =IFERROR(HR9/HP9,"") | HT9: =FV9+GC9+GJ9+GQ9+GX9+HE9+HL9 | HU9: =IFERROR(HP9/HO9/7,"") | JU9: =HW9+ID9+IK9+IR9+IY9+JF9+JM9 | JV9: =IFERROR(JU9/JT9/7,"") | JW9: =HX9+IE9+IL9+IS9+IZ9+JG9+JN9 | JX9: =IFERROR(JW9/JU9,"") | JY9: =IA9+IH9+IO9+IV9+JC9+JJ9+JQ9 | JZ9: =IFERROR(JU9/JT9/7,"") | LZ9: =KB9+KI9+KP9+KW9+LD9+LK9+LR9 | MA9: =IFERROR(LZ9/LY9/7,"") | MB9: =KC9+KJ9+KQ9+KX9+LE9+LL9+LS9 | MC9: =IFERROR(MB9/LZ9,"") | MD9: =KF9+KM9+KT9+LA9+LH9+LO9+LV9 | ME9: =IFERROR(LZ9/LY9/7,"") | OE9: =MG9+MN9+MU9+NB9+NI9+NP9+NW9 | OF9: =IFERROR(OE9/OD9/7,"") | OG9: =MH9+MO9+MV9+NC9+NJ9+NQ9+NX9 | OH9: =IFERROR(OG9/OE9,"") | OI9: =MK9+MR9+MY9+NF9+NM9+NT9+OA9 | OJ9: =IFERROR(OE9/OD9/7,"") | QJ9: =OL9+OS9+OZ9+PG9+PN9+PU9+QB9 | QK9: =IFERROR(QJ9/QI9/7,"") | QL9: =OM9+OT9+PA9+PH9+PO9+PV9+QC9 | QM9: =IFERROR(QL9/QJ9,"") | QN9: =OP9+OW9+PD9+PK9+PR9+PY9+QF9 | QO9: =IFERROR(QJ9/QI9/7,"") | SO9: =QQ9+QX9+RE9+RL9+RS9+RZ9+SG9 | SP9: =IFERROR(SO9/SN9/7,"") | SQ9: =QR9+QY9+RF9+RM9+RT9+SA9+SH9 | SR9: =IFERROR(SQ9/SO9,"") | SS9: =QU9+RB9+RI9+RP9+RW9+SD9+SK9 | ST9: =IFERROR(SO9/SN9/7,"") | UT9: =SV9+TC9+TJ9+TQ9+TX9+UE9+UL9 | UU9: =IFERROR(UT9/US9/7,"") | UV9: =SW9+TD9+TK9+TR9+TY9+UF9+UM9 | UW9: =IFERROR(UV9/UT9,"") | UX9: =SZ9+TG9+TN9+TU9+UB9+UI9+UP9 | UY9: =IFERROR(UT9/US9/7,"")
A10: 7 | B10: 12 | BA10: =C10+J10+Q10+X10+AE10+AL10+AS10 | BB10: =IFERROR(BA10/AZ10/7,"") | BC10: =D10+K10+R10+Y10+AF10+AM10+AT10 | BD10: =IFERROR(BC10/BA10,"") | BE10: =G10+N10+U10+AB10+AI10+AP10+AW10 | BF10: =IFERROR(BA10/AZ10/7,"") | DF10: =BH10+BO10+BV10+CC10+CJ10+CQ10+CX10 | DG10: =IFERROR(DF10/DE10/7,"") | DH10: =BI10+BP10+BW10+CD10+CK10+CR10+CY10 | DI10: =IFERROR(DH10/DF10,"") | DJ10: =BL10+BS10+BZ10+CG10+CN10+CU10+DB10 | DK10: =IFERROR(DF10/DE10/7,"") | FK10: =DM10+DT10+EA10+EH10+EO10+EV10+FC10 | FL10: =IFERROR(FK10/FJ10/7,"") | FM10: =DN10+DU10+EB10+EI10+EP10+EW10+FD10 | FN10: =IFERROR(FM10/FK10,"") | FO10: =DQ10+DX10+EE10+EL10+ES10+EZ10+FG10 | FP10: =IFERROR(FK10/FJ10/7,"") | HP10: =FR10+FY10+GF10+GM10+GT10+HA10+HH10 | HQ10: =IFERROR(HP10/HO10/7,"") | HR10: =FS10+FZ10+GG10+GN10+GU10+HB10+HI10 | HS10: =IFERROR(HR10/HP10,"") | HT10: =FV10+GC10+GJ10+GQ10+GX10+HE10+HL10 | HU10: =IFERROR(HP10/HO10/7,"") | JU10: =HW10+ID10+IK10+IR10+IY10+JF10+JM10 | JV10: =IFERROR(JU10/JT10/7,"") | JW10: =HX10+IE10+IL10+IS10+IZ10+JG10+JN10 | JX10: =IFERROR(JW10/JU10,"") | JY10: =IA10+IH10+IO10+IV10+JC10+JJ10+JQ10 | JZ10: =IFERROR(JU10/JT10/7,"") | LZ10: =KB10+KI10+KP10+KW10+LD10+LK10+LR10 | MA10: =IFERROR(LZ10/LY10/7,"") | MB10: =KC10+KJ10+KQ10+KX10+LE10+LL10+LS10 | MC10: =IFERROR(MB10/LZ10,"") | MD10: =KF10+KM10+KT10+LA10+LH10+LO10+LV10 | ME10: =IFERROR(LZ10/LY10/7,"") | OE10: =MG10+MN10+MU10+NB10+NI10+NP10+NW10 | OF10: =IFERROR(OE10/OD10/7,"") | OG10: =MH10+MO10+MV10+NC10+NJ10+NQ10+NX10 | OH10: =IFERROR(OG10/OE10,"") | OI10: =MK10+MR10+MY10+NF10+NM10+NT10+OA10 | OJ10: =IFERROR(OE10/OD10/7,"") | QJ10: =OL10+OS10+OZ10+PG10+PN10+PU10+QB10 | QK10: =IFERROR(QJ10/QI10/7,"") | QL10: =OM10+OT10+PA10+PH10+PO10+PV10+QC10 | QM10: =IFERROR(QL10/QJ10,"") | QN10: =OP10+OW10+PD10+PK10+PR10+PY10+QF10 | QO10: =IFERROR(QJ10/QI10/7,"") | SO10: =QQ10+QX10+RE10+RL10+RS10+RZ10+SG10 | SP10: =IFERROR(SO10/SN10/7,"") | SQ10: =QR10+QY10+RF10+RM10+RT10+SA10+SH10 | SR10: =IFERROR(SQ10/SO10,"") | SS10: =QU10+RB10+RI10+RP10+RW10+SD10+SK10 | ST10: =IFERROR(SO10/SN10/7,"") | UT10: =SV10+TC10+TJ10+TQ10+TX10+UE10+UL10 | UU10: =IFERROR(UT10/US10/7,"") | UV10: =SW10+TD10+TK10+TR10+TY10+UF10+UM10 | UW10: =IFERROR(UV10/UT10,"") | UX10: =SZ10+TG10+TN10+TU10+UB10+UI10+UP10 | UY10: =IFERROR(UT10/US10/7,"")
A11: 8 | B11: 20 | BA11: =C11+J11+Q11+X11+AE11+AL11+AS11 | BB11: =IFERROR(BA11/AZ11/7,"") | BC11: =D11+K11+R11+Y11+AF11+AM11+AT11 | BD11: =IFERROR(BC11/BA11,"") | BE11: =G11+N11+U11+AB11+AI11+AP11+AW11 | BF11: =IFERROR(BA11/AZ11/7,"") | DF11: =BH11+BO11+BV11+CC11+CJ11+CQ11+CX11 | DG11: =IFERROR(DF11/DE11/7,"") | DH11: =BI11+BP11+BW11+CD11+CK11+CR11+CY11 | DI11: =IFERROR(DH11/DF11,"") | DJ11: =BL11+BS11+BZ11+CG11+CN11+CU11+DB11 | DK11: =IFERROR(DF11/DE11/7,"") | FK11: =DM11+DT11+EA11+EH11+EO11+EV11+FC11 | FL11: =IFERROR(FK11/FJ11/7,"") | FM11: =DN11+DU11+EB11+EI11+EP11+EW11+FD11 | FN11: =IFERROR(FM11/FK11,"") | FO11: =DQ11+DX11+EE11+EL11+ES11+EZ11+FG11 | FP11: =IFERROR(FK11/FJ11/7,"") | HP11: =FR11+FY11+GF11+GM11+GT11+HA11+HH11 | HQ11: =IFERROR(HP11/HO11/7,"") | HR11: =FS11+FZ11+GG11+GN11+GU11+HB11+HI11 | HS11: =IFERROR(HR11/HP11,"") | HT11: =FV11+GC11+GJ11+GQ11+GX11+HE11+HL11 | HU11: =IFERROR(HP11/HO11/7,"") | JU11: =HW11+ID11+IK11+IR11+IY11+JF11+JM11 | JV11: =IFERROR(JU11/JT11/7,"") | JW11: =HX11+IE11+IL11+IS11+IZ11+JG11+JN11 | JX11: =IFERROR(JW11/JU11,"") | JY11: =IA11+IH11+IO11+IV11+JC11+JJ11+JQ11 | JZ11: =IFERROR(JU11/JT11/7,"") | LZ11: =KB11+KI11+KP11+KW11+LD11+LK11+LR11 | MA11: =IFERROR(LZ11/LY11/7,"") | MB11: =KC11+KJ11+KQ11+KX11+LE11+LL11+LS11 | MC11: =IFERROR(MB11/LZ11,"") | MD11: =KF11+KM11+KT11+LA11+LH11+LO11+LV11 | ME11: =IFERROR(LZ11/LY11/7,"") | OE11: =MG11+MN11+MU11+NB11+NI11+NP11+NW11 | OF11: =IFERROR(OE11/OD11/7,"") | OG11: =MH11+MO11+MV11+NC11+NJ11+NQ11+NX11 | OH11: =IFERROR(OG11/OE11,"") | OI11: =MK11+MR11+MY11+NF11+NM11+NT11+OA11 | OJ11: =IFERROR(OE11/OD11/7,"") | QJ11: =OL11+OS11+OZ11+PG11+PN11+PU11+QB11 | QK11: =IFERROR(QJ11/QI11/7,"") | QL11: =OM11+OT11+PA11+PH11+PO11+PV11+QC11 | QM11: =IFERROR(QL11/QJ11,"") | QN11: =OP11+OW11+PD11+PK11+PR11+PY11+QF11 | QO11: =IFERROR(QJ11/QI11/7,"") | SO11: =QQ11+QX11+RE11+RL11+RS11+RZ11+SG11 | SP11: =IFERROR(SO11/SN11/7,"") | SQ11: =QR11+QY11+RF11+RM11+RT11+SA11+SH11 | SR11: =IFERROR(SQ11/SO11,"") | SS11: =QU11+RB11+RI11+RP11+RW11+SD11+SK11 | ST11: =IFERROR(SO11/SN11/7,"") | UT11: =SV11+TC11+TJ11+TQ11+TX11+UE11+UL11 | UU11: =IFERROR(UT11/US11/7,"") | UV11: =SW11+TD11+TK11+TR11+TY11+UF11+UM11 | UW11: =IFERROR(UV11/UT11,"") | UX11: =SZ11+TG11+TN11+TU11+UB11+UI11+UP11 | UY11: =IFERROR(UT11/US11/7,"")
A12: 9 | B12: 32 | BA12: =C12+J12+Q12+X12+AE12+AL12+AS12 | BB12: =IFERROR(BA12/AZ12/7,"") | BC12: =D12+K12+R12+Y12+AF12+AM12+AT12 | BD12: =IFERROR(BC12/BA12,"") | BE12: =G12+N12+U12+AB12+AI12+AP12+AW12 | BF12: =IFERROR(BA12/AZ12/7,"") | DF12: =BH12+BO12+BV12+CC12+CJ12+CQ12+CX12 | DG12: =IFERROR(DF12/DE12/7,"") | DH12: =BI12+BP12+BW12+CD12+CK12+CR12+CY12 | DI12: =IFERROR(DH12/DF12,"") | DJ12: =BL12+BS12+BZ12+CG12+CN12+CU12+DB12 | DK12: =IFERROR(DF12/DE12/7,"") | FK12: =DM12+DT12+EA12+EH12+EO12+EV12+FC12 | FL12: =IFERROR(FK12/FJ12/7,"") | FM12: =DN12+DU12+EB12+EI12+EP12+EW12+FD12 | FN12: =IFERROR(FM12/FK12,"") | FO12: =DQ12+DX12+EE12+EL12+ES12+EZ12+FG12 | FP12: =IFERROR(FK12/FJ12/7,"") | HP12: =FR12+FY12+GF12+GM12+GT12+HA12+HH12 | HQ12: =IFERROR(HP12/HO12/7,"") | HR12: =FS12+FZ12+GG12+GN12+GU12+HB12+HI12 | HS12: =IFERROR(HR12/HP12,"") | HT12: =FV12+GC12+GJ12+GQ12+GX12+HE12+HL12 | HU12: =IFERROR(HP12/HO12/7,"") | JU12: =HW12+ID12+IK12+IR12+IY12+JF12+JM12 | JV12: =IFERROR(JU12/JT12/7,"") | JW12: =HX12+IE12+IL12+IS12+IZ12+JG12+JN12 | JX12: =IFERROR(JW12/JU12,"") | JY12: =IA12+IH12+IO12+IV12+JC12+JJ12+JQ12 | JZ12: =IFERROR(JU12/JT12/7,"") | LZ12: =KB12+KI12+KP12+KW12+LD12+LK12+LR12 | MA12: =IFERROR(LZ12/LY12/7,"") | MB12: =KC12+KJ12+KQ12+KX12+LE12+LL12+LS12 | MC12: =IFERROR(MB12/LZ12,"") | MD12: =KF12+KM12+KT12+LA12+LH12+LO12+LV12 | ME12: =IFERROR(LZ12/LY12/7,"") | OE12: =MG12+MN12+MU12+NB12+NI12+NP12+NW12 | OF12: =IFERROR(OE12/OD12/7,"") | OG12: =MH12+MO12+MV12+NC12+NJ12+NQ12+NX12 | OH12: =IFERROR(OG12/OE12,"") | OI12: =MK12+MR12+MY12+NF12+NM12+NT12+OA12 | OJ12: =IFERROR(OE12/OD12/7,"") | QJ12: =OL12+OS12+OZ12+PG12+PN12+PU12+QB12 | QK12: =IFERROR(QJ12/QI12/7,"") | QL12: =OM12+OT12+PA12+PH12+PO12+PV12+QC12 | QM12: =IFERROR(QL12/QJ12,"") | QN12: =OP12+OW12+PD12+PK12+PR12+PY12+QF12 | QO12: =IFERROR(QJ12/QI12/7,"") | SO12: =QQ12+QX12+RE12+RL12+RS12+RZ12+SG12 | SP12: =IFERROR(SO12/SN12/7,"") | SQ12: =QR12+QY12+RF12+RM12+RT12+SA12+SH12 | SR12: =IFERROR(SQ12/SO12,"") | SS12: =QU12+RB12+RI12+RP12+RW12+SD12+SK12 | ST12: =IFERROR(SO12/SN12/7,"") | UT12: =SV12+TC12+TJ12+TQ12+TX12+UE12+UL12 | UU12: =IFERROR(UT12/US12/7,"") | UV12: =SW12+TD12+TK12+TR12+TY12+UF12+UM12 | UW12: =IFERROR(UV12/UT12,"") | UX12: =SZ12+TG12+TN12+TU12+UB12+UI12+UP12 | UY12: =IFERROR(UT12/US12/7,"")
A13: 10 | B13: 8 | BA13: =C13+J13+Q13+X13+AE13+AL13+AS13 | BB13: =IFERROR(BA13/AZ13/7,"") | BC13: =D13+K13+R13+Y13+AF13+AM13+AT13 | BD13: =IFERROR(BC13/BA13,"") | BE13: =G13+N13+U13+AB13+AI13+AP13+AW13 | BF13: =IFERROR(BA13/AZ13/7,"") | DF13: =BH13+BO13+BV13+CC13+CJ13+CQ13+CX13 | DG13: =IFERROR(DF13/DE13/7,"") | DH13: =BI13+BP13+BW13+CD13+CK13+CR13+CY13 | DI13: =IFERROR(DH13/DF13,"") | DJ13: =BL13+BS13+BZ13+CG13+CN13+CU13+DB13 | DK13: =IFERROR(DF13/DE13/7,"") | FK13: =DM13+DT13+EA13+EH13+EO13+EV13+FC13 | FL13: =IFERROR(FK13/FJ13/7,"") | FM13: =DN13+DU13+EB13+EI13+EP13+EW13+FD13 | FN13: =IFERROR(FM13/FK13,"") | FO13: =DQ13+DX13+EE13+EL13+ES13+EZ13+FG13 | FP13: =IFERROR(FK13/FJ13/7,"") | HP13: =FR13+FY13+GF13+GM13+GT13+HA13+HH13 | HQ13: =IFERROR(HP13/HO13/7,"") | HR13: =FS13+FZ13+GG13+GN13+GU13+HB13+HI13 | HS13: =IFERROR(HR13/HP13,"") | HT13: =FV13+GC13+GJ13+GQ13+GX13+HE13+HL13 | HU13: =IFERROR(HP13/HO13/7,"") | JU13: =HW13+ID13+IK13+IR13+IY13+JF13+JM13 | JV13: =IFERROR(JU13/JT13/7,"") | JW13: =HX13+IE13+IL13+IS13+IZ13+JG13+JN13 | JX13: =IFERROR(JW13/JU13,"") | JY13: =IA13+IH13+IO13+IV13+JC13+JJ13+JQ13 | JZ13: =IFERROR(JU13/JT13/7,"") | LZ13: =KB13+KI13+KP13+KW13+LD13+LK13+LR13 | MA13: =IFERROR(LZ13/LY13/7,"") | MB13: =KC13+KJ13+KQ13+KX13+LE13+LL13+LS13 | MC13: =IFERROR(MB13/LZ13,"") | MD13: =KF13+KM13+KT13+LA13+LH13+LO13+LV13 | ME13: =IFERROR(LZ13/LY13/7,"") | OE13: =MG13+MN13+MU13+NB13+NI13+NP13+NW13 | OF13: =IFERROR(OE13/OD13/7,"") | OG13: =MH13+MO13+MV13+NC13+NJ13+NQ13+NX13 | OH13: =IFERROR(OG13/OE13,"") | OI13: =MK13+MR13+MY13+NF13+NM13+NT13+OA13 | OJ13: =IFERROR(OE13/OD13/7,"") | QJ13: =OL13+OS13+OZ13+PG13+PN13+PU13+QB13 | QK13: =IFERROR(QJ13/QI13/7,"") | QL13: =OM13+OT13+PA13+PH13+PO13+PV13+QC13 | QM13: =IFERROR(QL13/QJ13,"") | QN13: =OP13+OW13+PD13+PK13+PR13+PY13+QF13 | QO13: =IFERROR(QJ13/QI13/7,"") | SO13: =QQ13+QX13+RE13+RL13+RS13+RZ13+SG13 | SP13: =IFERROR(SO13/SN13/7,"") | SQ13: =QR13+QY13+RF13+RM13+RT13+SA13+SH13 | SR13: =IFERROR(SQ13/SO13,"") | SS13: =QU13+RB13+RI13+RP13+RW13+SD13+SK13 | ST13: =IFERROR(SO13/SN13/7,"") | UT13: =SV13+TC13+TJ13+TQ13+TX13+UE13+UL13 | UU13: =IFERROR(UT13/US13/7,"") | UV13: =SW13+TD13+TK13+TR13+TY13+UF13+UM13 | UW13: =IFERROR(UV13/UT13,"") | UX13: =SZ13+TG13+TN13+TU13+UB13+UI13+UP13 | UY13: =IFERROR(UT13/US13/7,"")
A14: 11 | B14: 16 | BA14: =C14+J14+Q14+X14+AE14+AL14+AS14 | BB14: =IFERROR(BA14/AZ14/7,"") | BC14: =D14+K14+R14+Y14+AF14+AM14+AT14 | BD14: =IFERROR(BC14/BA14,"") | BE14: =G14+N14+U14+AB14+AI14+AP14+AW14 | BF14: =IFERROR(BA14/AZ14/7,"") | DF14: =BH14+BO14+BV14+CC14+CJ14+CQ14+CX14 | DG14: =IFERROR(DF14/DE14/7,"") | DH14: =BI14+BP14+BW14+CD14+CK14+CR14+CY14 | DI14: =IFERROR(DH14/DF14,"") | DJ14: =BL14+BS14+BZ14+CG14+CN14+CU14+DB14 | DK14: =IFERROR(DF14/DE14/7,"") | FK14: =DM14+DT14+EA14+EH14+EO14+EV14+FC14 | FL14: =IFERROR(FK14/FJ14/7,"") | FM14: =DN14+DU14+EB14+EI14+EP14+EW14+FD14 | FN14: =IFERROR(FM14/FK14,"") | FO14: =DQ14+DX14+EE14+EL14+ES14+EZ14+FG14 | FP14: =IFERROR(FK14/FJ14/7,"") | HP14: =FR14+FY14+GF14+GM14+GT14+HA14+HH14 | HQ14: =IFERROR(HP14/HO14/7,"") | HR14: =FS14+FZ14+GG14+GN14+GU14+HB14+HI14 | HS14: =IFERROR(HR14/HP14,"") | HT14: =FV14+GC14+GJ14+GQ14+GX14+HE14+HL14 | HU14: =IFERROR(HP14/HO14/7,"") | JU14: =HW14+ID14+IK14+IR14+IY14+JF14+JM14 | JV14: =IFERROR(JU14/JT14/7,"") | JW14: =HX14+IE14+IL14+IS14+IZ14+JG14+JN14 | JX14: =IFERROR(JW14/JU14,"") | JY14: =IA14+IH14+IO14+IV14+JC14+JJ14+JQ14 | JZ14: =IFERROR(JU14/JT14/7,"") | LZ14: =KB14+KI14+KP14+KW14+LD14+LK14+LR14 | MA14: =IFERROR(LZ14/LY14/7,"") | MB14: =KC14+KJ14+KQ14+KX14+LE14+LL14+LS14 | MC14: =IFERROR(MB14/LZ14,"") | MD14: =KF14+KM14+KT14+LA14+LH14+LO14+LV14 | ME14: =IFERROR(LZ14/LY14/7,"") | OE14: =MG14+MN14+MU14+NB14+NI14+NP14+NW14 | OF14: =IFERROR(OE14/OD14/7,"") | OG14: =MH14+MO14+MV14+NC14+NJ14+NQ14+NX14 | OH14: =IFERROR(OG14/OE14,"") | OI14: =MK14+MR14+MY14+NF14+NM14+NT14+OA14 | OJ14: =IFERROR(OE14/OD14/7,"") | QJ14: =OL14+OS14+OZ14+PG14+PN14+PU14+QB14 | QK14: =IFERROR(QJ14/QI14/7,"") | QL14: =OM14+OT14+PA14+PH14+PO14+PV14+QC14 | QM14: =IFERROR(QL14/QJ14,"") | QN14: =OP14+OW14+PD14+PK14+PR14+PY14+QF14 | QO14: =IFERROR(QJ14/QI14/7,"") | SO14: =QQ14+QX14+RE14+RL14+RS14+RZ14+SG14 | SP14: =IFERROR(SO14/SN14/7,"") | SQ14: =QR14+QY14+RF14+RM14+RT14+SA14+SH14 | SR14: =IFERROR(SQ14/SO14,"") | SS14: =QU14+RB14+RI14+RP14+RW14+SD14+SK14 | ST14: =IFERROR(SO14/SN14/7,"") | UT14: =SV14+TC14+TJ14+TQ14+TX14+UE14+UL14 | UU14: =IFERROR(UT14/US14/7,"") | UV14: =SW14+TD14+TK14+TR14+TY14+UF14+UM14 | UW14: =IFERROR(UV14/UT14,"") | UX14: =SZ14+TG14+TN14+TU14+UB14+UI14+UP14 | UY14: =IFERROR(UT14/US14/7,"")
A15: 12 | B15: 24 | BA15: =C15+J15+Q15+X15+AE15+AL15+AS15 | BB15: =IFERROR(BA15/AZ15/7,"") | BC15: =D15+K15+R15+Y15+AF15+AM15+AT15 | BD15: =IFERROR(BC15/BA15,"") | BE15: =G15+N15+U15+AB15+AI15+AP15+AW15 | BF15: =IFERROR(BA15/AZ15/7,"") | DF15: =BH15+BO15+BV15+CC15+CJ15+CQ15+CX15 | DG15: =IFERROR(DF15/DE15/7,"") | DH15: =BI15+BP15+BW15+CD15+CK15+CR15+CY15 | DI15: =IFERROR(DH15/DF15,"") | DJ15: =BL15+BS15+BZ15+CG15+CN15+CU15+DB15 | DK15: =IFERROR(DF15/DE15/7,"") | FK15: =DM15+DT15+EA15+EH15+EO15+EV15+FC15 | FL15: =IFERROR(FK15/FJ15/7,"") | FM15: =DN15+DU15+EB15+EI15+EP15+EW15+FD15 | FN15: =IFERROR(FM15/FK15,"") | FO15: =DQ15+DX15+EE15+EL15+ES15+EZ15+FG15 | FP15: =IFERROR(FK15/FJ15/7,"") | HP15: =FR15+FY15+GF15+GM15+GT15+HA15+HH15 | HQ15: =IFERROR(HP15/HO15/7,"") | HR15: =FS15+FZ15+GG15+GN15+GU15+HB15+HI15 | HS15: =IFERROR(HR15/HP15,"") | HT15: =FV15+GC15+GJ15+GQ15+GX15+HE15+HL15 | HU15: =IFERROR(HP15/HO15/7,"") | JU15: =HW15+ID15+IK15+IR15+IY15+JF15+JM15 | JV15: =IFERROR(JU15/JT15/7,"") | JW15: =HX15+IE15+IL15+IS15+IZ15+JG15+JN15 | JX15: =IFERROR(JW15/JU15,"") | JY15: =IA15+IH15+IO15+IV15+JC15+JJ15+JQ15 | JZ15: =IFERROR(JU15/JT15/7,"") | LZ15: =KB15+KI15+KP15+KW15+LD15+LK15+LR15 | MA15: =IFERROR(LZ15/LY15/7,"") | MB15: =KC15+KJ15+KQ15+KX15+LE15+LL15+LS15 | MC15: =IFERROR(MB15/LZ15,"") | MD15: =KF15+KM15+KT15+LA15+LH15+LO15+LV15 | ME15: =IFERROR(LZ15/LY15/7,"") | OE15: =MG15+MN15+MU15+NB15+NI15+NP15+NW15 | OF15: =IFERROR(OE15/OD15/7,"") | OG15: =MH15+MO15+MV15+NC15+NJ15+NQ15+NX15 | OH15: =IFERROR(OG15/OE15,"") | OI15: =MK15+MR15+MY15+NF15+NM15+NT15+OA15 | OJ15: =IFERROR(OE15/OD15/7,"") | QJ15: =OL15+OS15+OZ15+PG15+PN15+PU15+QB15 | QK15: =IFERROR(QJ15/QI15/7,"") | QL15: =OM15+OT15+PA15+PH15+PO15+PV15+QC15 | QM15: =IFERROR(QL15/QJ15,"") | QN15: =OP15+OW15+PD15+PK15+PR15+PY15+QF15 | QO15: =IFERROR(QJ15/QI15/7,"") | SO15: =QQ15+QX15+RE15+RL15+RS15+RZ15+SG15 | SP15: =IFERROR(SO15/SN15/7,"") | SQ15: =QR15+QY15+RF15+RM15+RT15+SA15+SH15 | SR15: =IFERROR(SQ15/SO15,"") | SS15: =QU15+RB15+RI15+RP15+RW15+SD15+SK15 | ST15: =IFERROR(SO15/SN15/7,"") | UT15: =SV15+TC15+TJ15+TQ15+TX15+UE15+UL15 | UU15: =IFERROR(UT15/US15/7,"") | UV15: =SW15+TD15+TK15+TR15+TY15+UF15+UM15 | UW15: =IFERROR(UV15/UT15,"") | UX15: =SZ15+TG15+TN15+TU15+UB15+UI15+UP15 | UY15: =IFERROR(UT15/US15/7,"")
... A195: 192 | B195: 29 | BA195: =C195+J195+Q195+X195+AE195+AL195+AS195 | BB195: =IFERROR(BA195/AZ195/7,"") | BC195: =D195+K195+R195+Y195+AF195+AM195+AT195 | BD195: =IFERROR(BC195/BA195,"") | BE195: =G195+N195+U195+AB195+AI195+AP195+AW195 | BF195: =IFERROR(BA195/AZ195/7,"") | DF195: =BH195+BO195+BV195+CC195+CJ195+CQ195+CX195 | DG195: =IFERROR(DF195/DE195/7,"") | DH195: =BI195+BP195+BW195+CD195+CK195+CR195+CY195 | DI195: =IFERROR(DH195/DF195,"") | DJ195: =BL195+BS195+BZ195+CG195+CN195+CU195+DB195 | DK195: =IFERROR(DF195/DE195/7,"") | FK195: =DM195+DT195+EA195+EH195+EO195+EV195+FC195 | FL195: =IFERROR(FK195/FJ195/7,"") | FM195: =DN195+DU195+EB195+EI195+EP195+EW195+FD195 | FN195: =IFERROR(FM195/FK195,"") | FO195: =DQ195+DX195+EE195+EL195+ES195+EZ195+FG195 | FP195: =IFERROR(FK195/FJ195/7,"") | HP195: =FR195+FY195+GF195+GM195+GT195+HA195+HH195 | HQ195: =IFERROR(HP195/HO195/7,"") | HR195: =FS195+FZ195+GG195+GN195+GU195+HB195+HI195 | HS195: =IFERROR(HR195/HP195,"") | HT195: =FV195+GC195+GJ195+GQ195+GX195+HE195+HL195 | HU195: =IFERROR(HP195/HO195/7,"") | JU195: =HW195+ID195+IK195+IR195+IY195+JF195+JM195 | JV195: =IFERROR(JU195/JT195/7,"") | JW195: =HX195+IE195+IL195+IS195+IZ195+JG195+JN195 | JX195: =IFERROR(JW195/JU195,"") | JY195: =IA195+IH195+IO195+IV195+JC195+JJ195+JQ195 | JZ195: =IFERROR(JU195/JT195/7,"") | LZ195: =KB195+KI195+KP195+KW195+LD195+LK195+LR195 | MA195: =IFERROR(LZ195/LY195/7,"") | MB195: =KC195+KJ195+KQ195+KX195+LE195+LL195+LS195 | MC195: =IFERROR(MB195/LZ195,"") | MD195: =KF195+KM195+KT195+LA195+LH195+LO195+LV195 | ME195: =IFERROR(LZ195/LY195/7,"") | OE195: =MG195+MN195+MU195+NB195+NI195+NP195+NW195 | OF195: =IFERROR(OE195/OD195/7,"") | OG195: =MH195+MO195+MV195+NC195+NJ195+NQ195+NX195 | OH195: =IFERROR(OG195/OE195,"") | OI195: =MK195+MR195+MY195+NF195+NM195+NT195+OA195 | OJ195: =IFERROR(OE195/OD195/7,"") | QJ195: =OL195+OS195+OZ195+PG195+PN195+PU195+QB195 | QK195: =IFERROR(QJ195/QI195/7,"") | QL195: =OM195+OT195+PA195+PH195+PO195+PV195+QC195 | QM195: =IFERROR(QL195/QJ195,"") | QN195: =OP195+OW195+PD195+PK195+PR195+PY195+QF195 | QO195: =IFERROR(QJ195/QI195/7,"") | SO195: =QQ195+QX195+RE195+RL195+RS195+RZ195+SG195 | SP195: =IFERROR(SO195/SN195/7,"") | SQ195: =QR195+QY195+RF195+RM195+RT195+SA195+SH195 | SR195: =IFERROR(SQ195/SO195,"") | SS195: =QU195+RB195+RI195+RP195+RW195+SD195+SK195 | ST195: =IFERROR(SO195/SN195/7,"") | UT195: =SV195+TC195+TJ195+TQ195+TX195+UE195+UL195 | UU195: =IFERROR(UT195/US195/7,"") | UV195: =SW195+TD195+TK195+TR195+TY195+UF195+UM195 | UW195: =IFERROR(UV195/UT195,"") | UX195: =SZ195+TG195+TN195+TU195+UB195+UI195+UP195 | UY195: =IFERROR(UT195/US195/7,"")
C197: =SUM(C4:C195) | G197: =SUM(G4:G195) | J197: =SUM(J4:J195) | N197: =SUM(N4:N195) | Q197: =SUM(Q4:Q195) | U197: =SUM(U4:U195) | X197: =SUM(X4:X195) | AB197: =SUM(AB4:AB195) | AE197: =SUM(AE4:AE195) | AI197: =SUM(AI4:AI195) | AL197: =SUM(AL4:AL195) | AP197: =SUM(AP4:AP195) | AS197: =SUM(AS4:AS195) | AW197: =SUM(AW4:AW195) | BH197: =SUM(BH4:BH195) | BL197: =SUM(BL4:BL195) | BO197: =SUM(BO4:BO195) | BS197: =SUM(BS4:BS195) | BV197: =SUM(BV4:BV195) | BZ197: =SUM(BZ4:BZ195) | CC197: =SUM(CC4:CC195) | CG197: =SUM(CG4:CG195) | CJ197: =SUM(CJ4:CJ195) | CN197: =SUM(CN4:CN195) | CQ197: =SUM(CQ4:CQ195) | CU197: =SUM(CU4:CU195) | CX197: =SUM(CX4:CX195) | DB197: =SUM(DB4:DB195) | DM197: =SUM(DM4:DM195) | DQ197: =SUM(DQ4:DQ195) | DT197: =SUM(DT4:DT195) | DX197: =SUM(DX4:DX195) | EA197: =SUM(EA4:EA195) | EE197: =SUM(EE4:EE195) | EH197: =SUM(EH4:EH195) | EL197: =SUM(EL4:EL195) | EO197: =SUM(EO4:EO195) | ES197: =SUM(ES4:ES195) | EV197: =SUM(EV4:EV195) | EZ197: =SUM(EZ4:EZ195) | FC197: =SUM(FC4:FC195) | FG197: =SUM(FG4:FG195) | FR197: =SUM(FR4:FR195) | FV197: =SUM(FV4:FV195) | FY197: =SUM(FY4:FY195) | GC197: =SUM(GC4:GC195) | GF197: =SUM(GF4:GF195) | GJ197: =SUM(GJ4:GJ195) | GM197: =SUM(GM4:GM195) | GQ197: =SUM(GQ4:GQ195) | GT197: =SUM(GT4:GT195) | GX197: =SUM(GX4:GX195) | HA197: =SUM(HA4:HA195) | HE197: =SUM(HE4:HE195) | HH197: =SUM(HH4:HH195) | HL197: =SUM(HL4:HL195) | HW197: =SUM(HW4:HW195) | IA197: =SUM(IA4:IA195) | ID197: =SUM(ID4:ID195) | IH197: =SUM(IH4:IH195) | IK197: =SUM(IK4:IK195) | IO197: =SUM(IO4:IO195) | IR197: =SUM(IR4:IR195) | IV197: =SUM(IV4:IV195) | IY197: =SUM(IY4:IY195) | JC197: =SUM(JC4:JC195) | JF197: =SUM(JF4:JF195) | JJ197: =SUM(JJ4:JJ195) | JM197: =SUM(JM4:JM195) | JQ197: =SUM(JQ4:JQ195) | KB197: =SUM(KB4:KB195) | KF197: =SUM(KF4:KF195) | KI197: =SUM(KI4:KI195) | KM197: =SUM(KM4:KM195) | KP197: =SUM(KP4:KP195) | KT197: =SUM(KT4:KT195) | KW197: =SUM(KW4:KW195) | LA197: =SUM(LA4:LA195) | LD197: =SUM(LD4:LD195) | LH197: =SUM(LH4:LH195) | LK197: =SUM(LK4:LK195) | LO197: =SUM(LO4:LO195) | LR197: =SUM(LR4:LR195) | LV197: =SUM(LV4:LV195) | MG197: =SUM(MG4:MG195) | MK197: =SUM(MK4:MK195) | MN197: =SUM(MN4:MN195) | MR197: =SUM(MR4:MR195) | MU197: =SUM(MU4:MU195) | MY197: =SUM(MY4:MY195) | NB197: =SUM(NB4:NB195) | NF197: =SUM(NF4:NF195) | NI197: =SUM(NI4:NI195) | NM197: =SUM(NM4:NM195) | NP197: =SUM(NP4:NP195) | NT197: =SUM(NT4:NT195) | NW197: =SUM(NW4:NW195) | OA197: =SUM(OA4:OA195) | OL197: =SUM(OL4:OL195) | OP197: =SUM(OP4:OP195) | OS197: =SUM(OS4:OS195) | OW197: =SUM(OW4:OW195) | OZ197: =SUM(OZ4:OZ195) | PD197: =SUM(PD4:PD195) | PG197: =SUM(PG4:PG195) | PK197: =SUM(PK4:PK195) | PN197: =SUM(PN4:PN195) | PR197: =SUM(PR4:PR195) | PU197: =SUM(PU4:PU195) | PY197: =SUM(PY4:PY195) | QB197: =SUM(QB4:QB195) | QF197: =SUM(QF4:QF195) | QQ197: =SUM(QQ4:QQ195) | QU197: =SUM(QU4:QU195) | QX197: =SUM(QX4:QX195) | RB197: =SUM(RB4:RB195) | RE197: =SUM(RE4:RE195) | RI197: =SUM(RI4:RI195) | RL197: =SUM(RL4:RL195) | RP197: =SUM(RP4:RP195) | RS197: =SUM(RS4:RS195) | RW197: =SUM(RW4:RW195) | RZ197: =SUM(RZ4:RZ195) | SD197: =SUM(SD4:SD195) | SG197: =SUM(SG4:SG195) | SK197: =SUM(SK4:SK195) | SV197: =SUM(SV4:SV195) | SZ197: =SUM(SZ4:SZ195) | TC197: =SUM(TC4:TC195) | TG197: =SUM(TG4:TG195) | TJ197: =SUM(TJ4:TJ195) | TN197: =SUM(TN4:TN195) | TQ197: =SUM(TQ4:TQ195) | TU197: =SUM(TU4:TU195) | TX197: =SUM(TX4:TX195) | UB197: =SUM(UB4:UB195) | UE197: =SUM(UE4:UE195) | UI197: =SUM(UI4:UI195) | UL197: =SUM(UL4:UL195) | UP197: =SUM(UP4:UP195)

Sheet Feed Data
D1: 04Aug - 10Aug2026 | K1: 11Aug - 17Aug2026 | R1: 18Aug - 24Aug2026 | Y1: 25Aug - 31Aug2026 | AF1: 01Sep - 07Sep2026 | AM1: 08Sep - 14Sep2026 | AT1: 15Sep - 21Sep2026 | BA1: 22Sep - 28Sep2026 | BH1: 29Sep - 05Oct2026 | BO1: 06Oct - 12Oct2026
D2: 94W | K2: 95W | R2: 96W | Y2: 97W | AF2: 98W | AM2: 99W | AT2: 100W | BA2: 101W | BH2: 102W | BO2: 103W
A3: Pen Number | B3: Treatment Number | D3: Bird # | E3: Feed Allocation | F3: Feed Orts | G3: Weekly Pen FI 94W | H3: Weekly Ave Bird FI 94W | I3: FCR 94W | K3: Bird # | L3: Feed Allocation | M3: Feed Orts | N3: Weekly Pen FI 95W | O3: Weekly Ave Bird FI 95W | P3: FCR 95W | R3: Bird # | S3: Feed Allocation | T3: Feed Orts | U3: Weekly Pen FI 96W | V3: Weekly Ave Bird FI 96W | W3: FCR 96W | Y3: Bird # | Z3: Feed Allocation | AA3: Feed Orts | AB3: Weekly Pen FI 97W | AC3: Weekly Ave Bird FI 97W | AD3: FCR 97W | AF3: Bird # | AG3: Feed Allocation | AH3: Feed Orts | AI3: Weekly Pen FI 98W | AJ3: Weekly Ave Bird FI 98W | AK3: FCR 98W | AM3: Bird # | AN3: Feed Allocation | AO3: Feed Orts | AP3: Weekly Pen FI 99W | AQ3: Weekly Ave Bird FI 99W | AR3: FCR 99W | AT3: Bird # | AU3: Feed Allocation | AV3: Feed Orts | AW3: Weekly Pen FI 100W | AX3: Weekly Ave Bird FI 100W | AY3: FCR 100W | BA3: Bird # | BB3: Feed Allocation | BC3: Feed Orts | BD3: Weekly Pen FI 101W | BE3: Weekly Ave Bird FI 101W | BF3: FCR 101W | BH3: Bird # | BI3: Feed Allocation | BJ3: Feed Orts | BK3: Weekly Pen FI 102W | BL3: Weekly Ave Bird FI 102W | BM3: FCR 102W | BO3: Bird # | BP3: Feed Allocation | BQ3: Feed Orts | BR3: Weekly Pen FI 103W | BS3: Weekly Ave Bird FI 103W | BT3: FCR 103W
A4: 1 | B4: 1 | D4: 7 | G4: =E4-F4 | H4: =G4/D4 | I4: =IFERROR((G4*1000)/'Egg Data'!BC4,"") | K4: 7 | N4: =L4-M4 | O4: =N4/K4 | P4: =IFERROR((N4*1000)/'Egg Data'!DH4,"") | R4: 7 | U4: =S4-T4 | V4: =U4/R4 | W4: =IFERROR((U4*1000)/'Egg Data'!FM4,"") | Y4: 7 | AB4: =Z4-AA4 | AC4: =AB4/Y4 | AD4: =IFERROR((AB4*1000)/'Egg Data'!HR4,"") | AF4: 7 | AI4: =AG4-AH4 | AJ4: =AI4/AF4 | AK4: =IFERROR((AI4*1000)/'Egg Data'!JW4,"") | AM4: 7 | AP4: =AN4-AO4 | AQ4: =AP4/AM4 | AR4: =IFERROR((AP4*1000)/'Egg Data'!MB4,"") | AT4: 7 | AW4: =AU4-AV4 | AX4: =AW4/AT4 | AY4: =IFERROR((AW4*1000)/'Egg Data'!OG4,"") | BA4: 7 | BD4: =BB4-BC4 | BE4: =BD4/BA4 | BF4: =IFERROR((BD4*1000)/'Egg Data'!QL4,"") | BH4: 7 | BK4: =BI4-BJ4 | BL4: =BK4/BH4 | BM4: =IFERROR((BK4*1000)/'Egg Data'!SQ4,"") | BO4: 7 | BR4: =BP4-BQ4 | BS4: =BR4/BO4 | BT4: =IFERROR((BR4*1000)/'Egg Data'!UV4,"")
A5: 2 | B5: 9 | D5: 7 | G5: =E5-F5 | H5: =G5/D5 | I5: =IFERROR((G5*1000)/'Egg Data'!BC5,"") | K5: 7 | N5: =L5-M5 | O5: =N5/K5 | P5: =IFERROR((N5*1000)/'Egg Data'!DH5,"") | R5: 7 | U5: =S5-T5 | V5: =U5/R5 | W5: =IFERROR((U5*1000)/'Egg Data'!FM5,"") | Y5: 7 | AB5: =Z5-AA5 | AC5: =AB5/Y5 | AD5: =IFERROR((AB5*1000)/'Egg Data'!HR5,"") | AF5: 7 | AI5: =AG5-AH5 | AJ5: =AI5/AF5 | AK5: =IFERROR((AI5*1000)/'Egg Data'!JW5,"") | AM5: 7 | AP5: =AN5-AO5 | AQ5: =AP5/AM5 | AR5: =IFERROR((AP5*1000)/'Egg Data'!MB5,"") | AT5: 7 | AW5: =AU5-AV5 | AX5: =AW5/AT5 | AY5: =IFERROR((AW5*1000)/'Egg Data'!OG5,"") | BA5: 7 | BD5: =BB5-BC5 | BE5: =BD5/BA5 | BF5: =IFERROR((BD5*1000)/'Egg Data'!QL5,"") | BH5: 7 | BK5: =BI5-BJ5 | BL5: =BK5/BH5 | BM5: =IFERROR((BK5*1000)/'Egg Data'!SQ5,"") | BO5: 7 | BR5: =BP5-BQ5 | BS5: =BR5/BO5 | BT5: =IFERROR((BR5*1000)/'Egg Data'!UV5,"")
A6: 3 | B6: 17 | D6: 7 | G6: =E6-F6 | H6: =G6/D6 | I6: =IFERROR((G6*1000)/'Egg Data'!BC6,"") | K6: 7 | N6: =L6-M6 | O6: =N6/K6 | P6: =IFERROR((N6*1000)/'Egg Data'!DH6,"") | R6: 7 | U6: =S6-T6 | V6: =U6/R6 | W6: =IFERROR((U6*1000)/'Egg Data'!FM6,"") | Y6: 7 | AB6: =Z6-AA6 | AC6: =AB6/Y6 | AD6: =IFERROR((AB6*1000)/'Egg Data'!HR6,"") | AF6: 7 | AI6: =AG6-AH6 | AJ6: =AI6/AF6 | AK6: =IFERROR((AI6*1000)/'Egg Data'!JW6,"") | AM6: 7 | AP6: =AN6-AO6 | AQ6: =AP6/AM6 | AR6: =IFERROR((AP6*1000)/'Egg Data'!MB6,"") | AT6: 7 | AW6: =AU6-AV6 | AX6: =AW6/AT6 | AY6: =IFERROR((AW6*1000)/'Egg Data'!OG6,"") | BA6: 7 | BD6: =BB6-BC6 | BE6: =BD6/BA6 | BF6: =IFERROR((BD6*1000)/'Egg Data'!QL6,"") | BH6: 7 | BK6: =BI6-BJ6 | BL6: =BK6/BH6 | BM6: =IFERROR((BK6*1000)/'Egg Data'!SQ6,"") | BO6: 7 | BR6: =BP6-BQ6 | BS6: =BR6/BO6 | BT6: =IFERROR((BR6*1000)/'Egg Data'!UV6,"")
A7: 4 | B7: 25 | D7: 7 | G7: =E7-F7 | H7: =G7/D7 | I7: =IFERROR((G7*1000)/'Egg Data'!BC7,"") | K7: 7 | N7: =L7-M7 | O7: =N7/K7 | P7: =IFERROR((N7*1000)/'Egg Data'!DH7,"") | R7: 7 | U7: =S7-T7 | V7: =U7/R7 | W7: =IFERROR((U7*1000)/'Egg Data'!FM7,"") | Y7: 7 | AB7: =Z7-AA7 | AC7: =AB7/Y7 | AD7: =IFERROR((AB7*1000)/'Egg Data'!HR7,"") | AF7: 7 | AI7: =AG7-AH7 | AJ7: =AI7/AF7 | AK7: =IFERROR((AI7*1000)/'Egg Data'!JW7,"") | AM7: 7 | AP7: =AN7-AO7 | AQ7: =AP7/AM7 | AR7: =IFERROR((AP7*1000)/'Egg Data'!MB7,"") | AT7: 7 | AW7: =AU7-AV7 | AX7: =AW7/AT7 | AY7: =IFERROR((AW7*1000)/'Egg Data'!OG7,"") | BA7: 7 | BD7: =BB7-BC7 | BE7: =BD7/BA7 | BF7: =IFERROR((BD7*1000)/'Egg Data'!QL7,"") | BH7: 7 | BK7: =BI7-BJ7 | BL7: =BK7/BH7 | BM7: =IFERROR((BK7*1000)/'Egg Data'!SQ7,"") | BO7: 7 | BR7: =BP7-BQ7 | BS7: =BR7/BO7 | BT7: =IFERROR((BR7*1000)/'Egg Data'!UV7,"")
A8: 5 | B8: 28 | D8: 7 | G8: =E8-F8 | H8: =G8/D8 | I8: =IFERROR((G8*1000)/'Egg Data'!BC8,"") | K8: 7 | N8: =L8-M8 | O8: =N8/K8 | P8: =IFERROR((N8*1000)/'Egg Data'!DH8,"") | R8: 7 | U8: =S8-T8 | V8: =U8/R8 | W8: =IFERROR((U8*1000)/'Egg Data'!FM8,"") | Y8: 7 | AB8: =Z8-AA8 | AC8: =AB8/Y8 | AD8: =IFERROR((AB8*1000)/'Egg Data'!HR8,"") | AF8: 7 | AI8: =AG8-AH8 | AJ8: =AI8/AF8 | AK8: =IFERROR((AI8*1000)/'Egg Data'!JW8,"") | AM8: 7 | AP8: =AN8-AO8 | AQ8: =AP8/AM8 | AR8: =IFERROR((AP8*1000)/'Egg Data'!MB8,"") | AT8: 7 | AW8: =AU8-AV8 | AX8: =AW8/AT8 | AY8: =IFERROR((AW8*1000)/'Egg Data'!OG8,"") | BA8: 7 | BD8: =BB8-BC8 | BE8: =BD8/BA8 | BF8: =IFERROR((BD8*1000)/'Egg Data'!QL8,"") | BH8: 7 | BK8: =BI8-BJ8 | BL8: =BK8/BH8 | BM8: =IFERROR((BK8*1000)/'Egg Data'!SQ8,"") | BO8: 7 | BR8: =BP8-BQ8 | BS8: =BR8/BO8 | BT8: =IFERROR((BR8*1000)/'Egg Data'!UV8,"")
A9: 6 | B9: 4 | D9: 7 | G9: =E9-F9 | H9: =G9/D9 | I9: =IFERROR((G9*1000)/'Egg Data'!BC9,"") | K9: 7 | N9: =L9-M9 | O9: =N9/K9 | P9: =IFERROR((N9*1000)/'Egg Data'!DH9,"") | R9: 7 | U9: =S9-T9 | V9: =U9/R9 | W9: =IFERROR((U9*1000)/'Egg Data'!FM9,"") | Y9: 7 | AB9: =Z9-AA9 | AC9: =AB9/Y9 | AD9: =IFERROR((AB9*1000)/'Egg Data'!HR9,"") | AF9: 7 | AI9: =AG9-AH9 | AJ9: =AI9/AF9 | AK9: =IFERROR((AI9*1000)/'Egg Data'!JW9,"") | AM9: 7 | AP9: =AN9-AO9 | AQ9: =AP9/AM9 | AR9: =IFERROR((AP9*1000)/'Egg Data'!MB9,"") | AT9: 7 | AW9: =AU9-AV9 | AX9: =AW9/AT9 | AY9: =IFERROR((AW9*1000)/'Egg Data'!OG9,"") | BA9: 7 | BD9: =BB9-BC9 | BE9: =BD9/BA9 | BF9: =IFERROR((BD9*1000)/'Egg Data'!QL9,"") | BH9: 7 | BK9: =BI9-BJ9 | BL9: =BK9/BH9 | BM9: =IFERROR((BK9*1000)/'Egg Data'!SQ9,"") | BO9: 7 | BR9: =BP9-BQ9 | BS9: =BR9/BO9 | BT9: =IFERROR((BR9*1000)/'Egg Data'!UV9,"")
A10: 7 | B10: 12 | D10: 7 | G10: =E10-F10 | H10: =G10/D10 | I10: =IFERROR((G10*1000)/'Egg Data'!BC10,"") | K10: 7 | N10: =L10-M10 | O10: =N10/K10 | P10: =IFERROR((N10*1000)/'Egg Data'!DH10,"") | R10: 7 | U10: =S10-T10 | V10: =U10/R10 | W10: =IFERROR((U10*1000)/'Egg Data'!FM10,"") | Y10: 7 | AB10: =Z10-AA10 | AC10: =AB10/Y10 | AD10: =IFERROR((AB10*1000)/'Egg Data'!HR10,"") | AF10: 7 | AI10: =AG10-AH10 | AJ10: =AI10/AF10 | AK10: =IFERROR((AI10*1000)/'Egg Data'!JW10,"") | AM10: 7 | AP10: =AN10-AO10 | AQ10: =AP10/AM10 | AR10: =IFERROR((AP10*1000)/'Egg Data'!MB10,"") | AT10: 7 | AW10: =AU10-AV10 | AX10: =AW10/AT10 | AY10: =IFERROR((AW10*1000)/'Egg Data'!OG10,"") | BA10: 7 | BD10: =BB10-BC10 | BE10: =BD10/BA10 | BF10: =IFERROR((BD10*1000)/'Egg Data'!QL10,"") | BH10: 7 | BK10: =BI10-BJ10 | BL10: =BK10/BH10 | BM10: =IFERROR((BK10*1000)/'Egg Data'!SQ10,"") | BO10: 7 | BR10: =BP10-BQ10 | BS10: =BR10/BO10 | BT10: =IFERROR((BR10*1000)/'Egg Data'!UV10,"")
A11: 8 | B11: 20 | D11: 7 | G11: =E11-F11 | H11: =G11/D11 | I11: =IFERROR((G11*1000)/'Egg Data'!BC11,"") | K11: 7 | N11: =L11-M11 | O11: =N11/K11 | P11: =IFERROR((N11*1000)/'Egg Data'!DH11,"") | R11: 7 | U11: =S11-T11 | V11: =U11/R11 | W11: =IFERROR((U11*1000)/'Egg Data'!FM11,"") | Y11: 7 | AB11: =Z11-AA11 | AC11: =AB11/Y11 | AD11: =IFERROR((AB11*1000)/'Egg Data'!HR11,"") | AF11: 7 | AI11: =AG11-AH11 | AJ11: =AI11/AF11 | AK11: =IFERROR((AI11*1000)/'Egg Data'!JW11,"") | AM11: 7 | AP11: =AN11-AO11 | AQ11: =AP11/AM11 | AR11: =IFERROR((AP11*1000)/'Egg Data'!MB11,"") | AT11: 7 | AW11: =AU11-AV11 | AX11: =AW11/AT11 | AY11: =IFERROR((AW11*1000)/'Egg Data'!OG11,"") | BA11: 7 | BD11: =BB11-BC11 | BE11: =BD11/BA11 | BF11: =IFERROR((BD11*1000)/'Egg Data'!QL11,"") | BH11: 7 | BK11: =BI11-BJ11 | BL11: =BK11/BH11 | BM11: =IFERROR((BK11*1000)/'Egg Data'!SQ11,"") | BO11: 7 | BR11: =BP11-BQ11 | BS11: =BR11/BO11 | BT11: =IFERROR((BR11*1000)/'Egg Data'!UV11,"")
A12: 9 | B12: 32 | D12: 7 | G12: =E12-F12 | H12: =G12/D12 | I12: =IFERROR((G12*1000)/'Egg Data'!BC12,"") | K12: 7 | N12: =L12-M12 | O12: =N12/K12 | P12: =IFERROR((N12*1000)/'Egg Data'!DH12,"") | R12: 7 | U12: =S12-T12 | V12: =U12/R12 | W12: =IFERROR((U12*1000)/'Egg Data'!FM12,"") | Y12: 7 | AB12: =Z12-AA12 | AC12: =AB12/Y12 | AD12: =IFERROR((AB12*1000)/'Egg Data'!HR12,"") | AF12: 7 | AI12: =AG12-AH12 | AJ12: =AI12/AF12 | AK12: =IFERROR((AI12*1000)/'Egg Data'!JW12,"") | AM12: 7 | AP12: =AN12-AO12 | AQ12: =AP12/AM12 | AR12: =IFERROR((AP12*1000)/'Egg Data'!MB12,"") | AT12: 7 | AW12: =AU12-AV12 | AX12: =AW12/AT12 | AY12: =IFERROR((AW12*1000)/'Egg Data'!OG12,"") | BA12: 7 | BD12: =BB12-BC12 | BE12: =BD12/BA12 | BF12: =IFERROR((BD12*1000)/'Egg Data'!QL12,"") | BH12: 7 | BK12: =BI12-BJ12 | BL12: =BK12/BH12 | BM12: =IFERROR((BK12*1000)/'Egg Data'!SQ12,"") | BO12: 7 | BR12: =BP12-BQ12 | BS12: =BR12/BO12 | BT12: =IFERROR((BR12*1000)/'Egg Data'!UV12,"")
A13: 10 | B13: 8 | D13: 7 | G13: =E13-F13 | H13: =G13/D13 | I13: =IFERROR((G13*1000)/'Egg Data'!BC13,"") | K13: 7 | N13: =L13-M13 | O13: =N13/K13 | P13: =IFERROR((N13*1000)/'Egg Data'!DH13,"") | R13: 7 | U13: =S13-T13 | V13: =U13/R13 | W13: =IFERROR((U13*1000)/'Egg Data'!FM13,"") | Y13: 7 | AB13: =Z13-AA13 | AC13: =AB13/Y13 | AD13: =IFERROR((AB13*1000)/'Egg Data'!HR13,"") | AF13: 7 | AI13: =AG13-AH13 | AJ13: =AI13/AF13 | AK13: =IFERROR((AI13*1000)/'Egg Data'!JW13,"") | AM13: 7 | AP13: =AN13-AO13 | AQ13: =AP13/AM13 | AR13: =IFERROR((AP13*1000)/'Egg Data'!MB13,"") | AT13: 7 | AW13: =AU13-AV13 | AX13: =AW13/AT13 | AY13: =IFERROR((AW13*1000)/'Egg Data'!OG13,"") | BA13: 7 | BD13: =BB13-BC13 | BE13: =BD13/BA13 | BF13: =IFERROR((BD13*1000)/'Egg Data'!QL13,"") | BH13: 7 | BK13: =BI13-BJ13 | BL13: =BK13/BH13 | BM13: =IFERROR((BK13*1000)/'Egg Data'!SQ13,"") | BO13: 7 | BR13: =BP13-BQ13 | BS13: =BR13/BO13 | BT13: =IFERROR((BR13*1000)/'Egg Data'!UV13,"")
A14: 11 | B14: 16 | D14: 7 | G14: =E14-F14 | H14: =G14/D14 | I14: =IFERROR((G14*1000)/'Egg Data'!BC14,"") | K14: 7 | N14: =L14-M14 | O14: =N14/K14 | P14: =IFERROR((N14*1000)/'Egg Data'!DH14,"") | R14: 7 | U14: =S14-T14 | V14: =U14/R14 | W14: =IFERROR((U14*1000)/'Egg Data'!FM14,"") | Y14: 7 | AB14: =Z14-AA14 | AC14: =AB14/Y14 | AD14: =IFERROR((AB14*1000)/'Egg Data'!HR14,"") | AF14: 7 | AI14: =AG14-AH14 | AJ14: =AI14/AF14 | AK14: =IFERROR((AI14*1000)/'Egg Data'!JW14,"") | AM14: 7 | AP14: =AN14-AO14 | AQ14: =AP14/AM14 | AR14: =IFERROR((AP14*1000)/'Egg Data'!MB14,"") | AT14: 7 | AW14: =AU14-AV14 | AX14: =AW14/AT14 | AY14: =IFERROR((AW14*1000)/'Egg Data'!OG14,"") | BA14: 7 | BD14: =BB14-BC14 | BE14: =BD14/BA14 | BF14: =IFERROR((BD14*1000)/'Egg Data'!QL14,"") | BH14: 7 | BK14: =BI14-BJ14 | BL14: =BK14/BH14 | BM14: =IFERROR((BK14*1000)/'Egg Data'!SQ14,"") | BO14: 7 | BR14: =BP14-BQ14 | BS14: =BR14/BO14 | BT14: =IFERROR((BR14*1000)/'Egg Data'!UV14,"")
A15: 12 | B15: 24 | D15: 7 | G15: =E15-F15 | H15: =G15/D15 | I15: =IFERROR((G15*1000)/'Egg Data'!BC15,"") | K15: 7 | N15: =L15-M15 | O15: =N15/K15 | P15: =IFERROR((N15*1000)/'Egg Data'!DH15,"") | R15: 7 | U15: =S15-T15 | V15: =U15/R15 | W15: =IFERROR((U15*1000)/'Egg Data'!FM15,"") | Y15: 7 | AB15: =Z15-AA15 | AC15: =AB15/Y15 | AD15: =IFERROR((AB15*1000)/'Egg Data'!HR15,"") | AF15: 7 | AI15: =AG15-AH15 | AJ15: =AI15/AF15 | AK15: =IFERROR((AI15*1000)/'Egg Data'!JW15,"") | AM15: 7 | AP15: =AN15-AO15 | AQ15: =AP15/AM15 | AR15: =IFERROR((AP15*1000)/'Egg Data'!MB15,"") | AT15: 7 | AW15: =AU15-AV15 | AX15: =AW15/AT15 | AY15: =IFERROR((AW15*1000)/'Egg Data'!OG15,"") | BA15: 7 | BD15: =BB15-BC15 | BE15: =BD15/BA15 | BF15: =IFERROR((BD15*1000)/'Egg Data'!QL15,"") | BH15: 7 | BK15: =BI15-BJ15 | BL15: =BK15/BH15 | BM15: =IFERROR((BK15*1000)/'Egg Data'!SQ15,"") | BO15: 7 | BR15: =BP15-BQ15 | BS15: =BR15/BO15 | BT15: =IFERROR((BR15*1000)/'Egg Data'!UV15,"")
... A195: 192 | B195: 29 | D195: 7 | G195: =E195-F195 | H195: =G195/D195 | I195: =IFERROR((G195*1000)/'Egg Data'!BC195,"") | K195: 7 | N195: =L195-M195 | O195: =N195/K195 | P195: =IFERROR((N195*1000)/'Egg Data'!DH195,"") | R195: 7 | U195: =S195-T195 | V195: =U195/R195 | W195: =IFERROR((U195*1000)/'Egg Data'!FM195,"") | Y195: 7 | AB195: =Z195-AA195 | AC195: =AB195/Y195 | AD195: =IFERROR((AB195*1000)/'Egg Data'!HR195,"") | AF195: 7 | AI195: =AG195-AH195 | AJ195: =AI195/AF195 | AK195: =IFERROR((AI195*1000)/'Egg Data'!JW195,"") | AM195: 7 | AP195: =AN195-AO195 | AQ195: =AP195/AM195 | AR195: =IFERROR((AP195*1000)/'Egg Data'!MB195,"") | AT195: 7 | AW195: =AU195-AV195 | AX195: =AW195/AT195 | AY195: =IFERROR((AW195*1000)/'Egg Data'!OG195,"") | BA195: 7 | BD195: =BB195-BC195 | BE195: =BD195/BA195 | BF195: =IFERROR((BD195*1000)/'Egg Data'!QL195,"") | BH195: 7 | BK195: =BI195-BJ195 | BL195: =BK195/BH195 | BM195: =IFERROR((BK195*1000)/'Egg Data'!SQ195,"") | BO195: 7 | BR195: =BP195-BQ195 | BS195: =BR195/BO195 | BT195: =IFERROR((BR195*1000)/'Egg Data'!UV195,"")

Sheet Mortalities
A1: Week | B1: Date | C1: Pen | D1: Weight | E1: Reason

Sheet Body Weights
A1: PEN NO | B1: HEN NO | C1: WEIGHT | F1: PEN NO | G1: HEN NO | H1: WEIGHT
A2: 1 | B2: A | F2: 25 | G2: A
A3: 1 | B3: B | F3: 25 | G3: B
A4: 1 | B4: C | F4: 25 | G4: C
A5: 1 | B5: D | F5: 25 | G5: D
A6: 1 | B6: E | F6: 25 | G6: E
A7: 1 | B7: F | F7: 25 | G7: F
A8: 1 | B8: G | F8: 25 | G8: G
A9: 2 | B9: A | F9: 26 | G9: A
A10: 2 | B10: B | F10: 26 | G10: B
A11: 2 | B11: C | F11: 26 | G11: C
A12: 2 | B12: D | F12: 26 | G12: D
A13: 2 | B13: E | F13: 26 | G13: E
... A169: 24 | B169: G | F169: 48 | G169: G
A171: PEN NO | B171: HEN NO | F171: PEN NO | G171: HEN NO
A172: 49 | B172: A | F172: 73 | G172: A
A173: 49 | B173: B | F173: 73 | G173: B
A174: 49 | B174: C | F174: 73 | G174: C
A175: 49 | B175: D | F175: 73 | G175: D
A176: 49 | B176: E | F176: 73 | G176: E
A177: 49 | B177: F | F177: 73 | G177: F
A178: 49 | B178: G | F178: 73 | G178: G
A179: 50 | B179: A | F179: 74 | G179: A
A180: 50 | B180: B | F180: 74 | G180: B
A181: 50 | B181: C | F181: 74 | G181: C
A182: 50 | B182: D | F182: 74 | G182: D
A183: 50 | B183: E | F183: 74 | G183: E
... A339: 72 | B339: G | F339: 96 | G339: G
A341: PEN NO | B341: HEN NO | F341: PEN NO | G341: HEN NO
A342: 97 | B342: A | F342: 121 | G342: A
A343: 97 | B343: B | F343: 121 | G343: B
A344: 97 | B344: C | F344: 121 | G344: C
A345: 97 | B345: D | F345: 121 | G345: D
A346: 97 | B346: E | F346: 121 | G346: E
A347: 97 | B347: F | F347: 121 | G347: F
A348: 97 | B348: G | F348: 121 | G348: G
A349: 98 | B349: A | F349: 122 | G349: A
A350: 98 | B350: B | F350: 122 | G350: B
A351: 98 | B351: C | F351: 122 | G351: C
A352: 98 | B352: D | F352: 122 | G352: D
...

Sheet Egg Quality
A1: Month | B1: Date | C1: Pen | D1: Egg | E1: Individual Egg weight | F1: Diameter | G1: Height | H1: top | I1: bottom | J1: equater | K1: Force at Break (Standard) | L1: Displacement at Break (Standard)

Sheet Slaughter
A1: Month | B1: Date | C1: Pen | D1: Bird | E1: Body Weight (kg) | F1: Fat Pad (g) | G1: Liver (g)

Sheet Defeathering
A1: Month | B1: Date | C1: Pen | D1: Bird | E1: Weight (kg)

Sheet Not yet placed
