Workbook

Sheet Pen trt 
A1: Pen | B1: Treatment
A2: 1 | B2: 1
A3: 2 | B3: 9
A4: 3 | B4: 17
A5: 4 | B5: 25
A6: 5 | B6: 28
A7: 6 | B7: 4
A8: 7 | B8: 12
A9: 8 | B9: 20
A10: 9 | B10: 32
A11: 10 | B11: 8
A12: 11 | B12: 16
A13: 12 | B13: 24
... A193: 192 | B193: 29

Sheet Egg Data
C1: 46237 | J1: 46238 | Q1: 46239 | X1: 46240 | AE1: 46241 | AL1: 46242 | AS1: 46243 | AZ1: 1W | BH1: 46244 | BO1: 46245 | BV1: 46246 | CC1: 46247 | CJ1: 46248 | CQ1: 46249 | CX1: 46250 | DE1: 2W | DM1: 46251 | DT1: 46252 | EA1: 46253 | EH1: 46254 | EO1: 46255 | EV1: 46256 | FC1: 46257 | FJ1: 3W | FR1: 46258 | FY1: 46259 | GF1: 46260 | GM1: 46261 | GT1: 46262 | HA1: 46263 | HH1: 46264 | HO1: 4W | HW1: 46265 | ID1: 46266 | IK1: 46267 | IR1: 46268 | IY1: 46269 | JF1: 46270 | JM1: 46271 | JT1: 5W | KB1: 46272 | KI1: 46273 | KP1: 46274 | KW1: 46275 | LD1: 46276 | LK1: 46277 | LR1: 46278 | LY1: 6W | MG1: 46279 | MN1: 46280 | MU1: 46281 | NB1: 46282 | NI1: 46283 | NP1: 46284 | NW1: 46285 | OD1: 7W | OL1: 46286 | OS1: 46287 | OZ1: 46288 | PG1: 46289 | PN1: 46290 | PU1: 46291 | QB1: 46292 | QI1: 8W | QQ1: 46293 | QX1: 46294 | RE1: 46295 | RL1: 46296 | RS1: 46297 | RZ1: 46298 | SG1: 46299 | SN1: 9W | SV1: 46300 | TC1: 46301 | TJ1: 46302 | TQ1: 46303 | TX1: 46304 | UE1: 46305 | UL1: 46306 | US1: 10W | VA1: 46307 | VH1: 46308 | VO1: 46309 | VV1: 46310 | WC1: 46311 | WJ1: 46312 | WQ1: 46313 | WX1: 11W | XF1: 46314 | XM1: 46315 | XT1: 46316 | YA1: 46317 | YH1: 46318 | YO1: 46319 | YV1: 46320 | ZC1: 12W | ZK1: 46321 | ZR1: 46322 | ZY1: 46323 | AAF1: 46324 | AAM1: 46325 | AAT1: 46326 | ABA1: 46327 | ABH1: 13W | ABP1: 46328 | ABW1: 46329 | ACD1: 46330 | ACK1: 46331 | ACR1: 46332 | ACY1: 46333 | ADF1: 46334 | ADM1: 14W | ADU1: 46335 | AEB1: 46336 | AEI1: 46337 | AEP1: 46338 | AEW1: 46339 | AFD1: 46340 | AFK1: 46341 | AFR1: 15W | AFZ1: 46342 | AGG1: 46343 | AGN1: 46344 | AGU1: 46345 | AHB1: 46346 | AHI1: 46347 | AHP1: 46348 | AHW1: 16W | AIE1: 46349 | AIL1: 46350 | AIS1: 46351 | AIZ1: 46352 | AJG1: 46353 | AJN1: 46354 | AJU1: 46355 | AKB1: 17W | AKJ1: 46356 | AKQ1: 46357 | AKX1: 46358 | ALE1: 46359 | ALL1: 46360 | ALS1: 46361 | ALZ1: 46362 | AMG1: 18W | AMO1: 46363 | AMV1: 46364 | ANC1: 46365 | ANJ1: 46366 | ANQ1: 46367 | ANX1: 46368 | AOE1: 46369 | AOL1: 19W | AOT1: 46370 | APA1: 46371 | APH1: 46372 | APO1: 46373 | APV1: 46374 | AQC1: 46375 | AQJ1: 46376 | AQQ1: 20W | AQY1: 46377 | ARF1: 46378 | ARM1: 46379 | ART1: 46380 | ASA1: 46381 | ASH1: 46382 | ASO1: 46383 | ASV1: 21W | ATD1: 46384 | ATK1: 46385 | ATR1: 46386 | ATY1: 46387 | AUF1: 46388 | AUM1: 46389 | AUT1: 46390 | AVA1: 22W | AVI1: 46391 | AVP1: 46392 | AVW1: 46393 | AWD1: 46394 | AWK1: 46395 | AWR1: 46396 | AWY1: 46397 | AXF1: 23W | AXN1: 46398 | AXU1: 46399 | AYB1: 46400 | AYI1: 46401 | AYP1: 46402 | AYW1: 46403 | AZD1: 46404 | AZK1: 24W | AZS1: 46405 | AZZ1: 46406 | BAG1: 46407 | BAN1: 46408 | BAU1: 46409 | BBB1: 46410 | BBI1: 46411 | BBP1: 25W | BBX1: 46412 | BCE1: 46413 | BCL1: 46414 | BCS1: 46415 | BCZ1: 46416 | BDG1: 46417 | BDN1: 46418 | BDU1: 26W | BEC1: 46419 | BEJ1: 46420 | BEQ1: 46421 | BEX1: 46422 | BFE1: 46423 | BFL1: 46424 | BFS1: 46425 | BFZ1: 27W | BGH1: 46426 | BGO1: 46427 | BGV1: 46428 | BHC1: 46429 | BHJ1: 46430 | BHQ1: 46431 | BHX1: 46432 | BIE1: 28W | BIM1: 46433 | BIT1: 46434 | BJA1: 46435 | BJH1: 46436 | BJO1: 46437 | BJV1: 46438 | BKC1: 46439 | BKJ1: 29W | BKR1: 46440 | BKY1: 46441 | BLF1: 46442 | BLM1: 46443 | BLT1: 46444 | BMA1: 46445 | BMH1: 46446 | BMO1: 30W | BMW1: 46447 | BND1: 46448 | BNK1: 46449 | BNR1: 46450 | BNY1: 46451 | BOF1: 46452 | BOM1: 46453 | BOT1: 31W | BPB1: 46454 | BPI1: 46455 | BPP1: 46456 | BPW1: 46457 | BQD1: 46458 | BQK1: 46459 | BQR1: 46460 | BQY1: 32W | BRG1: 46461 | BRN1: 46462 | BRU1: 46463 | BSB1: 46464 | BSI1: 46465 | BSP1: 46466 | BSW1: 46467 | BTD1: 33W | BTL1: 46468 | BTS1: 46469 | BTZ1: 46470 | BUG1: 46471 | BUN1: 46472 | BUU1: 46473 | BVB1: 46474 | BVI1: 34W | BVQ1: 46475 | BVX1: 46476 | BWE1: 46477 | BWL1: 46478 | BWS1: 46479 | BWZ1: 46480 | BXG1: 46481 | BXN1: 35W | BXV1: 46482 | BYC1: 46483 | BYJ1: 46484 | BYQ1: 46485 | BYX1: 46486 | BZE1: 46487 | BZL1: 46488 | BZS1: 36W
C2: 1W | J2: 1W | Q2: 1W | X2: 1W | AE2: 1W | AL2: 1W | AS2: 1W | BH2: 2W | BO2: 2W | BV2: 2W | CC2: 2W | CJ2: 2W | CQ2: 2W | CX2: 2W | DM2: 3W | DT2: 3W | EA2: 3W | EH2: 3W | EO2: 3W | EV2: 3W | FC2: 3W | FR2: 4W | FY2: 4W | GF2: 4W | GM2: 4W | GT2: 4W | HA2: 4W | HH2: 4W | HW2: 5W | ID2: 5W | IK2: 5W | IR2: 5W | IY2: 5W | JF2: 5W | JM2: 5W | KB2: 6W | KI2: 6W | KP2: 6W | KW2: 6W | LD2: 6W | LK2: 6W | LR2: 6W | MG2: 7W | MN2: 7W | MU2: 7W | NB2: 7W | NI2: 7W | NP2: 7W | NW2: 7W | OL2: 8W | OS2: 8W | OZ2: 8W | PG2: 8W | PN2: 8W | PU2: 8W | QB2: 8W | QQ2: 9W | QX2: 9W | RE2: 9W | RL2: 9W | RS2: 9W | RZ2: 9W | SG2: 9W | SV2: 10W | TC2: 10W | TJ2: 10W | TQ2: 10W | TX2: 10W | UE2: 10W | UL2: 10W | VA2: 11W | VH2: 11W | VO2: 11W | VV2: 11W | WC2: 11W | WJ2: 11W | WQ2: 11W | XF2: 12W | XM2: 12W | XT2: 12W | YA2: 12W | YH2: 12W | YO2: 12W | YV2: 12W | ZK2: 13W | ZR2: 13W | ZY2: 13W | AAF2: 13W | AAM2: 13W | AAT2: 13W | ABA2: 13W | ABP2: 14W | ABW2: 14W | ACD2: 14W | ACK2: 14W | ACR2: 14W | ACY2: 14W | ADF2: 14W | ADU2: 15W | AEB2: 15W | AEI2: 15W | AEP2: 15W | AEW2: 15W | AFD2: 15W | AFK2: 15W | AFZ2: 16W | AGG2: 16W | AGN2: 16W | AGU2: 16W | AHB2: 16W | AHI2: 16W | AHP2: 16W | AIE2: 17W | AIL2: 17W | AIS2: 17W | AIZ2: 17W | AJG2: 17W | AJN2: 17W | AJU2: 17W | AKJ2: 18W | AKQ2: 18W | AKX2: 18W | ALE2: 18W | ALL2: 18W | ALS2: 18W | ALZ2: 18W | AMO2: 19W | AMV2: 19W | ANC2: 19W | ANJ2: 19W | ANQ2: 19W | ANX2: 19W | AOE2: 19W | AOT2: 20W | APA2: 20W | APH2: 20W | APO2: 20W | APV2: 20W | AQC2: 20W | AQJ2: 20W | AQY2: 21W | ARF2: 21W | ARM2: 21W | ART2: 21W | ASA2: 21W | ASH2: 21W | ASO2: 21W | ATD2: 22W | ATK2: 22W | ATR2: 22W | ATY2: 22W | AUF2: 22W | AUM2: 22W | AUT2: 22W | AVI2: 23W | AVP2: 23W | AVW2: 23W | AWD2: 23W | AWK2: 23W | AWR2: 23W | AWY2: 23W | AXN2: 24W | AXU2: 24W | AYB2: 24W | AYI2: 24W | AYP2: 24W | AYW2: 24W | AZD2: 24W | AZS2: 25W | AZZ2: 25W | BAG2: 25W | BAN2: 25W | BAU2: 25W | BBB2: 25W | BBI2: 25W | BBX2: 26W | BCE2: 26W | BCL2: 26W | BCS2: 26W | BCZ2: 26W | BDG2: 26W | BDN2: 26W | BEC2: 27W | BEJ2: 27W | BEQ2: 27W | BEX2: 27W | BFE2: 27W | BFL2: 27W | BFS2: 27W | BGH2: 28W | BGO2: 28W | BGV2: 28W | BHC2: 28W | BHJ2: 28W | BHQ2: 28W | BHX2: 28W | BIM2: 29W | BIT2: 29W | BJA2: 29W | BJH2: 29W | BJO2: 29W | BJV2: 29W | BKC2: 29W | BKR2: 30W | BKY2: 30W | BLF2: 30W | BLM2: 30W | BLT2: 30W | BMA2: 30W | BMH2: 30W | BMW2: 31W | BND2: 31W | BNK2: 31W | BNR2: 31W | BNY2: 31W | BOF2: 31W | BOM2: 31W | BPB2: 32W | BPI2: 32W | BPP2: 32W | BPW2: 32W | BQD2: 32W | BQK2: 32W | BQR2: 32W | BRG2: 33W | BRN2: 33W | BRU2: 33W | BSB2: 33W | BSI2: 33W | BSP2: 33W | BSW2: 33W | BTL2: 34W | BTS2: 34W | BTZ2: 34W | BUG2: 34W | BUN2: 34W | BUU2: 34W | BVB2: 34W | BVQ2: 35W | BVX2: 35W | BWE2: 35W | BWL2: 35W | BWS2: 35W | BWZ2: 35W | BXG2: 35W | BXV2: 36W | BYC2: 36W | BYJ2: 36W | BYQ2: 36W | BYX2: 36W | BZE2: 36W | BZL2: 36W
A3: Pen Number | B3: Treatment Number | C3: Number of Eggs | D3: Weight | E3: Average Weight | F3: Non Layer | G3: Number of Rejects | H3: Reason | J3: Number of Eggs | K3: Weight | L3: Average Weight | M3: Non Layer | N3: Number of Rejects | O3: Reason | Q3: Number of Eggs | R3: Weight | S3: Average Weight | T3: Non Layer | U3: Number of Rejects | V3: Reason | X3: Number of Eggs | Y3: Weight | Z3: Average Weight | AA3: Non Layer | AB3: Number of Rejects | AC3: Reason | AE3: Number of Eggs | AF3: Weight | AG3: Average Weight | AH3: Non Layer | AI3: Number of Rejects | AJ3: Reason | AL3: Number of Eggs | AM3: Weight | AN3: Average Weight | AO3: Non Layer | AP3: Number of Rejects | AQ3: Reason | AS3: Number of Eggs | AT3: Weight | AU3: Average Weight | AV3: Non Layer | AW3: Number of Rejects | AX3: Reason | AZ3: Bird # | BA3: Number of Eggs | BB3: Ave eggs | BC3: Weight | BD3: Average Weight | BE3: Number of Rejects | BF3: %HDE_ | BH3: Number of Eggs | BI3: Weight | BJ3: Average Weight | BK3: Non Layer | BL3: Number of Rejects | BM3: Reason | BO3: Number of Eggs | BP3: Weight | BQ3: Average Weight | BR3: Non Layer | BS3: Number of Rejects | BT3: Reason | BV3: Number of Eggs | BW3: Weight | BX3: Average Weight | BY3: Non Layer | BZ3: Number of Rejects | CA3: Reason | CC3: Number of Eggs | CD3: Weight | CE3: Average Weight | CF3: Non Layer | CG3: Number of Rejects | CH3: Reason | CJ3: Number of Eggs | CK3: Weight | CL3: Average Weight | CM3: Non Layer | CN3: Number of Rejects | CO3: Reason | CQ3: Number of Eggs | CR3: Weight | CS3: Average Weight | CT3: Non Layer | CU3: Number of Rejects | CV3: Reason | CX3: Number of Eggs | CY3: Weight | CZ3: Average Weight | DA3: Non Layer | DB3: Number of Rejects | DC3: Reason | DE3: Bird # | DF3: Number of Eggs | DG3: Ave eggs | DH3: Weight | DI3: Average Weight | DJ3: Number of Rejects | DK3: %HDE_ | DM3: Number of Eggs | DN3: Weight | DO3: Average Weight | DP3: Non Layer | DQ3: Number of Rejects | DR3: Reason | DT3: Number of Eggs | DU3: Weight | DV3: Average Weight | DW3: Non Layer | DX3: Number of Rejects | DY3: Reason | EA3: Number of Eggs | EB3: Weight | EC3: Average Weight | ED3: Non Layer | EE3: Number of Rejects | EF3: Reason | EH3: Number of Eggs | EI3: Weight | EJ3: Average Weight | EK3: Non Layer | EL3: Number of Rejects | EM3: Reason | EO3: Number of Eggs | EP3: Weight | EQ3: Average Weight | ER3: Non Layer | ES3: Number of Rejects | ET3: Reason | EV3: Number of Eggs | EW3: Weight | EX3: Average Weight | EY3: Non Layer | EZ3: Number of Rejects | FA3: Reason | FC3: Number of Eggs | FD3: Weight | FE3: Average Weight | FF3: Non Layer | FG3: Number of Rejects | FH3: Reason | FJ3: Bird # | FK3: Number of Eggs | FL3: Ave eggs | FM3: Weight | FN3: Average Weight | FO3: Number of Rejects | FP3: %HDE_ | FR3: Number of Eggs | FS3: Weight | FT3: Average Weight | FU3: Non Layer | FV3: Number of Rejects | FW3: Reason | FY3: Number of Eggs | FZ3: Weight | GA3: Average Weight | GB3: Non Layer | GC3: Number of Rejects | GD3: Reason | GF3: Number of Eggs | GG3: Weight | GH3: Average Weight | GI3: Non Layer | GJ3: Number of Rejects | GK3: Reason | GM3: Number of Eggs | GN3: Weight | GO3: Average Weight | GP3: Non Layer | GQ3: Number of Rejects | GR3: Reason | GT3: Number of Eggs | GU3: Weight | GV3: Average Weight | GW3: Non Layer | GX3: Number of Rejects | GY3: Reason | HA3: Number of Eggs | HB3: Weight | HC3: Average Weight | HD3: Non Layer | HE3: Number of Rejects | HF3: Reason | HH3: Number of Eggs | HI3: Weight | HJ3: Average Weight | HK3: Non Layer | HL3: Number of Rejects | HM3: Reason | HO3: Bird # | HP3: Number of Eggs | HQ3: Ave eggs | HR3: Weight | HS3: Average Weight | HT3: Number of Rejects | HU3: %HDE_ | HW3: Number of Eggs | HX3: Weight | HY3: Average Weight | HZ3: Non Layer | IA3: Number of Rejects | IB3: Reason | ID3: Number of Eggs | IE3: Weight | IF3: Average Weight | IG3: Non Layer | IH3: Number of Rejects | II3: Reason | IK3: Number of Eggs | IL3: Weight | IM3: Average Weight | IN3: Non Layer | IO3: Number of Rejects | IP3: Reason | IR3: Number of Eggs | IS3: Weight | IT3: Average Weight | IU3: Non Layer | IV3: Number of Rejects | IW3: Reason | IY3: Number of Eggs | IZ3: Weight | JA3: Average Weight | JB3: Non Layer | JC3: Number of Rejects | JD3: Reason | JF3: Number of Eggs | JG3: Weight | JH3: Average Weight | JI3: Non Layer | JJ3: Number of Rejects | JK3: Reason | JM3: Number of Eggs | JN3: Weight | JO3: Average Weight | JP3: Non Layer | JQ3: Number of Rejects | JR3: Reason | JT3: Bird # | JU3: Number of Eggs | JV3: Ave eggs | JW3: Weight | JX3: Average Weight | JY3: Number of Rejects | JZ3: %HDE_ | KB3: Number of Eggs | KC3: Weight | KD3: Average Weight | KE3: Non Layer | KF3: Number of Rejects | KG3: Reason | KI3: Number of Eggs | KJ3: Weight | KK3: Average Weight | KL3: Non Layer | KM3: Number of Rejects | KN3: Reason | KP3: Number of Eggs | KQ3: Weight | KR3: Average Weight | KS3: Non Layer | KT3: Number of Rejects | KU3: Reason | KW3: Number of Eggs | KX3: Weight | KY3: Average Weight | KZ3: Non Layer | LA3: Number of Rejects | LB3: Reason | LD3: Number of Eggs | LE3: Weight | LF3: Average Weight | LG3: Non Layer | LH3: Number of Rejects | LI3: Reason | LK3: Number of Eggs | LL3: Weight | LM3: Average Weight | LN3: Non Layer | LO3: Number of Rejects | LP3: Reason | LR3: Number of Eggs | LS3: Weight | LT3: Average Weight | LU3: Non Layer | LV3: Number of Rejects | LW3: Reason | LY3: Bird # | LZ3: Number of Eggs | MA3: Ave eggs | MB3: Weight | MC3: Average Weight | MD3: Number of Rejects | ME3: %HDE_ | MG3: Number of Eggs | MH3: Weight | MI3: Average Weight | MJ3: Non Layer | MK3: Number of Rejects | ML3: Reason | MN3: Number of Eggs | MO3: Weight | MP3: Average Weight | MQ3: Non Layer | MR3: Number of Rejects | MS3: Reason | MU3: Number of Eggs | MV3: Weight | MW3: Average Weight | MX3: Non Layer | MY3: Number of Rejects | MZ3: Reason | NB3: Number of Eggs | NC3: Weight | ND3: Average Weight | NE3: Non Layer | NF3: Number of Rejects | NG3: Reason | NI3: Number of Eggs | NJ3: Weight | NK3: Average Weight | NL3: Non Layer | NM3: Number of Rejects | NN3: Reason | NP3: Number of Eggs | NQ3: Weight | NR3: Average Weight | NS3: Non Layer | NT3: Number of Rejects | NU3: Reason | NW3: Number of Eggs | NX3: Weight | NY3: Average Weight | NZ3: Non Layer | OA3: Number of Rejects | OB3: Reason | OD3: Bird # | OE3: Number of Eggs | OF3: Ave eggs | OG3: Weight | OH3: Average Weight | OI3: Number of Rejects | OJ3: %HDE_ | OL3: Number of Eggs | OM3: Weight | ON3: Average Weight | OO3: Non Layer | OP3: Number of Rejects | OQ3: Reason | OS3: Number of Eggs | OT3: Weight | OU3: Average Weight | OV3: Non Layer | OW3: Number of Rejects | OX3: Reason | OZ3: Number of Eggs | PA3: Weight | PB3: Average Weight | PC3: Non Layer | PD3: Number of Rejects | PE3: Reason | PG3: Number of Eggs | PH3: Weight | PI3: Average Weight | PJ3: Non Layer | PK3: Number of Rejects | PL3: Reason | PN3: Number of Eggs | PO3: Weight | PP3: Average Weight | PQ3: Non Layer | PR3: Number of Rejects | PS3: Reason | PU3: Number of Eggs | PV3: Weight | PW3: Average Weight | PX3: Non Layer | PY3: Number of Rejects | PZ3: Reason | QB3: Number of Eggs | QC3: Weight | QD3: Average Weight | QE3: Non Layer | QF3: Number of Rejects | QG3: Reason | QI3: Bird # | QJ3: Number of Eggs | QK3: Ave eggs | QL3: Weight | QM3: Average Weight | QN3: Number of Rejects | QO3: %HDE_ | QQ3: Number of Eggs | QR3: Weight | QS3: Average Weight | QT3: Non Layer | QU3: Number of Rejects | QV3: Reason | QX3: Number of Eggs | QY3: Weight | QZ3: Average Weight | RA3: Non Layer | RB3: Number of Rejects | RC3: Reason | RE3: Number of Eggs | RF3: Weight | RG3: Average Weight | RH3: Non Layer | RI3: Number of Rejects | RJ3: Reason | RL3: Number of Eggs | RM3: Weight | RN3: Average Weight | RO3: Non Layer | RP3: Number of Rejects | RQ3: Reason | RS3: Number of Eggs | RT3: Weight | RU3: Average Weight | RV3: Non Layer | RW3: Number of Rejects | RX3: Reason | RZ3: Number of Eggs | SA3: Weight | SB3: Average Weight | SC3: Non Layer | SD3: Number of Rejects | SE3: Reason | SG3: Number of Eggs | SH3: Weight | SI3: Average Weight | SJ3: Non Layer | SK3: Number of Rejects | SL3: Reason | SN3: Bird # | SO3: Number of Eggs | SP3: Ave eggs | SQ3: Weight | SR3: Average Weight | SS3: Number of Rejects | ST3: %HDE_ | SV3: Number of Eggs | SW3: Weight | SX3: Average Weight | SY3: Non Layer | SZ3: Number of Rejects | TA3: Reason | TC3: Number of Eggs | TD3: Weight | TE3: Average Weight | TF3: Non Layer | TG3: Number of Rejects | TH3: Reason | TJ3: Number of Eggs | TK3: Weight | TL3: Average Weight | TM3: Non Layer | TN3: Number of Rejects | TO3: Reason | TQ3: Number of Eggs | TR3: Weight | TS3: Average Weight | TT3: Non Layer | TU3: Number of Rejects | TV3: Reason | TX3: Number of Eggs | TY3: Weight | TZ3: Average Weight | UA3: Non Layer | UB3: Number of Rejects | UC3: Reason | UE3: Number of Eggs | UF3: Weight | UG3: Average Weight | UH3: Non Layer | UI3: Number of Rejects | UJ3: Reason | UL3: Number of Eggs | UM3: Weight | UN3: Average Weight | UO3: Non Layer | UP3: Number of Rejects | UQ3: Reason | US3: Bird # | UT3: Number of Eggs | UU3: Ave eggs | UV3: Weight | UW3: Average Weight | UX3: Number of Rejects | UY3: %HDE_ | VA3: Number of Eggs | VB3: Weight | VC3: Average Weight | VD3: Non Layer | VE3: Number of Rejects | VF3: Reason | VH3: Number of Eggs | VI3: Weight | VJ3: Average Weight | VK3: Non Layer | VL3: Number of Rejects | VM3: Reason | VO3: Number of Eggs | VP3: Weight | VQ3: Average Weight | VR3: Non Layer | VS3: Number of Rejects | VT3: Reason | VV3: Number of Eggs | VW3: Weight | VX3: Average Weight | VY3: Non Layer | VZ3: Number of Rejects | WA3: Reason | WC3: Number of Eggs | WD3: Weight | WE3: Average Weight | WF3: Non Layer | WG3: Number of Rejects | WH3: Reason | WJ3: Number of Eggs | WK3: Weight | WL3: Average Weight | WM3: Non Layer | WN3: Number of Rejects | WO3: Reason | WQ3: Number of Eggs | WR3: Weight | WS3: Average Weight | WT3: Non Layer | WU3: Number of Rejects | WV3: Reason | WX3: Bird # | WY3: Number of Eggs | WZ3: Ave eggs | XA3: Weight | XB3: Average Weight | XC3: Number of Rejects | XD3: %HDE_ | XF3: Number of Eggs | XG3: Weight | XH3: Average Weight | XI3: Non Layer | XJ3: Number of Rejects | XK3: Reason | XM3: Number of Eggs | XN3: Weight | XO3: Average Weight | XP3: Non Layer | XQ3: Number of Rejects | XR3: Reason | XT3: Number of Eggs | XU3: Weight | XV3: Average Weight | XW3: Non Layer | XX3: Number of Rejects | XY3: Reason | YA3: Number of Eggs | YB3: Weight | YC3: Average Weight | YD3: Non Layer | YE3: Number of Rejects | YF3: Reason | YH3: Number of Eggs | YI3: Weight | YJ3: Average Weight | YK3: Non Layer | YL3: Number of Rejects | YM3: Reason | YO3: Number of Eggs | YP3: Weight | YQ3: Average Weight | YR3: Non Layer | YS3: Number of Rejects | YT3: Reason | YV3: Number of Eggs | YW3: Weight | YX3: Average Weight | YY3: Non Layer | YZ3: Number of Rejects | ZA3: Reason | ZC3: Bird # | ZD3: Number of Eggs | ZE3: Ave eggs | ZF3: Weight | ZG3: Average Weight | ZH3: Number of Rejects | ZI3: %HDE_ | ZK3: Number of Eggs | ZL3: Weight | ZM3: Average Weight | ZN3: Non Layer | ZO3: Number of Rejects | ZP3: Reason | ZR3: Number of Eggs | ZS3: Weight | ZT3: Average Weight | ZU3: Non Layer | ZV3: Number of Rejects | ZW3: Reason | ZY3: Number of Eggs | ZZ3: Weight | AAA3: Average Weight | AAB3: Non Layer | AAC3: Number of Rejects | AAD3: Reason | AAF3: Number of Eggs | AAG3: Weight | AAH3: Average Weight | AAI3: Non Layer | AAJ3: Number of Rejects | AAK3: Reason | AAM3: Number of Eggs | AAN3: Weight | AAO3: Average Weight | AAP3: Non Layer | AAQ3: Number of Rejects | AAR3: Reason | AAT3: Number of Eggs | AAU3: Weight | AAV3: Average Weight | AAW3: Non Layer | AAX3: Number of Rejects | AAY3: Reason | ABA3: Number of Eggs | ABB3: Weight | ABC3: Average Weight | ABD3: Non Layer | ABE3: Number of Rejects | ABF3: Reason | ABH3: Bird # | ABI3: Number of Eggs | ABJ3: Ave eggs | ABK3: Weight | ABL3: Average Weight | ABM3: Number of Rejects | ABN3: %HDE_ | ABP3: Number of Eggs | ABQ3: Weight | ABR3: Average Weight | ABS3: Non Layer | ABT3: Number of Rejects | ABU3: Reason | ABW3: Number of Eggs | ABX3: Weight | ABY3: Average Weight | ABZ3: Non Layer | ACA3: Number of Rejects | ACB3: Reason | ACD3: Number of Eggs | ACE3: Weight | ACF3: Average Weight | ACG3: Non Layer | ACH3: Number of Rejects | ACI3: Reason | ACK3: Number of Eggs | ACL3: Weight | ACM3: Average Weight | ACN3: Non Layer | ACO3: Number of Rejects | ACP3: Reason | ACR3: Number of Eggs | ACS3: Weight | ACT3: Average Weight | ACU3: Non Layer | ACV3: Number of Rejects | ACW3: Reason | ACY3: Number of Eggs | ACZ3: Weight | ADA3: Average Weight | ADB3: Non Layer | ADC3: Number of Rejects | ADD3: Reason | ADF3: Number of Eggs | ADG3: Weight | ADH3: Average Weight | ADI3: Non Layer | ADJ3: Number of Rejects | ADK3: Reason | ADM3: Bird # | ADN3: Number of Eggs | ADO3: Ave eggs | ADP3: Weight | ADQ3: Average Weight | ADR3: Number of Rejects | ADS3: %HDE_ | ADU3: Number of Eggs | ADV3: Weight | ADW3: Average Weight | ADX3: Non Layer | ADY3: Number of Rejects | ADZ3: Reason | AEB3: Number of Eggs | AEC3: Weight | AED3: Average Weight | AEE3: Non Layer | AEF3: Number of Rejects | AEG3: Reason | AEI3: Number of Eggs | AEJ3: Weight | AEK3: Average Weight | AEL3: Non Layer | AEM3: Number of Rejects | AEN3: Reason | AEP3: Number of Eggs | AEQ3: Weight | AER3: Average Weight | AES3: Non Layer | AET3: Number of Rejects | AEU3: Reason | AEW3: Number of Eggs | AEX3: Weight | AEY3: Average Weight | AEZ3: Non Layer | AFA3: Number of Rejects | AFB3: Reason | AFD3: Number of Eggs | AFE3: Weight | AFF3: Average Weight | AFG3: Non Layer | AFH3: Number of Rejects | AFI3: Reason | AFK3: Number of Eggs | AFL3: Weight | AFM3: Average Weight | AFN3: Non Layer | AFO3: Number of Rejects | AFP3: Reason | AFR3: Bird # | AFS3: Number of Eggs | AFT3: Ave eggs | AFU3: Weight | AFV3: Average Weight | AFW3: Number of Rejects | AFX3: %HDE_ | AFZ3: Number of Eggs | AGA3: Weight | AGB3: Average Weight | AGC3: Non Layer | AGD3: Number of Rejects | AGE3: Reason | AGG3: Number of Eggs | AGH3: Weight | AGI3: Average Weight | AGJ3: Non Layer | AGK3: Number of Rejects | AGL3: Reason | AGN3: Number of Eggs | AGO3: Weight | AGP3: Average Weight | AGQ3: Non Layer | AGR3: Number of Rejects | AGS3: Reason | AGU3: Number of Eggs | AGV3: Weight | AGW3: Average Weight | AGX3: Non Layer | AGY3: Number of Rejects | AGZ3: Reason | AHB3: Number of Eggs | AHC3: Weight | AHD3: Average Weight | AHE3: Non Layer | AHF3: Number of Rejects | AHG3: Reason | AHI3: Number of Eggs | AHJ3: Weight | AHK3: Average Weight | AHL3: Non Layer | AHM3: Number of Rejects | AHN3: Reason | AHP3: Number of Eggs | AHQ3: Weight | AHR3: Average Weight | AHS3: Non Layer | AHT3: Number of Rejects | AHU3: Reason | AHW3: Bird # | AHX3: Number of Eggs | AHY3: Ave eggs | AHZ3: Weight | AIA3: Average Weight | AIB3: Number of Rejects | AIC3: %HDE_ | AIE3: Number of Eggs | AIF3: Weight | AIG3: Average Weight | AIH3: Non Layer | AII3: Number of Rejects | AIJ3: Reason | AIL3: Number of Eggs | AIM3: Weight | AIN3: Average Weight | AIO3: Non Layer | AIP3: Number of Rejects | AIQ3: Reason | AIS3: Number of Eggs | AIT3: Weight | AIU3: Average Weight | AIV3: Non Layer | AIW3: Number of Rejects | AIX3: Reason | AIZ3: Number of Eggs | AJA3: Weight | AJB3: Average Weight | AJC3: Non Layer | AJD3: Number of Rejects | AJE3: Reason | AJG3: Number of Eggs | AJH3: Weight | AJI3: Average Weight | AJJ3: Non Layer | AJK3: Number of Rejects | AJL3: Reason | AJN3: Number of Eggs | AJO3: Weight | AJP3: Average Weight | AJQ3: Non Layer | AJR3: Number of Rejects | AJS3: Reason | AJU3: Number of Eggs | AJV3: Weight | AJW3: Average Weight | AJX3: Non Layer | AJY3: Number of Rejects | AJZ3: Reason | AKB3: Bird # | AKC3: Number of Eggs | AKD3: Ave eggs | AKE3: Weight | AKF3: Average Weight | AKG3: Number of Rejects | AKH3: %HDE_ | AKJ3: Number of Eggs | AKK3: Weight | AKL3: Average Weight | AKM3: Non Layer | AKN3: Number of Rejects | AKO3: Reason | AKQ3: Number of Eggs | AKR3: Weight | AKS3: Average Weight | AKT3: Non Layer | AKU3: Number of Rejects | AKV3: Reason | AKX3: Number of Eggs | AKY3: Weight | AKZ3: Average Weight | ALA3: Non Layer | ALB3: Number of Rejects | ALC3: Reason | ALE3: Number of Eggs | ALF3: Weight | ALG3: Average Weight | ALH3: Non Layer | ALI3: Number of Rejects | ALJ3: Reason | ALL3: Number of Eggs | ALM3: Weight | ALN3: Average Weight | ALO3: Non Layer | ALP3: Number of Rejects | ALQ3: Reason | ALS3: Number of Eggs | ALT3: Weight | ALU3: Average Weight | ALV3: Non Layer | ALW3: Number of Rejects | ALX3: Reason | ALZ3: Number of Eggs | AMA3: Weight | AMB3: Average Weight | AMC3: Non Layer | AMD3: Number of Rejects | AME3: Reason | AMG3: Bird # | AMH3: Number of Eggs | AMI3: Ave eggs | AMJ3: Weight | AMK3: Average Weight | AML3: Number of Rejects | AMM3: %HDE_ | AMO3: Number of Eggs | AMP3: Weight | AMQ3: Average Weight | AMR3: Non Layer | AMS3: Number of Rejects | AMT3: Reason | AMV3: Number of Eggs | AMW3: Weight | AMX3: Average Weight | AMY3: Non Layer | AMZ3: Number of Rejects | ANA3: Reason | ANC3: Number of Eggs | AND3: Weight | ANE3: Average Weight | ANF3: Non Layer | ANG3: Number of Rejects | ANH3: Reason | ANJ3: Number of Eggs | ANK3: Weight | ANL3: Average Weight | ANM3: Non Layer | ANN3: Number of Rejects | ANO3: Reason | ANQ3: Number of Eggs | ANR3: Weight | ANS3: Average Weight | ANT3: Non Layer | ANU3: Number of Rejects | ANV3: Reason | ANX3: Number of Eggs | ANY3: Weight | ANZ3: Average Weight | AOA3: Non Layer | AOB3: Number of Rejects | AOC3: Reason | AOE3: Number of Eggs | AOF3: Weight | AOG3: Average Weight | AOH3: Non Layer | AOI3: Number of Rejects | AOJ3: Reason | AOL3: Bird # | AOM3: Number of Eggs | AON3: Ave eggs | AOO3: Weight | AOP3: Average Weight | AOQ3: Number of Rejects | AOR3: %HDE_ | AOT3: Number of Eggs | AOU3: Weight | AOV3: Average Weight | AOW3: Non Layer | AOX3: Number of Rejects | AOY3: Reason | APA3: Number of Eggs | APB3: Weight | APC3: Average Weight | APD3: Non Layer | APE3: Number of Rejects | APF3: Reason | APH3: Number of Eggs | API3: Weight | APJ3: Average Weight | APK3: Non Layer | APL3: Number of Rejects | APM3: Reason | APO3: Number of Eggs | APP3: Weight | APQ3: Average Weight | APR3: Non Layer | APS3: Number of Rejects | APT3: Reason | APV3: Number of Eggs | APW3: Weight | APX3: Average Weight | APY3: Non Layer | APZ3: Number of Rejects | AQA3: Reason | AQC3: Number of Eggs | AQD3: Weight | AQE3: Average Weight | AQF3: Non Layer | AQG3: Number of Rejects | AQH3: Reason | AQJ3: Number of Eggs | AQK3: Weight | AQL3: Average Weight | AQM3: Non Layer | AQN3: Number of Rejects | AQO3: Reason | AQQ3: Bird # | AQR3: Number of Eggs | AQS3: Ave eggs | AQT3: Weight | AQU3: Average Weight | AQV3: Number of Rejects | AQW3: %HDE_ | AQY3: Number of Eggs | AQZ3: Weight | ARA3: Average Weight | ARB3: Non Layer | ARC3: Number of Rejects | ARD3: Reason | ARF3: Number of Eggs | ARG3: Weight | ARH3: Average Weight | ARI3: Non Layer | ARJ3: Number of Rejects | ARK3: Reason | ARM3: Number of Eggs | ARN3: Weight | ARO3: Average Weight | ARP3: Non Layer | ARQ3: Number of Rejects | ARR3: Reason | ART3: Number of Eggs | ARU3: Weight | ARV3: Average Weight | ARW3: Non Layer | ARX3: Number of Rejects | ARY3: Reason | ASA3: Number of Eggs | ASB3: Weight | ASC3: Average Weight | ASD3: Non Layer | ASE3: Number of Rejects | ASF3: Reason | ASH3: Number of Eggs | ASI3: Weight | ASJ3: Average Weight | ASK3: Non Layer | ASL3: Number of Rejects | ASM3: Reason | ASO3: Number of Eggs | ASP3: Weight | ASQ3: Average Weight | ASR3: Non Layer | ASS3: Number of Rejects | AST3: Reason | ASV3: Bird # | ASW3: Number of Eggs | ASX3: Ave eggs | ASY3: Weight | ASZ3: Average Weight | ATA3: Number of Rejects | ATB3: %HDE_ | ATD3: Number of Eggs | ATE3: Weight | ATF3: Average Weight | ATG3: Non Layer | ATH3: Number of Rejects | ATI3: Reason | ATK3: Number of Eggs | ATL3: Weight | ATM3: Average Weight | ATN3: Non Layer | ATO3: Number of Rejects | ATP3: Reason | ATR3: Number of Eggs | ATS3: Weight | ATT3: Average Weight | ATU3: Non Layer | ATV3: Number of Rejects | ATW3: Reason | ATY3: Number of Eggs | ATZ3: Weight | AUA3: Average Weight | AUB3: Non Layer | AUC3: Number of Rejects | AUD3: Reason | AUF3: Number of Eggs | AUG3: Weight | AUH3: Average Weight | AUI3: Non Layer | AUJ3: Number of Rejects | AUK3: Reason | AUM3: Number of Eggs | AUN3: Weight | AUO3: Average Weight | AUP3: Non Layer | AUQ3: Number of Rejects | AUR3: Reason | AUT3: Number of Eggs | AUU3: Weight | AUV3: Average Weight | AUW3: Non Layer | AUX3: Number of Rejects | AUY3: Reason | AVA3: Bird # | AVB3: Number of Eggs | AVC3: Ave eggs | AVD3: Weight | AVE3: Average Weight | AVF3: Number of Rejects | AVG3: %HDE_ | AVI3: Number of Eggs | AVJ3: Weight | AVK3: Average Weight | AVL3: Non Layer | AVM3: Number of Rejects | AVN3: Reason | AVP3: Number of Eggs | AVQ3: Weight | AVR3: Average Weight | AVS3: Non Layer | AVT3: Number of Rejects | AVU3: Reason | AVW3: Number of Eggs | AVX3: Weight | AVY3: Average Weight | AVZ3: Non Layer | AWA3: Number of Rejects | AWB3: Reason | AWD3: Number of Eggs | AWE3: Weight | AWF3: Average Weight | AWG3: Non Layer | AWH3: Number of Rejects | AWI3: Reason | AWK3: Number of Eggs | AWL3: Weight | AWM3: Average Weight | AWN3: Non Layer | AWO3: Number of Rejects | AWP3: Reason | AWR3: Number of Eggs | AWS3: Weight | AWT3: Average Weight | AWU3: Non Layer | AWV3: Number of Rejects | AWW3: Reason | AWY3: Number of Eggs | AWZ3: Weight | AXA3: Average Weight | AXB3: Non Layer | AXC3: Number of Rejects | AXD3: Reason | AXF3: Bird # | AXG3: Number of Eggs | AXH3: Ave eggs | AXI3: Weight | AXJ3: Average Weight | AXK3: Number of Rejects | AXL3: %HDE_ | AXN3: Number of Eggs | AXO3: Weight | AXP3: Average Weight | AXQ3: Non Layer | AXR3: Number of Rejects | AXS3: Reason | AXU3: Number of Eggs | AXV3: Weight | AXW3: Average Weight | AXX3: Non Layer | AXY3: Number of Rejects | AXZ3: Reason | AYB3: Number of Eggs | AYC3: Weight | AYD3: Average Weight | AYE3: Non Layer | AYF3: Number of Rejects | AYG3: Reason | AYI3: Number of Eggs | AYJ3: Weight | AYK3: Average Weight | AYL3: Non Layer | AYM3: Number of Rejects | AYN3: Reason | AYP3: Number of Eggs | AYQ3: Weight | AYR3: Average Weight | AYS3: Non Layer | AYT3: Number of Rejects | AYU3: Reason | AYW3: Number of Eggs | AYX3: Weight | AYY3: Average Weight | AYZ3: Non Layer | AZA3: Number of Rejects | AZB3: Reason | AZD3: Number of Eggs | AZE3: Weight | AZF3: Average Weight | AZG3: Non Layer | AZH3: Number of Rejects | AZI3: Reason | AZK3: Bird # | AZL3: Number of Eggs | AZM3: Ave eggs | AZN3: Weight | AZO3: Average Weight | AZP3: Number of Rejects | AZQ3: %HDE_ | AZS3: Number of Eggs | AZT3: Weight | AZU3: Average Weight | AZV3: Non Layer | AZW3: Number of Rejects | AZX3: Reason | AZZ3: Number of Eggs | BAA3: Weight | BAB3: Average Weight | BAC3: Non Layer | BAD3: Number of Rejects | BAE3: Reason | BAG3: Number of Eggs | BAH3: Weight | BAI3: Average Weight | BAJ3: Non Layer | BAK3: Number of Rejects | BAL3: Reason | BAN3: Number of Eggs | BAO3: Weight | BAP3: Average Weight | BAQ3: Non Layer | BAR3: Number of Rejects | BAS3: Reason | BAU3: Number of Eggs | BAV3: Weight | BAW3: Average Weight | BAX3: Non Layer | BAY3: Number of Rejects | BAZ3: Reason | BBB3: Number of Eggs | BBC3: Weight | BBD3: Average Weight | BBE3: Non Layer | BBF3: Number of Rejects | BBG3: Reason | BBI3: Number of Eggs | BBJ3: Weight | BBK3: Average Weight | BBL3: Non Layer | BBM3: Number of Rejects | BBN3: Reason | BBP3: Bird # | BBQ3: Number of Eggs | BBR3: Ave eggs | BBS3: Weight | BBT3: Average Weight | BBU3: Number of Rejects | BBV3: %HDE_ | BBX3: Number of Eggs | BBY3: Weight | BBZ3: Average Weight | BCA3: Non Layer | BCB3: Number of Rejects | BCC3: Reason | BCE3: Number of Eggs | BCF3: Weight | BCG3: Average Weight | BCH3: Non Layer | BCI3: Number of Rejects | BCJ3: Reason | BCL3: Number of Eggs | BCM3: Weight | BCN3: Average Weight | BCO3: Non Layer | BCP3: Number of Rejects | BCQ3: Reason | BCS3: Number of Eggs | BCT3: Weight | BCU3: Average Weight | BCV3: Non Layer | BCW3: Number of Rejects | BCX3: Reason | BCZ3: Number of Eggs | BDA3: Weight | BDB3: Average Weight | BDC3: Non Layer | BDD3: Number of Rejects | BDE3: Reason | BDG3: Number of Eggs | BDH3: Weight | BDI3: Average Weight | BDJ3: Non Layer | BDK3: Number of Rejects | BDL3: Reason | BDN3: Number of Eggs | BDO3: Weight | BDP3: Average Weight | BDQ3: Non Layer | BDR3: Number of Rejects | BDS3: Reason | BDU3: Bird # | BDV3: Number of Eggs | BDW3: Ave eggs | BDX3: Weight | BDY3: Average Weight | BDZ3: Number of Rejects | BEA3: %HDE_ | BEC3: Number of Eggs | BED3: Weight | BEE3: Average Weight | BEF3: Non Layer | BEG3: Number of Rejects | BEH3: Reason | BEJ3: Number of Eggs | BEK3: Weight | BEL3: Average Weight | BEM3: Non Layer | BEN3: Number of Rejects | BEO3: Reason | BEQ3: Number of Eggs | BER3: Weight | BES3: Average Weight | BET3: Non Layer | BEU3: Number of Rejects | BEV3: Reason | BEX3: Number of Eggs | BEY3: Weight | BEZ3: Average Weight | BFA3: Non Layer | BFB3: Number of Rejects | BFC3: Reason | BFE3: Number of Eggs | BFF3: Weight | BFG3: Average Weight | BFH3: Non Layer | BFI3: Number of Rejects | BFJ3: Reason | BFL3: Number of Eggs | BFM3: Weight | BFN3: Average Weight | BFO3: Non Layer | BFP3: Number of Rejects | BFQ3: Reason | BFS3: Number of Eggs | BFT3: Weight | BFU3: Average Weight | BFV3: Non Layer | BFW3: Number of Rejects | BFX3: Reason | BFZ3: Bird # | BGA3: Number of Eggs | BGB3: Ave eggs | BGC3: Weight | BGD3: Average Weight | BGE3: Number of Rejects | BGF3: %HDE_ | BGH3: Number of Eggs | BGI3: Weight | BGJ3: Average Weight | BGK3: Non Layer | BGL3: Number of Rejects | BGM3: Reason | BGO3: Number of Eggs | BGP3: Weight | BGQ3: Average Weight | BGR3: Non Layer | BGS3: Number of Rejects | BGT3: Reason | BGV3: Number of Eggs | BGW3: Weight | BGX3: Average Weight | BGY3: Non Layer | BGZ3: Number of Rejects | BHA3: Reason | BHC3: Number of Eggs | BHD3: Weight | BHE3: Average Weight | BHF3: Non Layer | BHG3: Number of Rejects | BHH3: Reason | BHJ3: Number of Eggs | BHK3: Weight | BHL3: Average Weight | BHM3: Non Layer | BHN3: Number of Rejects | BHO3: Reason | BHQ3: Number of Eggs | BHR3: Weight | BHS3: Average Weight | BHT3: Non Layer | BHU3: Number of Rejects | BHV3: Reason | BHX3: Number of Eggs | BHY3: Weight | BHZ3: Average Weight | BIA3: Non Layer | BIB3: Number of Rejects | BIC3: Reason | BIE3: Bird # | BIF3: Number of Eggs | BIG3: Ave eggs | BIH3: Weight | BII3: Average Weight | BIJ3: Number of Rejects | BIK3: %HDE_ | BIM3: Number of Eggs | BIN3: Weight | BIO3: Average Weight | BIP3: Non Layer | BIQ3: Number of Rejects | BIR3: Reason | BIT3: Number of Eggs | BIU3: Weight | BIV3: Average Weight | BIW3: Non Layer | BIX3: Number of Rejects | BIY3: Reason | BJA3: Number of Eggs | BJB3: Weight | BJC3: Average Weight | BJD3: Non Layer | BJE3: Number of Rejects | BJF3: Reason | BJH3: Number of Eggs | BJI3: Weight | BJJ3: Average Weight | BJK3: Non Layer | BJL3: Number of Rejects | BJM3: Reason | BJO3: Number of Eggs | BJP3: Weight | BJQ3: Average Weight | BJR3: Non Layer | BJS3: Number of Rejects | BJT3: Reason | BJV3: Number of Eggs | BJW3: Weight | BJX3: Average Weight | BJY3: Non Layer | BJZ3: Number of Rejects | BKA3: Reason | BKC3: Number of Eggs | BKD3: Weight | BKE3: Average Weight | BKF3: Non Layer | BKG3: Number of Rejects | BKH3: Reason | BKJ3: Bird # | BKK3: Number of Eggs | BKL3: Ave eggs | BKM3: Weight | BKN3: Average Weight | BKO3: Number of Rejects | BKP3: %HDE_ | BKR3: Number of Eggs | BKS3: Weight | BKT3: Average Weight | BKU3: Non Layer | BKV3: Number of Rejects | BKW3: Reason | BKY3: Number of Eggs | BKZ3: Weight | BLA3: Average Weight | BLB3: Non Layer | BLC3: Number of Rejects | BLD3: Reason | BLF3: Number of Eggs | BLG3: Weight | BLH3: Average Weight | BLI3: Non Layer | BLJ3: Number of Rejects | BLK3: Reason | BLM3: Number of Eggs | BLN3: Weight | BLO3: Average Weight | BLP3: Non Layer | BLQ3: Number of Rejects | BLR3: Reason | BLT3: Number of Eggs | BLU3: Weight | BLV3: Average Weight | BLW3: Non Layer | BLX3: Number of Rejects | BLY3: Reason | BMA3: Number of Eggs | BMB3: Weight | BMC3: Average Weight | BMD3: Non Layer | BME3: Number of Rejects | BMF3: Reason | BMH3: Number of Eggs | BMI3: Weight | BMJ3: Average Weight | BMK3: Non Layer | BML3: Number of Rejects | BMM3: Reason | BMO3: Bird # | BMP3: Number of Eggs | BMQ3: Ave eggs | BMR3: Weight | BMS3: Average Weight | BMT3: Number of Rejects | BMU3: %HDE_ | BMW3: Number of Eggs | BMX3: Weight | BMY3: Average Weight | BMZ3: Non Layer | BNA3: Number of Rejects | BNB3: Reason | BND3: Number of Eggs | BNE3: Weight | BNF3: Average Weight | BNG3: Non Layer | BNH3: Number of Rejects | BNI3: Reason | BNK3: Number of Eggs | BNL3: Weight | BNM3: Average Weight | BNN3: Non Layer | BNO3: Number of Rejects | BNP3: Reason | BNR3: Number of Eggs | BNS3: Weight | BNT3: Average Weight | BNU3: Non Layer | BNV3: Number of Rejects | BNW3: Reason | BNY3: Number of Eggs | BNZ3: Weight | BOA3: Average Weight | BOB3: Non Layer | BOC3: Number of Rejects | BOD3: Reason | BOF3: Number of Eggs | BOG3: Weight | BOH3: Average Weight | BOI3: Non Layer | BOJ3: Number of Rejects | BOK3: Reason | BOM3: Number of Eggs | BON3: Weight | BOO3: Average Weight | BOP3: Non Layer | BOQ3: Number of Rejects | BOR3: Reason | BOT3: Bird # | BOU3: Number of Eggs | BOV3: Ave eggs | BOW3: Weight | BOX3: Average Weight | BOY3: Number of Rejects | BOZ3: %HDE_ | BPB3: Number of Eggs | BPC3: Weight | BPD3: Average Weight | BPE3: Non Layer | BPF3: Number of Rejects | BPG3: Reason | BPI3: Number of Eggs | BPJ3: Weight | BPK3: Average Weight | BPL3: Non Layer | BPM3: Number of Rejects | BPN3: Reason | BPP3: Number of Eggs | BPQ3: Weight | BPR3: Average Weight | BPS3: Non Layer | BPT3: Number of Rejects | BPU3: Reason | BPW3: Number of Eggs | BPX3: Weight | BPY3: Average Weight | BPZ3: Non Layer | BQA3: Number of Rejects | BQB3: Reason | BQD3: Number of Eggs | BQE3: Weight | BQF3: Average Weight | BQG3: Non Layer | BQH3: Number of Rejects | BQI3: Reason | BQK3: Number of Eggs | BQL3: Weight | BQM3: Average Weight | BQN3: Non Layer | BQO3: Number of Rejects | BQP3: Reason | BQR3: Number of Eggs | BQS3: Weight | BQT3: Average Weight | BQU3: Non Layer | BQV3: Number of Rejects | BQW3: Reason | BQY3: Bird # | BQZ3: Number of Eggs | BRA3: Ave eggs | BRB3: Weight | BRC3: Average Weight | BRD3: Number of Rejects | BRE3: %HDE_ | BRG3: Number of Eggs | BRH3: Weight | BRI3: Average Weight | BRJ3: Non Layer | BRK3: Number of Rejects | BRL3: Reason | BRN3: Number of Eggs | BRO3: Weight | BRP3: Average Weight | BRQ3: Non Layer | BRR3: Number of Rejects | BRS3: Reason | BRU3: Number of Eggs | BRV3: Weight | BRW3: Average Weight | BRX3: Non Layer | BRY3: Number of Rejects | BRZ3: Reason | BSB3: Number of Eggs | BSC3: Weight | BSD3: Average Weight | BSE3: Non Layer | BSF3: Number of Rejects | BSG3: Reason | BSI3: Number of Eggs | BSJ3: Weight | BSK3: Average Weight | BSL3: Non Layer | BSM3: Number of Rejects | BSN3: Reason | BSP3: Number of Eggs | BSQ3: Weight | BSR3: Average Weight | BSS3: Non Layer | BST3: Number of Rejects | BSU3: Reason | BSW3: Number of Eggs | BSX3: Weight | BSY3: Average Weight | BSZ3: Non Layer | BTA3: Number of Rejects | BTB3: Reason | BTD3: Bird # | BTE3: Number of Eggs | BTF3: Ave eggs | BTG3: Weight | BTH3: Average Weight | BTI3: Number of Rejects | BTJ3: %HDE_ | BTL3: Number of Eggs | BTM3: Weight | BTN3: Average Weight | BTO3: Non Layer | BTP3: Number of Rejects | BTQ3: Reason | BTS3: Number of Eggs | BTT3: Weight | BTU3: Average Weight | BTV3: Non Layer | BTW3: Number of Rejects | BTX3: Reason | BTZ3: Number of Eggs | BUA3: Weight | BUB3: Average Weight | BUC3: Non Layer | BUD3: Number of Rejects | BUE3: Reason | BUG3: Number of Eggs | BUH3: Weight | BUI3: Average Weight | BUJ3: Non Layer | BUK3: Number of Rejects | BUL3: Reason | BUN3: Number of Eggs | BUO3: Weight | BUP3: Average Weight | BUQ3: Non Layer | BUR3: Number of Rejects | BUS3: Reason | BUU3: Number of Eggs | BUV3: Weight | BUW3: Average Weight | BUX3: Non Layer | BUY3: Number of Rejects | BUZ3: Reason | BVB3: Number of Eggs | BVC3: Weight | BVD3: Average Weight | BVE3: Non Layer | BVF3: Number of Rejects | BVG3: Reason | BVI3: Bird # | BVJ3: Number of Eggs | BVK3: Ave eggs | BVL3: Weight | BVM3: Average Weight | BVN3: Number of Rejects | BVO3: %HDE_ | BVQ3: Number of Eggs | BVR3: Weight | BVS3: Average Weight | BVT3: Non Layer | BVU3: Number of Rejects | BVV3: Reason | BVX3: Number of Eggs | BVY3: Weight | BVZ3: Average Weight | BWA3: Non Layer | BWB3: Number of Rejects | BWC3: Reason | BWE3: Number of Eggs | BWF3: Weight | BWG3: Average Weight | BWH3: Non Layer | BWI3: Number of Rejects | BWJ3: Reason | BWL3: Number of Eggs | BWM3: Weight | BWN3: Average Weight | BWO3: Non Layer | BWP3: Number of Rejects | BWQ3: Reason | BWS3: Number of Eggs | BWT3: Weight | BWU3: Average Weight | BWV3: Non Layer | BWW3: Number of Rejects | BWX3: Reason | BWZ3: Number of Eggs | BXA3: Weight | BXB3: Average Weight | BXC3: Non Layer | BXD3: Number of Rejects | BXE3: Reason | BXG3: Number of Eggs | BXH3: Weight | BXI3: Average Weight | BXJ3: Non Layer | BXK3: Number of Rejects | BXL3: Reason | BXN3: Bird # | BXO3: Number of Eggs | BXP3: Ave eggs | BXQ3: Weight | BXR3: Average Weight | BXS3: Number of Rejects | BXT3: %HDE_ | BXV3: Number of Eggs | BXW3: Weight | BXX3: Average Weight | BXY3: Non Layer | BXZ3: Number of Rejects | BYA3: Reason | BYC3: Number of Eggs | BYD3: Weight | BYE3: Average Weight | BYF3: Non Layer | BYG3: Number of Rejects | BYH3: Reason | BYJ3: Number of Eggs | BYK3: Weight | BYL3: Average Weight | BYM3: Non Layer | BYN3: Number of Rejects | BYO3: Reason | BYQ3: Number of Eggs | BYR3: Weight | BYS3: Average Weight | BYT3: Non Layer | BYU3: Number of Rejects | BYV3: Reason | BYX3: Number of Eggs | BYY3: Weight | BYZ3: Average Weight | BZA3: Non Layer | BZB3: Number of Rejects | BZC3: Reason | BZE3: Number of Eggs | BZF3: Weight | BZG3: Average Weight | BZH3: Non Layer | BZI3: Number of Rejects | BZJ3: Reason | BZL3: Number of Eggs | BZM3: Weight | BZN3: Average Weight | BZO3: Non Layer | BZP3: Number of Rejects | BZQ3: Reason | BZS3: Bird # | BZT3: Number of Eggs | BZU3: Ave eggs | BZV3: Weight | BZW3: Average Weight | BZX3: Number of Rejects | BZY3: %HDE_
A4: 1 | AZ4: 7 | BA4: =C4+J4+Q4+X4+AE4+AL4+AS4 | BB4: =IFERROR(BA4/AZ4/7,"") | BC4: =D4+K4+R4+Y4+AF4+AM4+AT4 | BD4: =IFERROR(BC4/BA4,"") | BE4: =G4+N4+U4+AB4+AI4+AP4+AW4 | BF4: =IFERROR(BA4/AZ4/7,"") | DE4: 7 | DF4: =BH4+BO4+BV4+CC4+CJ4+CQ4+CX4 | DG4: =IFERROR(DF4/DE4/7,"") | DH4: =BI4+BP4+BW4+CD4+CK4+CR4+CY4 | DI4: =IFERROR(DH4/DF4,"") | DJ4: =BL4+BS4+BZ4+CG4+CN4+CU4+DB4 | DK4: =IFERROR(DF4/DE4/7,"") | FJ4: 7 | FK4: =DM4+DT4+EA4+EH4+EO4+EV4+FC4 | FL4: =IFERROR(FK4/FJ4/7,"") | FM4: =DN4+DU4+EB4+EI4+EP4+EW4+FD4 | FN4: =IFERROR(FM4/FK4,"") | FO4: =DQ4+DX4+EE4+EL4+ES4+EZ4+FG4 | FP4: =IFERROR(FK4/FJ4/7,"") | HO4: 7 | HP4: =FR4+FY4+GF4+GM4+GT4+HA4+HH4 | HQ4: =IFERROR(HP4/HO4/7,"") | HR4: =FS4+FZ4+GG4+GN4+GU4+HB4+HI4 | HS4: =IFERROR(HR4/HP4,"") | HT4: =FV4+GC4+GJ4+GQ4+GX4+HE4+HL4 | HU4: =IFERROR(HP4/HO4/7,"") | JT4: 7 | JU4: =HW4+ID4+IK4+IR4+IY4+JF4+JM4 | JV4: =IFERROR(JU4/JT4/7,"") | JW4: =HX4+IE4+IL4+IS4+IZ4+JG4+JN4 | JX4: =IFERROR(JW4/JU4,"") | JY4: =IA4+IH4+IO4+IV4+JC4+JJ4+JQ4 | JZ4: =IFERROR(JU4/JT4/7,"") | LY4: 7 | LZ4: =KB4+KI4+KP4+KW4+LD4+LK4+LR4 | MA4: =IFERROR(LZ4/LY4/7,"") | MB4: =KC4+KJ4+KQ4+KX4+LE4+LL4+LS4 | MC4: =IFERROR(MB4/LZ4,"") | MD4: =KF4+KM4+KT4+LA4+LH4+LO4+LV4 | ME4: =IFERROR(LZ4/LY4/7,"") | OD4: 7 | OE4: =MG4+MN4+MU4+NB4+NI4+NP4+NW4 | OF4: =IFERROR(OE4/OD4/7,"") | OG4: =MH4+MO4+MV4+NC4+NJ4+NQ4+NX4 | OH4: =IFERROR(OG4/OE4,"") | OI4: =MK4+MR4+MY4+NF4+NM4+NT4+OA4 | OJ4: =IFERROR(OE4/OD4/7,"") | QI4: 7 | QJ4: =OL4+OS4+OZ4+PG4+PN4+PU4+QB4 | QK4: =IFERROR(QJ4/QI4/7,"") | QL4: =OM4+OT4+PA4+PH4+PO4+PV4+QC4 | QM4: =IFERROR(QL4/QJ4,"") | QN4: =OP4+OW4+PD4+PK4+PR4+PY4+QF4 | QO4: =IFERROR(QJ4/QI4/7,"") | SN4: 7 | SO4: =QQ4+QX4+RE4+RL4+RS4+RZ4+SG4 | SP4: =IFERROR(SO4/SN4/7,"") | SQ4: =QR4+QY4+RF4+RM4+RT4+SA4+SH4 | SR4: =IFERROR(SQ4/SO4,"") | SS4: =QU4+RB4+RI4+RP4+RW4+SD4+SK4 | ST4: =IFERROR(SO4/SN4/7,"") | US4: 7 | UT4: =SV4+TC4+TJ4+TQ4+TX4+UE4+UL4 | UU4: =IFERROR(UT4/US4/7,"") | UV4: =SW4+TD4+TK4+TR4+TY4+UF4+UM4 | UW4: =IFERROR(UV4/UT4,"") | UX4: =SZ4+TG4+TN4+TU4+UB4+UI4+UP4 | UY4: =IFERROR(UT4/US4/7,"") | WX4: 7 | WY4: =VA4+VH4+VO4+VV4+WC4+WJ4+WQ4 | WZ4: =IFERROR(WY4/WX4/7,"") | XA4: =VB4+VI4+VP4+VW4+WD4+WK4+WR4 | XB4: =IFERROR(XA4/WY4,"") | XC4: =VE4+VL4+VS4+VZ4+WG4+WN4+WU4 | XD4: =IFERROR(WY4/WX4/7,"") | ZC4: 7 | ZD4: =XF4+XM4+XT4+YA4+YH4+YO4+YV4 | ZE4: =IFERROR(ZD4/ZC4/7,"") | ZF4: =XG4+XN4+XU4+YB4+YI4+YP4+YW4 | ZG4: =IFERROR(ZF4/ZD4,"") | ZH4: =XJ4+XQ4+XX4+YE4+YL4+YS4+YZ4 | ZI4: =IFERROR(ZD4/ZC4/7,"") | ABH4: 7 | ABI4: =ZK4+ZR4+ZY4+AAF4+AAM4+AAT4+ABA4 | ABJ4: =IFERROR(ABI4/ABH4/7,"") | ABK4: =ZL4+ZS4+ZZ4+AAG4+AAN4+AAU4+ABB4 | ABL4: =IFERROR(ABK4/ABI4,"") | ABM4: =ZO4+ZV4+AAC4+AAJ4+AAQ4+AAX4+ABE4 | ABN4: =IFERROR(ABI4/ABH4/7,"") | ADM4: 7 | ADN4: =ABP4+ABW4+ACD4+ACK4+ACR4+ACY4+ADF4 | ADO4: =IFERROR(ADN4/ADM4/7,"") | ADP4: =ABQ4+ABX4+ACE4+ACL4+ACS4+ACZ4+ADG4 | ADQ4: =IFERROR(ADP4/ADN4,"") | ADR4: =ABT4+ACA4+ACH4+ACO4+ACV4+ADC4+ADJ4 | ADS4: =IFERROR(ADN4/ADM4/7,"") | AFR4: 7 | AFS4: =ADU4+AEB4+AEI4+AEP4+AEW4+AFD4+AFK4 | AFT4: =IFERROR(AFS4/AFR4/7,"") | AFU4: =ADV4+AEC4+AEJ4+AEQ4+AEX4+AFE4+AFL4 | AFV4: =IFERROR(AFU4/AFS4,"") | AFW4: =ADY4+AEF4+AEM4+AET4+AFA4+AFH4+AFO4 | AFX4: =IFERROR(AFS4/AFR4/7,"") | AHW4: 7 | AHX4: =AFZ4+AGG4+AGN4+AGU4+AHB4+AHI4+AHP4 | AHY4: =IFERROR(AHX4/AHW4/7,"") | AHZ4: =AGA4+AGH4+AGO4+AGV4+AHC4+AHJ4+AHQ4 | AIA4: =IFERROR(AHZ4/AHX4,"") | AIB4: =AGD4+AGK4+AGR4+AGY4+AHF4+AHM4+AHT4 | AIC4: =IFERROR(AHX4/AHW4/7,"") | AKB4: 7 | AKC4: =AIE4+AIL4+AIS4+AIZ4+AJG4+AJN4+AJU4 | AKD4: =IFERROR(AKC4/AKB4/7,"") | AKE4: =AIF4+AIM4+AIT4+AJA4+AJH4+AJO4+AJV4 | AKF4: =IFERROR(AKE4/AKC4,"") | AKG4: =AII4+AIP4+AIW4+AJD4+AJK4+AJR4+AJY4 | AKH4: =IFERROR(AKC4/AKB4/7,"") | AMG4: 7 | AMH4: =AKJ4+AKQ4+AKX4+ALE4+ALL4+ALS4+ALZ4 | AMI4: =IFERROR(AMH4/AMG4/7,"") | AMJ4: =AKK4+AKR4+AKY4+ALF4+ALM4+ALT4+AMA4 | AMK4: =IFERROR(AMJ4/AMH4,"") | AML4: =AKN4+AKU4+ALB4+ALI4+ALP4+ALW4+AMD4 | AMM4: =IFERROR(AMH4/AMG4/7,"") | AOL4: 7 | AOM4: =AMO4+AMV4+ANC4+ANJ4+ANQ4+ANX4+AOE4 | AON4: =IFERROR(AOM4/AOL4/7,"") | AOO4: =AMP4+AMW4+AND4+ANK4+ANR4+ANY4+AOF4 | AOP4: =IFERROR(AOO4/AOM4,"") | AOQ4: =AMS4+AMZ4+ANG4+ANN4+ANU4+AOB4+AOI4 | AOR4: =IFERROR(AOM4/AOL4/7,"") | AQQ4: 7 | AQR4: =AOT4+APA4+APH4+APO4+APV4+AQC4+AQJ4 | AQS4: =IFERROR(AQR4/AQQ4/7,"") | AQT4: =AOU4+APB4+API4+APP4+APW4+AQD4+AQK4 | AQU4: =IFERROR(AQT4/AQR4,"") | AQV4: =AOX4+APE4+APL4+APS4+APZ4+AQG4+AQN4 | AQW4: =IFERROR(AQR4/AQQ4/7,"") | ASV4: 7 | ASW4: =AQY4+ARF4+ARM4+ART4+ASA4+ASH4+ASO4 | ASX4: =IFERROR(ASW4/ASV4/7,"") | ASY4: =AQZ4+ARG4+ARN4+ARU4+ASB4+ASI4+ASP4 | ASZ4: =IFERROR(ASY4/ASW4,"") | ATA4: =ARC4+ARJ4+ARQ4+ARX4+ASE4+ASL4+ASS4 | ATB4: =IFERROR(ASW4/ASV4/7,"") | AVA4: 7 | AVB4: =ATD4+ATK4+ATR4+ATY4+AUF4+AUM4+AUT4 | AVC4: =IFERROR(AVB4/AVA4/7,"") | AVD4: =ATE4+ATL4+ATS4+ATZ4+AUG4+AUN4+AUU4 | AVE4: =IFERROR(AVD4/AVB4,"") | AVF4: =ATH4+ATO4+ATV4+AUC4+AUJ4+AUQ4+AUX4 | AVG4: =IFERROR(AVB4/AVA4/7,"") | AXF4: 7 | AXG4: =AVI4+AVP4+AVW4+AWD4+AWK4+AWR4+AWY4 | AXH4: =IFERROR(AXG4/AXF4/7,"") | AXI4: =AVJ4+AVQ4+AVX4+AWE4+AWL4+AWS4+AWZ4 | AXJ4: =IFERROR(AXI4/AXG4,"") | AXK4: =AVM4+AVT4+AWA4+AWH4+AWO4+AWV4+AXC4 | AXL4: =IFERROR(AXG4/AXF4/7,"") | AZK4: 7 | AZL4: =AXN4+AXU4+AYB4+AYI4+AYP4+AYW4+AZD4 | AZM4: =IFERROR(AZL4/AZK4/7,"") | AZN4: =AXO4+AXV4+AYC4+AYJ4+AYQ4+AYX4+AZE4 | AZO4: =IFERROR(AZN4/AZL4,"") | AZP4: =AXR4+AXY4+AYF4+AYM4+AYT4+AZA4+AZH4 | AZQ4: =IFERROR(AZL4/AZK4/7,"") | BBP4: 7 | BBQ4: =AZS4+AZZ4+BAG4+BAN4+BAU4+BBB4+BBI4 | BBR4: =IFERROR(BBQ4/BBP4/7,"") | BBS4: =AZT4+BAA4+BAH4+BAO4+BAV4+BBC4+BBJ4 | BBT4: =IFERROR(BBS4/BBQ4,"") | BBU4: =AZW4+BAD4+BAK4+BAR4+BAY4+BBF4+BBM4 | BBV4: =IFERROR(BBQ4/BBP4/7,"") | BDU4: 7 | BDV4: =BBX4+BCE4+BCL4+BCS4+BCZ4+BDG4+BDN4 | BDW4: =IFERROR(BDV4/BDU4/7,"") | BDX4: =BBY4+BCF4+BCM4+BCT4+BDA4+BDH4+BDO4 | BDY4: =IFERROR(BDX4/BDV4,"") | BDZ4: =BCB4+BCI4+BCP4+BCW4+BDD4+BDK4+BDR4 | BEA4: =IFERROR(BDV4/BDU4/7,"") | BFZ4: 7 | BGA4: =BEC4+BEJ4+BEQ4+BEX4+BFE4+BFL4+BFS4 | BGB4: =IFERROR(BGA4/BFZ4/7,"") | BGC4: =BED4+BEK4+BER4+BEY4+BFF4+BFM4+BFT4 | BGD4: =IFERROR(BGC4/BGA4,"") | BGE4: =BEG4+BEN4+BEU4+BFB4+BFI4+BFP4+BFW4 | BGF4: =IFERROR(BGA4/BFZ4/7,"") | BIE4: 7 | BIF4: =BGH4+BGO4+BGV4+BHC4+BHJ4+BHQ4+BHX4 | BIG4: =IFERROR(BIF4/BIE4/7,"") | BIH4: =BGI4+BGP4+BGW4+BHD4+BHK4+BHR4+BHY4 | BII4: =IFERROR(BIH4/BIF4,"") | BIJ4: =BGL4+BGS4+BGZ4+BHG4+BHN4+BHU4+BIB4 | BIK4: =IFERROR(BIF4/BIE4/7,"") | BKJ4: 7 | BKK4: =BIM4+BIT4+BJA4+BJH4+BJO4+BJV4+BKC4 | BKL4: =IFERROR(BKK4/BKJ4/7,"") | BKM4: =BIN4+BIU4+BJB4+BJI4+BJP4+BJW4+BKD4 | BKN4: =IFERROR(BKM4/BKK4,"") | BKO4: =BIQ4+BIX4+BJE4+BJL4+BJS4+BJZ4+BKG4 | BKP4: =IFERROR(BKK4/BKJ4/7,"") | BMO4: 7 | BMP4: =BKR4+BKY4+BLF4+BLM4+BLT4+BMA4+BMH4 | BMQ4: =IFERROR(BMP4/BMO4/7,"") | BMR4: =BKS4+BKZ4+BLG4+BLN4+BLU4+BMB4+BMI4 | BMS4: =IFERROR(BMR4/BMP4,"") | BMT4: =BKV4+BLC4+BLJ4+BLQ4+BLX4+BME4+BML4 | BMU4: =IFERROR(BMP4/BMO4/7,"") | BOT4: 7 | BOU4: =BMW4+BND4+BNK4+BNR4+BNY4+BOF4+BOM4 | BOV4: =IFERROR(BOU4/BOT4/7,"") | BOW4: =BMX4+BNE4+BNL4+BNS4+BNZ4+BOG4+BON4 | BOX4: =IFERROR(BOW4/BOU4,"") | BOY4: =BNA4+BNH4+BNO4+BNV4+BOC4+BOJ4+BOQ4 | BOZ4: =IFERROR(BOU4/BOT4/7,"") | BQY4: 7 | BQZ4: =BPB4+BPI4+BPP4+BPW4+BQD4+BQK4+BQR4 | BRA4: =IFERROR(BQZ4/BQY4/7,"") | BRB4: =BPC4+BPJ4+BPQ4+BPX4+BQE4+BQL4+BQS4 | BRC4: =IFERROR(BRB4/BQZ4,"") | BRD4: =BPF4+BPM4+BPT4+BQA4+BQH4+BQO4+BQV4 | BRE4: =IFERROR(BQZ4/BQY4/7,"") | BTD4: 7 | BTE4: =BRG4+BRN4+BRU4+BSB4+BSI4+BSP4+BSW4 | BTF4: =IFERROR(BTE4/BTD4/7,"") | BTG4: =BRH4+BRO4+BRV4+BSC4+BSJ4+BSQ4+BSX4 | BTH4: =IFERROR(BTG4/BTE4,"") | BTI4: =BRK4+BRR4+BRY4+BSF4+BSM4+BST4+BTA4 | BTJ4: =IFERROR(BTE4/BTD4/7,"") | BVI4: 7 | BVJ4: =BTL4+BTS4+BTZ4+BUG4+BUN4+BUU4+BVB4 | BVK4: =IFERROR(BVJ4/BVI4/7,"") | BVL4: =BTM4+BTT4+BUA4+BUH4+BUO4+BUV4+BVC4 | BVM4: =IFERROR(BVL4/BVJ4,"") | BVN4: =BTP4+BTW4+BUD4+BUK4+BUR4+BUY4+BVF4 | BVO4: =IFERROR(BVJ4/BVI4/7,"") | BXN4: 7 | BXO4: =BVQ4+BVX4+BWE4+BWL4+BWS4+BWZ4+BXG4 | BXP4: =IFERROR(BXO4/BXN4/7,"") | BXQ4: =BVR4+BVY4+BWF4+BWM4+BWT4+BXA4+BXH4 | BXR4: =IFERROR(BXQ4/BXO4,"") | BXS4: =BVU4+BWB4+BWI4+BWP4+BWW4+BXD4+BXK4 | BXT4: =IFERROR(BXO4/BXN4/7,"") | BZS4: 7 | BZT4: =BXV4+BYC4+BYJ4+BYQ4+BYX4+BZE4+BZL4 | BZU4: =IFERROR(BZT4/BZS4/7,"") | BZV4: =BXW4+BYD4+BYK4+BYR4+BYY4+BZF4+BZM4 | BZW4: =IFERROR(BZV4/BZT4,"") | BZX4: =BXZ4+BYG4+BYN4+BYU4+BZB4+BZI4+BZP4 | BZY4: =IFERROR(BZT4/BZS4/7,"")
A5: 2 | AZ5: 7 | BA5: =C5+J5+Q5+X5+AE5+AL5+AS5 | BB5: =IFERROR(BA5/AZ5/7,"") | BC5: =D5+K5+R5+Y5+AF5+AM5+AT5 | BD5: =IFERROR(BC5/BA5,"") | BE5: =G5+N5+U5+AB5+AI5+AP5+AW5 | BF5: =IFERROR(BA5/AZ5/7,"") | DE5: 7 | DF5: =BH5+BO5+BV5+CC5+CJ5+CQ5+CX5 | DG5: =IFERROR(DF5/DE5/7,"") | DH5: =BI5+BP5+BW5+CD5+CK5+CR5+CY5 | DI5: =IFERROR(DH5/DF5,"") | DJ5: =BL5+BS5+BZ5+CG5+CN5+CU5+DB5 | DK5: =IFERROR(DF5/DE5/7,"") | FJ5: 7 | FK5: =DM5+DT5+EA5+EH5+EO5+EV5+FC5 | FL5: =IFERROR(FK5/FJ5/7,"") | FM5: =DN5+DU5+EB5+EI5+EP5+EW5+FD5 | FN5: =IFERROR(FM5/FK5,"") | FO5: =DQ5+DX5+EE5+EL5+ES5+EZ5+FG5 | FP5: =IFERROR(FK5/FJ5/7,"") | HO5: 7 | HP5: =FR5+FY5+GF5+GM5+GT5+HA5+HH5 | HQ5: =IFERROR(HP5/HO5/7,"") | HR5: =FS5+FZ5+GG5+GN5+GU5+HB5+HI5 | HS5: =IFERROR(HR5/HP5,"") | HT5: =FV5+GC5+GJ5+GQ5+GX5+HE5+HL5 | HU5: =IFERROR(HP5/HO5/7,"") | JT5: 7 | JU5: =HW5+ID5+IK5+IR5+IY5+JF5+JM5 | JV5: =IFERROR(JU5/JT5/7,"") | JW5: =HX5+IE5+IL5+IS5+IZ5+JG5+JN5 | JX5: =IFERROR(JW5/JU5,"") | JY5: =IA5+IH5+IO5+IV5+JC5+JJ5+JQ5 | JZ5: =IFERROR(JU5/JT5/7,"") | LY5: 7 | LZ5: =KB5+KI5+KP5+KW5+LD5+LK5+LR5 | MA5: =IFERROR(LZ5/LY5/7,"") | MB5: =KC5+KJ5+KQ5+KX5+LE5+LL5+LS5 | MC5: =IFERROR(MB5/LZ5,"") | MD5: =KF5+KM5+KT5+LA5+LH5+LO5+LV5 | ME5: =IFERROR(LZ5/LY5/7,"") | OD5: 7 | OE5: =MG5+MN5+MU5+NB5+NI5+NP5+NW5 | OF5: =IFERROR(OE5/OD5/7,"") | OG5: =MH5+MO5+MV5+NC5+NJ5+NQ5+NX5 | OH5: =IFERROR(OG5/OE5,"") | OI5: =MK5+MR5+MY5+NF5+NM5+NT5+OA5 | OJ5: =IFERROR(OE5/OD5/7,"") | QI5: 7 | QJ5: =OL5+OS5+OZ5+PG5+PN5+PU5+QB5 | QK5: =IFERROR(QJ5/QI5/7,"") | QL5: =OM5+OT5+PA5+PH5+PO5+PV5+QC5 | QM5: =IFERROR(QL5/QJ5,"") | QN5: =OP5+OW5+PD5+PK5+PR5+PY5+QF5 | QO5: =IFERROR(QJ5/QI5/7,"") | SN5: 7 | SO5: =QQ5+QX5+RE5+RL5+RS5+RZ5+SG5 | SP5: =IFERROR(SO5/SN5/7,"") | SQ5: =QR5+QY5+RF5+RM5+RT5+SA5+SH5 | SR5: =IFERROR(SQ5/SO5,"") | SS5: =QU5+RB5+RI5+RP5+RW5+SD5+SK5 | ST5: =IFERROR(SO5/SN5/7,"") | US5: 7 | UT5: =SV5+TC5+TJ5+TQ5+TX5+UE5+UL5 | UU5: =IFERROR(UT5/US5/7,"") | UV5: =SW5+TD5+TK5+TR5+TY5+UF5+UM5 | UW5: =IFERROR(UV5/UT5,"") | UX5: =SZ5+TG5+TN5+TU5+UB5+UI5+UP5 | UY5: =IFERROR(UT5/US5/7,"") | WX5: 7 | WY5: =VA5+VH5+VO5+VV5+WC5+WJ5+WQ5 | WZ5: =IFERROR(WY5/WX5/7,"") | XA5: =VB5+VI5+VP5+VW5+WD5+WK5+WR5 | XB5: =IFERROR(XA5/WY5,"") | XC5: =VE5+VL5+VS5+VZ5+WG5+WN5+WU5 | XD5: =IFERROR(WY5/WX5/7,"") | ZC5: 7 | ZD5: =XF5+XM5+XT5+YA5+YH5+YO5+YV5 | ZE5: =IFERROR(ZD5/ZC5/7,"") | ZF5: =XG5+XN5+XU5+YB5+YI5+YP5+YW5 | ZG5: =IFERROR(ZF5/ZD5,"") | ZH5: =XJ5+XQ5+XX5+YE5+YL5+YS5+YZ5 | ZI5: =IFERROR(ZD5/ZC5/7,"") | ABH5: 7 | ABI5: =ZK5+ZR5+ZY5+AAF5+AAM5+AAT5+ABA5 | ABJ5: =IFERROR(ABI5/ABH5/7,"") | ABK5: =ZL5+ZS5+ZZ5+AAG5+AAN5+AAU5+ABB5 | ABL5: =IFERROR(ABK5/ABI5,"") | ABM5: =ZO5+ZV5+AAC5+AAJ5+AAQ5+AAX5+ABE5 | ABN5: =IFERROR(ABI5/ABH5/7,"") | ADM5: 7 | ADN5: =ABP5+ABW5+ACD5+ACK5+ACR5+ACY5+ADF5 | ADO5: =IFERROR(ADN5/ADM5/7,"") | ADP5: =ABQ5+ABX5+ACE5+ACL5+ACS5+ACZ5+ADG5 | ADQ5: =IFERROR(ADP5/ADN5,"") | ADR5: =ABT5+ACA5+ACH5+ACO5+ACV5+ADC5+ADJ5 | ADS5: =IFERROR(ADN5/ADM5/7,"") | AFR5: 7 | AFS5: =ADU5+AEB5+AEI5+AEP5+AEW5+AFD5+AFK5 | AFT5: =IFERROR(AFS5/AFR5/7,"") | AFU5: =ADV5+AEC5+AEJ5+AEQ5+AEX5+AFE5+AFL5 | AFV5: =IFERROR(AFU5/AFS5,"") | AFW5: =ADY5+AEF5+AEM5+AET5+AFA5+AFH5+AFO5 | AFX5: =IFERROR(AFS5/AFR5/7,"") | AHW5: 7 | AHX5: =AFZ5+AGG5+AGN5+AGU5+AHB5+AHI5+AHP5 | AHY5: =IFERROR(AHX5/AHW5/7,"") | AHZ5: =AGA5+AGH5+AGO5+AGV5+AHC5+AHJ5+AHQ5 | AIA5: =IFERROR(AHZ5/AHX5,"") | AIB5: =AGD5+AGK5+AGR5+AGY5+AHF5+AHM5+AHT5 | AIC5: =IFERROR(AHX5/AHW5/7,"") | AKB5: 7 | AKC5: =AIE5+AIL5+AIS5+AIZ5+AJG5+AJN5+AJU5 | AKD5: =IFERROR(AKC5/AKB5/7,"") | AKE5: =AIF5+AIM5+AIT5+AJA5+AJH5+AJO5+AJV5 | AKF5: =IFERROR(AKE5/AKC5,"") | AKG5: =AII5+AIP5+AIW5+AJD5+AJK5+AJR5+AJY5 | AKH5: =IFERROR(AKC5/AKB5/7,"") | AMG5: 7 | AMH5: =AKJ5+AKQ5+AKX5+ALE5+ALL5+ALS5+ALZ5 | AMI5: =IFERROR(AMH5/AMG5/7,"") | AMJ5: =AKK5+AKR5+AKY5+ALF5+ALM5+ALT5+AMA5 | AMK5: =IFERROR(AMJ5/AMH5,"") | AML5: =AKN5+AKU5+ALB5+ALI5+ALP5+ALW5+AMD5 | AMM5: =IFERROR(AMH5/AMG5/7,"") | AOL5: 7 | AOM5: =AMO5+AMV5+ANC5+ANJ5+ANQ5+ANX5+AOE5 | AON5: =IFERROR(AOM5/AOL5/7,"") | AOO5: =AMP5+AMW5+AND5+ANK5+ANR5+ANY5+AOF5 | AOP5: =IFERROR(AOO5/AOM5,"") | AOQ5: =AMS5+AMZ5+ANG5+ANN5+ANU5+AOB5+AOI5 | AOR5: =IFERROR(AOM5/AOL5/7,"") | AQQ5: 7 | AQR5: =AOT5+APA5+APH5+APO5+APV5+AQC5+AQJ5 | AQS5: =IFERROR(AQR5/AQQ5/7,"") | AQT5: =AOU5+APB5+API5+APP5+APW5+AQD5+AQK5 | AQU5: =IFERROR(AQT5/AQR5,"") | AQV5: =AOX5+APE5+APL5+APS5+APZ5+AQG5+AQN5 | AQW5: =IFERROR(AQR5/AQQ5/7,"") | ASV5: 7 | ASW5: =AQY5+ARF5+ARM5+ART5+ASA5+ASH5+ASO5 | ASX5: =IFERROR(ASW5/ASV5/7,"") | ASY5: =AQZ5+ARG5+ARN5+ARU5+ASB5+ASI5+ASP5 | ASZ5: =IFERROR(ASY5/ASW5,"") | ATA5: =ARC5+ARJ5+ARQ5+ARX5+ASE5+ASL5+ASS5 | ATB5: =IFERROR(ASW5/ASV5/7,"") | AVA5: 7 | AVB5: =ATD5+ATK5+ATR5+ATY5+AUF5+AUM5+AUT5 | AVC5: =IFERROR(AVB5/AVA5/7,"") | AVD5: =ATE5+ATL5+ATS5+ATZ5+AUG5+AUN5+AUU5 | AVE5: =IFERROR(AVD5/AVB5,"") | AVF5: =ATH5+ATO5+ATV5+AUC5+AUJ5+AUQ5+AUX5 | AVG5: =IFERROR(AVB5/AVA5/7,"") | AXF5: 7 | AXG5: =AVI5+AVP5+AVW5+AWD5+AWK5+AWR5+AWY5 | AXH5: =IFERROR(AXG5/AXF5/7,"") | AXI5: =AVJ5+AVQ5+AVX5+AWE5+AWL5+AWS5+AWZ5 | AXJ5: =IFERROR(AXI5/AXG5,"") | AXK5: =AVM5+AVT5+AWA5+AWH5+AWO5+AWV5+AXC5 | AXL5: =IFERROR(AXG5/AXF5/7,"") | AZK5: 7 | AZL5: =AXN5+AXU5+AYB5+AYI5+AYP5+AYW5+AZD5 | AZM5: =IFERROR(AZL5/AZK5/7,"") | AZN5: =AXO5+AXV5+AYC5+AYJ5+AYQ5+AYX5+AZE5 | AZO5: =IFERROR(AZN5/AZL5,"") | AZP5: =AXR5+AXY5+AYF5+AYM5+AYT5+AZA5+AZH5 | AZQ5: =IFERROR(AZL5/AZK5/7,"") | BBP5: 7 | BBQ5: =AZS5+AZZ5+BAG5+BAN5+BAU5+BBB5+BBI5 | BBR5: =IFERROR(BBQ5/BBP5/7,"") | BBS5: =AZT5+BAA5+BAH5+BAO5+BAV5+BBC5+BBJ5 | BBT5: =IFERROR(BBS5/BBQ5,"") | BBU5: =AZW5+BAD5+BAK5+BAR5+BAY5+BBF5+BBM5 | BBV5: =IFERROR(BBQ5/BBP5/7,"") | BDU5: 7 | BDV5: =BBX5+BCE5+BCL5+BCS5+BCZ5+BDG5+BDN5 | BDW5: =IFERROR(BDV5/BDU5/7,"") | BDX5: =BBY5+BCF5+BCM5+BCT5+BDA5+BDH5+BDO5 | BDY5: =IFERROR(BDX5/BDV5,"") | BDZ5: =BCB5+BCI5+BCP5+BCW5+BDD5+BDK5+BDR5 | BEA5: =IFERROR(BDV5/BDU5/7,"") | BFZ5: 7 | BGA5: =BEC5+BEJ5+BEQ5+BEX5+BFE5+BFL5+BFS5 | BGB5: =IFERROR(BGA5/BFZ5/7,"") | BGC5: =BED5+BEK5+BER5+BEY5+BFF5+BFM5+BFT5 | BGD5: =IFERROR(BGC5/BGA5,"") | BGE5: =BEG5+BEN5+BEU5+BFB5+BFI5+BFP5+BFW5 | BGF5: =IFERROR(BGA5/BFZ5/7,"") | BIE5: 7 | BIF5: =BGH5+BGO5+BGV5+BHC5+BHJ5+BHQ5+BHX5 | BIG5: =IFERROR(BIF5/BIE5/7,"") | BIH5: =BGI5+BGP5+BGW5+BHD5+BHK5+BHR5+BHY5 | BII5: =IFERROR(BIH5/BIF5,"") | BIJ5: =BGL5+BGS5+BGZ5+BHG5+BHN5+BHU5+BIB5 | BIK5: =IFERROR(BIF5/BIE5/7,"") | BKJ5: 7 | BKK5: =BIM5+BIT5+BJA5+BJH5+BJO5+BJV5+BKC5 | BKL5: =IFERROR(BKK5/BKJ5/7,"") | BKM5: =BIN5+BIU5+BJB5+BJI5+BJP5+BJW5+BKD5 | BKN5: =IFERROR(BKM5/BKK5,"") | BKO5: =BIQ5+BIX5+BJE5+BJL5+BJS5+BJZ5+BKG5 | BKP5: =IFERROR(BKK5/BKJ5/7,"") | BMO5: 7 | BMP5: =BKR5+BKY5+BLF5+BLM5+BLT5+BMA5+BMH5 | BMQ5: =IFERROR(BMP5/BMO5/7,"") | BMR5: =BKS5+BKZ5+BLG5+BLN5+BLU5+BMB5+BMI5 | BMS5: =IFERROR(BMR5/BMP5,"") | BMT5: =BKV5+BLC5+BLJ5+BLQ5+BLX5+BME5+BML5 | BMU5: =IFERROR(BMP5/BMO5/7,"") | BOT5: 7 | BOU5: =BMW5+BND5+BNK5+BNR5+BNY5+BOF5+BOM5 | BOV5: =IFERROR(BOU5/BOT5/7,"") | BOW5: =BMX5+BNE5+BNL5+BNS5+BNZ5+BOG5+BON5 | BOX5: =IFERROR(BOW5/BOU5,"") | BOY5: =BNA5+BNH5+BNO5+BNV5+BOC5+BOJ5+BOQ5 | BOZ5: =IFERROR(BOU5/BOT5/7,"") | BQY5: 7 | BQZ5: =BPB5+BPI5+BPP5+BPW5+BQD5+BQK5+BQR5 | BRA5: =IFERROR(BQZ5/BQY5/7,"") | BRB5: =BPC5+BPJ5+BPQ5+BPX5+BQE5+BQL5+BQS5 | BRC5: =IFERROR(BRB5/BQZ5,"") | BRD5: =BPF5+BPM5+BPT5+BQA5+BQH5+BQO5+BQV5 | BRE5: =IFERROR(BQZ5/BQY5/7,"") | BTD5: 7 | BTE5: =BRG5+BRN5+BRU5+BSB5+BSI5+BSP5+BSW5 | BTF5: =IFERROR(BTE5/BTD5/7,"") | BTG5: =BRH5+BRO5+BRV5+BSC5+BSJ5+BSQ5+BSX5 | BTH5: =IFERROR(BTG5/BTE5,"") | BTI5: =BRK5+BRR5+BRY5+BSF5+BSM5+BST5+BTA5 | BTJ5: =IFERROR(BTE5/BTD5/7,"") | BVI5: 7 | BVJ5: =BTL5+BTS5+BTZ5+BUG5+BUN5+BUU5+BVB5 | BVK5: =IFERROR(BVJ5/BVI5/7,"") | BVL5: =BTM5+BTT5+BUA5+BUH5+BUO5+BUV5+BVC5 | BVM5: =IFERROR(BVL5/BVJ5,"") | BVN5: =BTP5+BTW5+BUD5+BUK5+BUR5+BUY5+BVF5 | BVO5: =IFERROR(BVJ5/BVI5/7,"") | BXN5: 7 | BXO5: =BVQ5+BVX5+BWE5+BWL5+BWS5+BWZ5+BXG5 | BXP5: =IFERROR(BXO5/BXN5/7,"") | BXQ5: =BVR5+BVY5+BWF5+BWM5+BWT5+BXA5+BXH5 | BXR5: =IFERROR(BXQ5/BXO5,"") | BXS5: =BVU5+BWB5+BWI5+BWP5+BWW5+BXD5+BXK5 | BXT5: =IFERROR(BXO5/BXN5/7,"") | BZS5: 7 | BZT5: =BXV5+BYC5+BYJ5+BYQ5+BYX5+BZE5+BZL5 | BZU5: =IFERROR(BZT5/BZS5/7,"") | BZV5: =BXW5+BYD5+BYK5+BYR5+BYY5+BZF5+BZM5 | BZW5: =IFERROR(BZV5/BZT5,"") | BZX5: =BXZ5+BYG5+BYN5+BYU5+BZB5+BZI5+BZP5 | BZY5: =IFERROR(BZT5/BZS5/7,"")
