Workbook

Sheet Pen trt 
A1: Pen | B1: Treatment
A2: 1 | B2: 1
A3: 2 | B3: 9
A4: 3 | B4: 17
A5: 4 | B5: 25
A6: 5 | B6: 28
A7: 6 | B7: 4
A8: 7 | B8: 12
A9: 8 | B9: 20
A10: 9 | B10: 32
A11: 10 | B11: 8
A12: 11 | B12: 16
A13: 12 | B13: 24
... A193: 192 | B193: 29

Sheet Egg Data
C1: 46327 | J1: 46328 | Q1: 46329 | X1: 46330 | AE1: 46331 | AL1: 46332 | AS1: 46333 | AZ1: 1W | BH1: 46334 | BO1: 46335 | BV1: 46336 | CC1: 46337 | CJ1: 46338 | CQ1: 46339 | CX1: 46340 | DE1: 2W | DM1: 46341 | DT1: 46342 | EA1: 46343 | EH1: 46344 | EO1: 46345 | EV1: 46346 | FC1: 46347 | FJ1: 3W | FR1: 46348 | FY1: 46349 | GF1: 46350 | GM1: 46351 | GT1: 46352 | HA1: 46353 | HH1: 46354 | HO1: 4W | HW1: 46355 | ID1: 46356 | IK1: 46357 | IR1: 46358 | IY1: 46359 | JF1: 46360 | JM1: 46361 | JT1: 5W | KB1: 46362 | KI1: 46363 | KP1: 46364 | KW1: 46365 | LD1: 46366 | LK1: 46367 | LR1: 46368 | LY1: 6W | MG1: 46369 | MN1: 46370 | MU1: 46371 | NB1: 46372 | NI1: 46373 | NP1: 46374 | NW1: 46375 | OD1: 7W | OL1: 46376 | OS1: 46377 | OZ1: 46378 | PG1: 46379 | PN1: 46380 | PU1: 46381 | QB1: 46382 | QI1: 8W | QQ1: 46383 | QX1: 46384 | RE1: 46385 | RL1: 46386 | RS1: 46387 | RZ1: 46388 | SG1: 46389 | SN1: 9W | SV1: 46390 | TC1: 46391 | TJ1: 46392 | TQ1: 46393 | TX1: 46394 | UE1: 46395 | UL1: 46396 | US1: 10W | VA1: 46397 | VH1: 46398 | VO1: 46399 | VV1: 46400 | WC1: 46401 | WJ1: 46402 | WQ1: 46403 | WX1: 11W | XF1: 46404 | XM1: 46405 | XT1: 46406 | YA1: 46407 | YH1: 46408 | YO1: 46409 | YV1: 46410 | ZC1: 12W | ZK1: 46411 | ZR1: 46412 | ZY1: 46413 | AAF1: 46414 | AAM1: 46415 | AAT1: 46416 | ABA1: 46417 | ABH1: 13W | ABP1: 46418 | ABW1: 46419 | ACD1: 46420 | ACK1: 46421 | ACR1: 46422 | ACY1: 46423 | ADF1: 46424 | ADM1: 14W | ADU1: 46425 | AEB1: 46426 | AEI1: 46427 | AEP1: 46428 | AEW1: 46429 | AFD1: 46430 | AFK1: 46431 | AFR1: 15W | AFZ1: 46432 | AGG1: 46433 | AGN1: 46434 | AGU1: 46435 | AHB1: 46436 | AHI1: 46437 | AHP1: 46438 | AHW1: 16W | AIE1: 46439 | AIL1: 46440 | AIS1: 46441 | AIZ1: 46442 | AJG1: 46443 | AJN1: 46444 | AJU1: 46445 | AKB1: 17W | AKJ1: 46446 | AKQ1: 46447 | AKX1: 46448 | ALE1: 46449 | ALL1: 46450 | ALS1: 46451 | ALZ1: 46452 | AMG1: 18W | AMO1: 46453 | AMV1: 46454 | ANC1: 46455 | ANJ1: 46456 | ANQ1: 46457 | ANX1: 46458 | AOE1: 46459 | AOL1: 19W | AOT1: 46460 | APA1: 46461 | APH1: 46462 | APO1: 46463 | APV1: 46464 | AQC1: 46465 | AQJ1: 46466 | AQQ1: 20W
C2: 1W | J2: 1W | Q2: 1W | X2: 1W | AE2: 1W | AL2: 1W | AS2: 1W | BH2: 2W | BO2: 2W | BV2: 2W | CC2: 2W | CJ2: 2W | CQ2: 2W | CX2: 2W | DM2: 3W | DT2: 3W | EA2: 3W | EH2: 3W | EO2: 3W | EV2: 3W | FC2: 3W | FR2: 4W | FY2: 4W | GF2: 4W | GM2: 4W | GT2: 4W | HA2: 4W | HH2: 4W | HW2: 5W | ID2: 5W | IK2: 5W | IR2: 5W | IY2: 5W | JF2: 5W | JM2: 5W | KB2: 6W | KI2: 6W | KP2: 6W | KW2: 6W | LD2: 6W | LK2: 6W | LR2: 6W | MG2: 7W | MN2: 7W | MU2: 7W | NB2: 7W | NI2: 7W | NP2: 7W | NW2: 7W | OL2: 8W | OS2: 8W | OZ2: 8W | PG2: 8W | PN2: 8W | PU2: 8W | QB2: 8W | QQ2: 9W | QX2: 9W | RE2: 9W | RL2: 9W | RS2: 9W | RZ2: 9W | SG2: 9W | SV2: 10W | TC2: 10W | TJ2: 10W | TQ2: 10W | TX2: 10W | UE2: 10W | UL2: 10W | VA2: 11W | VH2: 11W | VO2: 11W | VV2: 11W | WC2: 11W | WJ2: 11W | WQ2: 11W | XF2: 12W | XM2: 12W | XT2: 12W | YA2: 12W | YH2: 12W | YO2: 12W | YV2: 12W | ZK2: 13W | ZR2: 13W | ZY2: 13W | AAF2: 13W | AAM2: 13W | AAT2: 13W | ABA2: 13W | ABP2: 14W | ABW2: 14W | ACD2: 14W | ACK2: 14W | ACR2: 14W | ACY2: 14W | ADF2: 14W | ADU2: 15W | AEB2: 15W | AEI2: 15W | AEP2: 15W | AEW2: 15W | AFD2: 15W | AFK2: 15W | AFZ2: 16W | AGG2: 16W | AGN2: 16W | AGU2: 16W | AHB2: 16W | AHI2: 16W | AHP2: 16W | AIE2: 17W | AIL2: 17W | AIS2: 17W | AIZ2: 17W | AJG2: 17W | AJN2: 17W | AJU2: 17W | AKJ2: 18W | AKQ2: 18W | AKX2: 18W | ALE2: 18W | ALL2: 18W | ALS2: 18W | ALZ2: 18W | AMO2: 19W | AMV2: 19W | ANC2: 19W | ANJ2: 19W | ANQ2: 19W | ANX2: 19W | AOE2: 19W | AOT2: 20W | APA2: 20W | APH2: 20W | APO2: 20W | APV2: 20W | AQC2: 20W | AQJ2: 20W
A3: Pen Number | B3: Treatment Number | C3: Number of Eggs | D3: Weight | E3: Average Weight | F3: Non Layer | G3: Number of Rejects | H3: Reason | J3: Number of Eggs | K3: Weight | L3: Average Weight | M3: Non Layer | N3: Number of Rejects | O3: Reason | Q3: Number of Eggs | R3: Weight | S3: Average Weight | T3: Non Layer | U3: Number of Rejects | V3: Reason | X3: Number of Eggs | Y3: Weight | Z3: Average Weight | AA3: Non Layer | AB3: Number of Rejects | AC3: Reason | AE3: Number of Eggs | AF3: Weight | AG3: Average Weight | AH3: Non Layer | AI3: Number of Rejects | AJ3: Reason | AL3: Number of Eggs | AM3: Weight | AN3: Average Weight | AO3: Non Layer | AP3: Number of Rejects | AQ3: Reason | AS3: Number of Eggs | AT3: Weight | AU3: Average Weight | AV3: Non Layer | AW3: Number of Rejects | AX3: Reason | AZ3: Bird # | BA3: Number of Eggs | BB3: Ave eggs | BC3: Weight | BD3: Average Weight | BE3: Number of Rejects | BF3: %HDE_ | BH3: Number of Eggs | BI3: Weight | BJ3: Average Weight | BK3: Non Layer | BL3: Number of Rejects | BM3: Reason | BO3: Number of Eggs | BP3: Weight | BQ3: Average Weight | BR3: Non Layer | BS3: Number of Rejects | BT3: Reason | BV3: Number of Eggs | BW3: Weight | BX3: Average Weight | BY3: Non Layer | BZ3: Number of Rejects | CA3: Reason | CC3: Number of Eggs | CD3: Weight | CE3: Average Weight | CF3: Non Layer | CG3: Number of Rejects | CH3: Reason | CJ3: Number of Eggs | CK3: Weight | CL3: Average Weight | CM3: Non Layer | CN3: Number of Rejects | CO3: Reason | CQ3: Number of Eggs | CR3: Weight | CS3: Average Weight | CT3: Non Layer | CU3: Number of Rejects | CV3: Reason | CX3: Number of Eggs | CY3: Weight | CZ3: Average Weight | DA3: Non Layer | DB3: Number of Rejects | DC3: Reason | DE3: Bird # | DF3: Number of Eggs | DG3: Ave eggs | DH3: Weight | DI3: Average Weight | DJ3: Number of Rejects | DK3: %HDE_ | DM3: Number of Eggs | DN3: Weight | DO3: Average Weight | DP3: Non Layer | DQ3: Number of Rejects | DR3: Reason | DT3: Number of Eggs | DU3: Weight | DV3: Average Weight | DW3: Non Layer | DX3: Number of Rejects | DY3: Reason | EA3: Number of Eggs | EB3: Weight | EC3: Average Weight | ED3: Non Layer | EE3: Number of Rejects | EF3: Reason | EH3: Number of Eggs | EI3: Weight | EJ3: Average Weight | EK3: Non Layer | EL3: Number of Rejects | EM3: Reason | EO3: Number of Eggs | EP3: Weight | EQ3: Average Weight | ER3: Non Layer | ES3: Number of Rejects | ET3: Reason | EV3: Number of Eggs | EW3: Weight | EX3: Average Weight | EY3: Non Layer | EZ3: Number of Rejects | FA3: Reason | FC3: Number of Eggs | FD3: Weight | FE3: Average Weight | FF3: Non Layer | FG3: Number of Rejects | FH3: Reason | FJ3: Bird # | FK3: Number of Eggs | FL3: Ave eggs | FM3: Weight | FN3: Average Weight | FO3: Number of Rejects | FP3: %HDE_ | FR3: Number of Eggs | FS3: Weight | FT3: Average Weight | FU3: Non Layer | FV3: Number of Rejects | FW3: Reason | FY3: Number of Eggs | FZ3: Weight | GA3: Average Weight | GB3: Non Layer | GC3: Number of Rejects | GD3: Reason | GF3: Number of Eggs | GG3: Weight | GH3: Average Weight | GI3: Non Layer | GJ3: Number of Rejects | GK3: Reason | GM3: Number of Eggs | GN3: Weight | GO3: Average Weight | GP3: Non Layer | GQ3: Number of Rejects | GR3: Reason | GT3: Number of Eggs | GU3: Weight | GV3: Average Weight | GW3: Non Layer | GX3: Number of Rejects | GY3: Reason | HA3: Number of Eggs | HB3: Weight | HC3: Average Weight | HD3: Non Layer | HE3: Number of Rejects | HF3: Reason | HH3: Number of Eggs | HI3: Weight | HJ3: Average Weight | HK3: Non Layer | HL3: Number of Rejects | HM3: Reason | HO3: Bird # | HP3: Number of Eggs | HQ3: Ave eggs | HR3: Weight | HS3: Average Weight | HT3: Number of Rejects | HU3: %HDE_ | HW3: Number of Eggs | HX3: Weight | HY3: Average Weight | HZ3: Non Layer | IA3: Number of Rejects | IB3: Reason | ID3: Number of Eggs | IE3: Weight | IF3: Average Weight | IG3: Non Layer | IH3: Number of Rejects | II3: Reason | IK3: Number of Eggs | IL3: Weight | IM3: Average Weight | IN3: Non Layer | IO3: Number of Rejects | IP3: Reason | IR3: Number of Eggs | IS3: Weight | IT3: Average Weight | IU3: Non Layer | IV3: Number of Rejects | IW3: Reason | IY3: Number of Eggs | IZ3: Weight | JA3: Average Weight | JB3: Non Layer | JC3: Number of Rejects | JD3: Reason | JF3: Number of Eggs | JG3: Weight | JH3: Average Weight | JI3: Non Layer | JJ3: Number of Rejects | JK3: Reason | JM3: Number of Eggs | JN3: Weight | JO3: Average Weight | JP3: Non Layer | JQ3: Number of Rejects | JR3: Reason | JT3: Bird # | JU3: Number of Eggs | JV3: Ave eggs | JW3: Weight | JX3: Average Weight | JY3: Number of Rejects | JZ3: %HDE_ | KB3: Number of Eggs | KC3: Weight | KD3: Average Weight | KE3: Non Layer | KF3: Number of Rejects | KG3: Reason | KI3: Number of Eggs | KJ3: Weight | KK3: Average Weight | KL3: Non Layer | KM3: Number of Rejects | KN3: Reason | KP3: Number of Eggs | KQ3: Weight | KR3: Average Weight | KS3: Non Layer | KT3: Number of Rejects | KU3: Reason | KW3: Number of Eggs | KX3: Weight | KY3: Average Weight | KZ3: Non Layer | LA3: Number of Rejects | LB3: Reason | LD3: Number of Eggs | LE3: Weight | LF3: Average Weight | LG3: Non Layer | LH3: Number of Rejects | LI3: Reason | LK3: Number of Eggs | LL3: Weight | LM3: Average Weight | LN3: Non Layer | LO3: Number of Rejects | LP3: Reason | LR3: Number of Eggs | LS3: Weight | LT3: Average Weight | LU3: Non Layer | LV3: Number of Rejects | LW3: Reason | LY3: Bird # | LZ3: Number of Eggs | MA3: Ave eggs | MB3: Weight | MC3: Average Weight | MD3: Number of Rejects | ME3: %HDE_ | MG3: Number of Eggs | MH3: Weight | MI3: Average Weight | MJ3: Non Layer | MK3: Number of Rejects | ML3: Reason | MN3: Number of Eggs | MO3: Weight | MP3: Average Weight | MQ3: Non Layer | MR3: Number of Rejects | MS3: Reason | MU3: Number of Eggs | MV3: Weight | MW3: Average Weight | MX3: Non Layer | MY3: Number of Rejects | MZ3: Reason | NB3: Number of Eggs | NC3: Weight | ND3: Average Weight | NE3: Non Layer | NF3: Number of Rejects | NG3: Reason | NI3: Number of Eggs | NJ3: Weight | NK3: Average Weight | NL3: Non Layer | NM3: Number of Rejects | NN3: Reason | NP3: Number of Eggs | NQ3: Weight | NR3: Average Weight | NS3: Non Layer | NT3: Number of Rejects | NU3: Reason | NW3: Number of Eggs | NX3: Weight | NY3: Average Weight | NZ3: Non Layer | OA3: Number of Rejects | OB3: Reason | OD3: Bird # | OE3: Number of Eggs | OF3: Ave eggs | OG3: Weight | OH3: Average Weight | OI3: Number of Rejects | OJ3: %HDE_ | OL3: Number of Eggs | OM3: Weight | ON3: Average Weight | OO3: Non Layer | OP3: Number of Rejects | OQ3: Reason | OS3: Number of Eggs | OT3: Weight | OU3: Average Weight | OV3: Non Layer | OW3: Number of Rejects | OX3: Reason | OZ3: Number of Eggs | PA3: Weight | PB3: Average Weight | PC3: Non Layer | PD3: Number of Rejects | PE3: Reason | PG3: Number of Eggs | PH3: Weight | PI3: Average Weight | PJ3: Non Layer | PK3: Number of Rejects | PL3: Reason | PN3: Number of Eggs | PO3: Weight | PP3: Average Weight | PQ3: Non Layer | PR3: Number of Rejects | PS3: Reason | PU3: Number of Eggs | PV3: Weight | PW3: Average Weight | PX3: Non Layer | PY3: Number of Rejects | PZ3: Reason | QB3: Number of Eggs | QC3: Weight | QD3: Average Weight | QE3: Non Layer | QF3: Number of Rejects | QG3: Reason | QI3: Bird # | QJ3: Number of Eggs | QK3: Ave eggs | QL3: Weight | QM3: Average Weight | QN3: Number of Rejects | QO3: %HDE_ | QQ3: Number of Eggs | QR3: Weight | QS3: Average Weight | QT3: Non Layer | QU3: Number of Rejects | QV3: Reason | QX3: Number of Eggs | QY3: Weight | QZ3: Average Weight | RA3: Non Layer | RB3: Number of Rejects | RC3: Reason | RE3: Number of Eggs | RF3: Weight | RG3: Average Weight | RH3: Non Layer | RI3: Number of Rejects | RJ3: Reason | RL3: Number of Eggs | RM3: Weight | RN3: Average Weight | RO3: Non Layer | RP3: Number of Rejects | RQ3: Reason | RS3: Number of Eggs | RT3: Weight | RU3: Average Weight | RV3: Non Layer | RW3: Number of Rejects | RX3: Reason | RZ3: Number of Eggs | SA3: Weight | SB3: Average Weight | SC3: Non Layer | SD3: Number of Rejects | SE3: Reason | SG3: Number of Eggs | SH3: Weight | SI3: Average Weight | SJ3: Non Layer | SK3: Number of Rejects | SL3: Reason | SN3: Bird # | SO3: Number of Eggs | SP3: Ave eggs | SQ3: Weight | SR3: Average Weight | SS3: Number of Rejects | ST3: %HDE_ | SV3: Number of Eggs | SW3: Weight | SX3: Average Weight | SY3: Non Layer | SZ3: Number of Rejects | TA3: Reason | TC3: Number of Eggs | TD3: Weight | TE3: Average Weight | TF3: Non Layer | TG3: Number of Rejects | TH3: Reason | TJ3: Number of Eggs | TK3: Weight | TL3: Average Weight | TM3: Non Layer | TN3: Number of Rejects | TO3: Reason | TQ3: Number of Eggs | TR3: Weight | TS3: Average Weight | TT3: Non Layer | TU3: Number of Rejects | TV3: Reason | TX3: Number of Eggs | TY3: Weight | TZ3: Average Weight | UA3: Non Layer | UB3: Number of Rejects | UC3: Reason | UE3: Number of Eggs | UF3: Weight | UG3: Average Weight | UH3: Non Layer | UI3: Number of Rejects | UJ3: Reason | UL3: Number of Eggs | UM3: Weight | UN3: Average Weight | UO3: Non Layer | UP3: Number of Rejects | UQ3: Reason | US3: Bird # | UT3: Number of Eggs | UU3: Ave eggs | UV3: Weight | UW3: Average Weight | UX3: Number of Rejects | UY3: %HDE_ | VA3: Number of Eggs | VB3: Weight | VC3: Average Weight | VD3: Non Layer | VE3: Number of Rejects | VF3: Reason | VH3: Number of Eggs | VI3: Weight | VJ3: Average Weight | VK3: Non Layer | VL3: Number of Rejects | VM3: Reason | VO3: Number of Eggs | VP3: Weight | VQ3: Average Weight | VR3: Non Layer | VS3: Number of Rejects | VT3: Reason | VV3: Number of Eggs | VW3: Weight | VX3: Average Weight | VY3: Non Layer | VZ3: Number of Rejects | WA3: Reason | WC3: Number of Eggs | WD3: Weight | WE3: Average Weight | WF3: Non Layer | WG3: Number of Rejects | WH3: Reason | WJ3: Number of Eggs | WK3: Weight | WL3: Average Weight | WM3: Non Layer | WN3: Number of Rejects | WO3: Reason | WQ3: Number of Eggs | WR3: Weight | WS3: Average Weight | WT3: Non Layer | WU3: Number of Rejects | WV3: Reason | WX3: Bird # | WY3: Number of Eggs | WZ3: Ave eggs | XA3: Weight | XB3: Average Weight | XC3: Number of Rejects | XD3: %HDE_ | XF3: Number of Eggs | XG3: Weight | XH3: Average Weight | XI3: Non Layer | XJ3: Number of Rejects | XK3: Reason | XM3: Number of Eggs | XN3: Weight | XO3: Average Weight | XP3: Non Layer | XQ3: Number of Rejects | XR3: Reason | XT3: Number of Eggs | XU3: Weight | XV3: Average Weight | XW3: Non Layer | XX3: Number of Rejects | XY3: Reason | YA3: Number of Eggs | YB3: Weight | YC3: Average Weight | YD3: Non Layer | YE3: Number of Rejects | YF3: Reason | YH3: Number of Eggs | YI3: Weight | YJ3: Average Weight | YK3: Non Layer | YL3: Number of Rejects | YM3: Reason | YO3: Number of Eggs | YP3: Weight | YQ3: Average Weight | YR3: Non Layer | YS3: Number of Rejects | YT3: Reason | YV3: Number of Eggs | YW3: Weight | YX3: Average Weight | YY3: Non Layer | YZ3: Number of Rejects | ZA3: Reason | ZC3: Bird # | ZD3: Number of Eggs | ZE3: Ave eggs | ZF3: Weight | ZG3: Average Weight | ZH3: Number of Rejects | ZI3: %HDE_ | ZK3: Number of Eggs | ZL3: Weight | ZM3: Average Weight | ZN3: Non Layer | ZO3: Number of Rejects | ZP3: Reason | ZR3: Number of Eggs | ZS3: Weight | ZT3: Average Weight | ZU3: Non Layer | ZV3: Number of Rejects | ZW3: Reason | ZY3: Number of Eggs | ZZ3: Weight | AAA3: Average Weight | AAB3: Non Layer | AAC3: Number of Rejects | AAD3: Reason | AAF3: Number of Eggs | AAG3: Weight | AAH3: Average Weight | AAI3: Non Layer | AAJ3: Number of Rejects | AAK3: Reason | AAM3: Number of Eggs | AAN3: Weight | AAO3: Average Weight | AAP3: Non Layer | AAQ3: Number of Rejects | AAR3: Reason | AAT3: Number of Eggs | AAU3: Weight | AAV3: Average Weight | AAW3: Non Layer | AAX3: Number of Rejects | AAY3: Reason | ABA3: Number of Eggs | ABB3: Weight | ABC3: Average Weight | ABD3: Non Layer | ABE3: Number of Rejects | ABF3: Reason | ABH3: Bird # | ABI3: Number of Eggs | ABJ3: Ave eggs | ABK3: Weight | ABL3: Average Weight | ABM3: Number of Rejects | ABN3: %HDE_ | ABP3: Number of Eggs | ABQ3: Weight | ABR3: Average Weight | ABS3: Non Layer | ABT3: Number of Rejects | ABU3: Reason | ABW3: Number of Eggs | ABX3: Weight | ABY3: Average Weight | ABZ3: Non Layer | ACA3: Number of Rejects | ACB3: Reason | ACD3: Number of Eggs | ACE3: Weight | ACF3: Average Weight | ACG3: Non Layer | ACH3: Number of Rejects | ACI3: Reason | ACK3: Number of Eggs | ACL3: Weight | ACM3: Average Weight | ACN3: Non Layer | ACO3: Number of Rejects | ACP3: Reason | ACR3: Number of Eggs | ACS3: Weight | ACT3: Average Weight | ACU3: Non Layer | ACV3: Number of Rejects | ACW3: Reason | ACY3: Number of Eggs | ACZ3: Weight | ADA3: Average Weight | ADB3: Non Layer | ADC3: Number of Rejects | ADD3: Reason | ADF3: Number of Eggs | ADG3: Weight | ADH3: Average Weight | ADI3: Non Layer | ADJ3: Number of Rejects | ADK3: Reason | ADM3: Bird # | ADN3: Number of Eggs | ADO3: Ave eggs | ADP3: Weight | ADQ3: Average Weight | ADR3: Number of Rejects | ADS3: %HDE_ | ADU3: Number of Eggs | ADV3: Weight | ADW3: Average Weight | ADX3: Non Layer | ADY3: Number of Rejects | ADZ3: Reason | AEB3: Number of Eggs | AEC3: Weight | AED3: Average Weight | AEE3: Non Layer | AEF3: Number of Rejects | AEG3: Reason | AEI3: Number of Eggs | AEJ3: Weight | AEK3: Average Weight | AEL3: Non Layer | AEM3: Number of Rejects | AEN3: Reason | AEP3: Number of Eggs | AEQ3: Weight | AER3: Average Weight | AES3: Non Layer | AET3: Number of Rejects | AEU3: Reason | AEW3: Number of Eggs | AEX3: Weight | AEY3: Average Weight | AEZ3: Non Layer | AFA3: Number of Rejects | AFB3: Reason | AFD3: Number of Eggs | AFE3: Weight | AFF3: Average Weight | AFG3: Non Layer | AFH3: Number of Rejects | AFI3: Reason | AFK3: Number of Eggs | AFL3: Weight | AFM3: Average Weight | AFN3: Non Layer | AFO3: Number of Rejects | AFP3: Reason | AFR3: Bird # | AFS3: Number of Eggs | AFT3: Ave eggs | AFU3: Weight | AFV3: Average Weight | AFW3: Number of Rejects | AFX3: %HDE_ | AFZ3: Number of Eggs | AGA3: Weight | AGB3: Average Weight | AGC3: Non Layer | AGD3: Number of Rejects | AGE3: Reason | AGG3: Number of Eggs | AGH3: Weight | AGI3: Average Weight | AGJ3: Non Layer | AGK3: Number of Rejects | AGL3: Reason | AGN3: Number of Eggs | AGO3: Weight | AGP3: Average Weight | AGQ3: Non Layer | AGR3: Number of Rejects | AGS3: Reason | AGU3: Number of Eggs | AGV3: Weight | AGW3: Average Weight | AGX3: Non Layer | AGY3: Number of Rejects | AGZ3: Reason | AHB3: Number of Eggs | AHC3: Weight | AHD3: Average Weight | AHE3: Non Layer | AHF3: Number of Rejects | AHG3: Reason | AHI3: Number of Eggs | AHJ3: Weight | AHK3: Average Weight | AHL3: Non Layer | AHM3: Number of Rejects | AHN3: Reason | AHP3: Number of Eggs | AHQ3: Weight | AHR3: Average Weight | AHS3: Non Layer | AHT3: Number of Rejects | AHU3: Reason | AHW3: Bird # | AHX3: Number of Eggs | AHY3: Ave eggs | AHZ3: Weight | AIA3: Average Weight | AIB3: Number of Rejects | AIC3: %HDE_ | AIE3: Number of Eggs | AIF3: Weight | AIG3: Average Weight | AIH3: Non Layer | AII3: Number of Rejects | AIJ3: Reason | AIL3: Number of Eggs | AIM3: Weight | AIN3: Average Weight | AIO3: Non Layer | AIP3: Number of Rejects | AIQ3: Reason | AIS3: Number of Eggs | AIT3: Weight | AIU3: Average Weight | AIV3: Non Layer | AIW3: Number of Rejects | AIX3: Reason | AIZ3: Number of Eggs | AJA3: Weight | AJB3: Average Weight | AJC3: Non Layer | AJD3: Number of Rejects | AJE3: Reason | AJG3: Number of Eggs | AJH3: Weight | AJI3: Average Weight | AJJ3: Non Layer | AJK3: Number of Rejects | AJL3: Reason | AJN3: Number of Eggs | AJO3: Weight | AJP3: Average Weight | AJQ3: Non Layer | AJR3: Number of Rejects | AJS3: Reason | AJU3: Number of Eggs | AJV3: Weight | AJW3: Average Weight | AJX3: Non Layer | AJY3: Number of Rejects | AJZ3: Reason | AKB3: Bird # | AKC3: Number of Eggs | AKD3: Ave eggs | AKE3: Weight | AKF3: Average Weight | AKG3: Number of Rejects | AKH3: %HDE_ | AKJ3: Number of Eggs | AKK3: Weight | AKL3: Average Weight | AKM3: Non Layer | AKN3: Number of Rejects | AKO3: Reason | AKQ3: Number of Eggs | AKR3: Weight | AKS3: Average Weight | AKT3: Non Layer | AKU3: Number of Rejects | AKV3: Reason | AKX3: Number of Eggs | AKY3: Weight | AKZ3: Average Weight | ALA3: Non Layer | ALB3: Number of Rejects | ALC3: Reason | ALE3: Number of Eggs | ALF3: Weight | ALG3: Average Weight | ALH3: Non Layer | ALI3: Number of Rejects | ALJ3: Reason | ALL3: Number of Eggs | ALM3: Weight | ALN3: Average Weight | ALO3: Non Layer | ALP3: Number of Rejects | ALQ3: Reason | ALS3: Number of Eggs | ALT3: Weight | ALU3: Average Weight | ALV3: Non Layer | ALW3: Number of Rejects | ALX3: Reason | ALZ3: Number of Eggs | AMA3: Weight | AMB3: Average Weight | AMC3: Non Layer | AMD3: Number of Rejects | AME3: Reason | AMG3: Bird # | AMH3: Number of Eggs | AMI3: Ave eggs | AMJ3: Weight | AMK3: Average Weight | AML3: Number of Rejects | AMM3: %HDE_ | AMO3: Number of Eggs | AMP3: Weight | AMQ3: Average Weight | AMR3: Non Layer | AMS3: Number of Rejects | AMT3: Reason | AMV3: Number of Eggs | AMW3: Weight | AMX3: Average Weight | AMY3: Non Layer | AMZ3: Number of Rejects | ANA3: Reason | ANC3: Number of Eggs | AND3: Weight | ANE3: Average Weight | ANF3: Non Layer | ANG3: Number of Rejects | ANH3: Reason | ANJ3: Number of Eggs | ANK3: Weight | ANL3: Average Weight | ANM3: Non Layer | ANN3: Number of Rejects | ANO3: Reason | ANQ3: Number of Eggs | ANR3: Weight | ANS3: Average Weight | ANT3: Non Layer | ANU3: Number of Rejects | ANV3: Reason | ANX3: Number of Eggs | ANY3: Weight | ANZ3: Average Weight | AOA3: Non Layer | AOB3: Number of Rejects | AOC3: Reason | AOE3: Number of Eggs | AOF3: Weight | AOG3: Average Weight | AOH3: Non Layer | AOI3: Number of Rejects | AOJ3: Reason | AOL3: Bird # | AOM3: Number of Eggs | AON3: Ave eggs | AOO3: Weight | AOP3: Average Weight | AOQ3: Number of Rejects | AOR3: %HDE_ | AOT3: Number of Eggs | AOU3: Weight | AOV3: Average Weight | AOW3: Non Layer | AOX3: Number of Rejects | AOY3: Reason | APA3: Number of Eggs | APB3: Weight | APC3: Average Weight | APD3: Non Layer | APE3: Number of Rejects | APF3: Reason | APH3: Number of Eggs | API3: Weight | APJ3: Average Weight | APK3: Non Layer | APL3: Number of Rejects | APM3: Reason | APO3: Number of Eggs | APP3: Weight | APQ3: Average Weight | APR3: Non Layer | APS3: Number of Rejects | APT3: Reason | APV3: Number of Eggs | APW3: Weight | APX3: Average Weight | APY3: Non Layer | APZ3: Number of Rejects | AQA3: Reason | AQC3: Number of Eggs | AQD3: Weight | AQE3: Average Weight | AQF3: Non Layer | AQG3: Number of Rejects | AQH3: Reason | AQJ3: Number of Eggs | AQK3: Weight | AQL3: Average Weight | AQM3: Non Layer | AQN3: Number of Rejects | AQO3: Reason | AQQ3: Bird # | AQR3: Number of Eggs | AQS3: Ave eggs | AQT3: Weight | AQU3: Average Weight | AQV3: Number of Rejects | AQW3: %HDE_
A4: 1 | AZ4: 7 | BA4: =C4+J4+Q4+X4+AE4+AL4+AS4 | BB4: =IFERROR(BA4/AZ4/7,"") | BC4: =D4+K4+R4+Y4+AF4+AM4+AT4 | BD4: =IFERROR(BC4/BA4,"") | BE4: =G4+N4+U4+AB4+AI4+AP4+AW4 | BF4: =IFERROR(BA4/AZ4/7,"") | DE4: 7 | DF4: =BH4+BO4+BV4+CC4+CJ4+CQ4+CX4 | DG4: =IFERROR(DF4/DE4/7,"") | DH4: =BI4+BP4+BW4+CD4+CK4+CR4+CY4 | DI4: =IFERROR(DH4/DF4,"") | DJ4: =BL4+BS4+BZ4+CG4+CN4+CU4+DB4 | DK4: =IFERROR(DF4/DE4/7,"") | FJ4: 7 | FK4: =DM4+DT4+EA4+EH4+EO4+EV4+FC4 | FL4: =IFERROR(FK4/FJ4/7,"") | FM4: =DN4+DU4+EB4+EI4+EP4+EW4+FD4 | FN4: =IFERROR(FM4/FK4,"") | FO4: =DQ4+DX4+EE4+EL4+ES4+EZ4+FG4 | FP4: =IFERROR(FK4/FJ4/7,"") | HO4: 7 | HP4: =FR4+FY4+GF4+GM4+GT4+HA4+HH4 | HQ4: =IFERROR(HP4/HO4/7,"") | HR4: =FS4+FZ4+GG4+GN4+GU4+HB4+HI4 | HS4: =IFERROR(HR4/HP4,"") | HT4: =FV4+GC4+GJ4+GQ4+GX4+HE4+HL4 | HU4: =IFERROR(HP4/HO4/7,"") | JT4: 7 | JU4: =HW4+ID4+IK4+IR4+IY4+JF4+JM4 | JV4: =IFERROR(JU4/JT4/7,"") | JW4: =HX4+IE4+IL4+IS4+IZ4+JG4+JN4 | JX4: =IFERROR(JW4/JU4,"") | JY4: =IA4+IH4+IO4+IV4+JC4+JJ4+JQ4 | JZ4: =IFERROR(JU4/JT4/7,"") | LY4: 7 | LZ4: =KB4+KI4+KP4+KW4+LD4+LK4+LR4 | MA4: =IFERROR(LZ4/LY4/7,"") | MB4: =KC4+KJ4+KQ4+KX4+LE4+LL4+LS4 | MC4: =IFERROR(MB4/LZ4,"") | MD4: =KF4+KM4+KT4+LA4+LH4+LO4+LV4 | ME4: =IFERROR(LZ4/LY4/7,"") | OD4: 7 | OE4: =MG4+MN4+MU4+NB4+NI4+NP4+NW4 | OF4: =IFERROR(OE4/OD4/7,"") | OG4: =MH4+MO4+MV4+NC4+NJ4+NQ4+NX4 | OH4: =IFERROR(OG4/OE4,"") | OI4: =MK4+MR4+MY4+NF4+NM4+NT4+OA4 | OJ4: =IFERROR(OE4/OD4/7,"") | QI4: 7 | QJ4: =OL4+OS4+OZ4+PG4+PN4+PU4+QB4 | QK4: =IFERROR(QJ4/QI4/7,"") | QL4: =OM4+OT4+PA4+PH4+PO4+PV4+QC4 | QM4: =IFERROR(QL4/QJ4,"") | QN4: =OP4+OW4+PD4+PK4+PR4+PY4+QF4 | QO4: =IFERROR(QJ4/QI4/7,"") | SN4: 7 | SO4: =QQ4+QX4+RE4+RL4+RS4+RZ4+SG4 | SP4: =IFERROR(SO4/SN4/7,"") | SQ4: =QR4+QY4+RF4+RM4+RT4+SA4+SH4 | SR4: =IFERROR(SQ4/SO4,"") | SS4: =QU4+RB4+RI4+RP4+RW4+SD4+SK4 | ST4: =IFERROR(SO4/SN4/7,"") | US4: 7 | UT4: =SV4+TC4+TJ4+TQ4+TX4+UE4+UL4 | UU4: =IFERROR(UT4/US4/7,"") | UV4: =SW4+TD4+TK4+TR4+TY4+UF4+UM4 | UW4: =IFERROR(UV4/UT4,"") | UX4: =SZ4+TG4+TN4+TU4+UB4+UI4+UP4 | UY4: =IFERROR(UT4/US4/7,"") | WX4: 7 | WY4: =VA4+VH4+VO4+VV4+WC4+WJ4+WQ4 | WZ4: =IFERROR(WY4/WX4/7,"") | XA4: =VB4+VI4+VP4+VW4+WD4+WK4+WR4 | XB4: =IFERROR(XA4/WY4,"") | XC4: =VE4+VL4+VS4+VZ4+WG4+WN4+WU4 | XD4: =IFERROR(WY4/WX4/7,"") | ZC4: 7 | ZD4: =XF4+XM4+XT4+YA4+YH4+YO4+YV4 | ZE4: =IFERROR(ZD4/ZC4/7,"") | ZF4: =XG4+XN4+XU4+YB4+YI4+YP4+YW4 | ZG4: =IFERROR(ZF4/ZD4,"") | ZH4: =XJ4+XQ4+XX4+YE4+YL4+YS4+YZ4 | ZI4: =IFERROR(ZD4/ZC4/7,"") | ABH4: 7 | ABI4: =ZK4+ZR4+ZY4+AAF4+AAM4+AAT4+ABA4 | ABJ4: =IFERROR(ABI4/ABH4/7,"") | ABK4: =ZL4+ZS4+ZZ4+AAG4+AAN4+AAU4+ABB4 | ABL4: =IFERROR(ABK4/ABI4,"") | ABM4: =ZO4+ZV4+AAC4+AAJ4+AAQ4+AAX4+ABE4 | ABN4: =IFERROR(ABI4/ABH4/7,"") | ADM4: 7 | ADN4: =ABP4+ABW4+ACD4+ACK4+ACR4+ACY4+ADF4 | ADO4: =IFERROR(ADN4/ADM4/7,"") | ADP4: =ABQ4+ABX4+ACE4+ACL4+ACS4+ACZ4+ADG4 | ADQ4: =IFERROR(ADP4/ADN4,"") | ADR4: =ABT4+ACA4+ACH4+ACO4+ACV4+ADC4+ADJ4 | ADS4: =IFERROR(ADN4/ADM4/7,"") | AFR4: 7 | AFS4: =ADU4+AEB4+AEI4+AEP4+AEW4+AFD4+AFK4 | AFT4: =IFERROR(AFS4/AFR4/7,"") | AFU4: =ADV4+AEC4+AEJ4+AEQ4+AEX4+AFE4+AFL4 | AFV4: =IFERROR(AFU4/AFS4,"") | AFW4: =ADY4+AEF4+AEM4+AET4+AFA4+AFH4+AFO4 | AFX4: =IFERROR(AFS4/AFR4/7,"") | AHW4: 7 | AHX4: =AFZ4+AGG4+AGN4+AGU4+AHB4+AHI4+AHP4 | AHY4: =IFERROR(AHX4/AHW4/7,"") | AHZ4: =AGA4+AGH4+AGO4+AGV4+AHC4+AHJ4+AHQ4 | AIA4: =IFERROR(AHZ4/AHX4,"") | AIB4: =AGD4+AGK4+AGR4+AGY4+AHF4+AHM4+AHT4 | AIC4: =IFERROR(AHX4/AHW4/7,"") | AKB4: 7 | AKC4: =AIE4+AIL4+AIS4+AIZ4+AJG4+AJN4+AJU4 | AKD4: =IFERROR(AKC4/AKB4/7,"") | AKE4: =AIF4+AIM4+AIT4+AJA4+AJH4+AJO4+AJV4 | AKF4: =IFERROR(AKE4/AKC4,"") | AKG4: =AII4+AIP4+AIW4+AJD4+AJK4+AJR4+AJY4 | AKH4: =IFERROR(AKC4/AKB4/7,"") | AMG4: 7 | AMH4: =AKJ4+AKQ4+AKX4+ALE4+ALL4+ALS4+ALZ4 | AMI4: =IFERROR(AMH4/AMG4/7,"") | AMJ4: =AKK4+AKR4+AKY4+ALF4+ALM4+ALT4+AMA4 | AMK4: =IFERROR(AMJ4/AMH4,"") | AML4: =AKN4+AKU4+ALB4+ALI4+ALP4+ALW4+AMD4 | AMM4: =IFERROR(AMH4/AMG4/7,"") | AOL4: 7 | AOM4: =AMO4+AMV4+ANC4+ANJ4+ANQ4+ANX4+AOE4 | AON4: =IFERROR(AOM4/AOL4/7,"") | AOO4: =AMP4+AMW4+AND4+ANK4+ANR4+ANY4+AOF4 | AOP4: =IFERROR(AOO4/AOM4,"") | AOQ4: =AMS4+AMZ4+ANG4+ANN4+ANU4+AOB4+AOI4 | AOR4: =IFERROR(AOM4/AOL4/7,"") | AQQ4: 7 | AQR4: =AOT4+APA4+APH4+APO4+APV4+AQC4+AQJ4 | AQS4: =IFERROR(AQR4/AQQ4/7,"") | AQT4: =AOU4+APB4+API4+APP4+APW4+AQD4+AQK4 | AQU4: =IFERROR(AQT4/AQR4,"") | AQV4: =AOX4+APE4+APL4+APS4+APZ4+AQG4+AQN4 | AQW4: =IFERROR(AQR4/AQQ4/7,"")
A5: 2 | AZ5: 7 | BA5: =C5+J5+Q5+X5+AE5+AL5+AS5 | BB5: =IFERROR(BA5/AZ5/7,"") | BC5: =D5+K5+R5+Y5+AF5+AM5+AT5 | BD5: =IFERROR(BC5/BA5,"") | BE5: =G5+N5+U5+AB5+AI5+AP5+AW5 | BF5: =IFERROR(BA5/AZ5/7,"") | DE5: 7 | DF5: =BH5+BO5+BV5+CC5+CJ5+CQ5+CX5 | DG5: =IFERROR(DF5/DE5/7,"") | DH5: =BI5+BP5+BW5+CD5+CK5+CR5+CY5 | DI5: =IFERROR(DH5/DF5,"") | DJ5: =BL5+BS5+BZ5+CG5+CN5+CU5+DB5 | DK5: =IFERROR(DF5/DE5/7,"") | FJ5: 7 | FK5: =DM5+DT5+EA5+EH5+EO5+EV5+FC5 | FL5: =IFERROR(FK5/FJ5/7,"") | FM5: =DN5+DU5+EB5+EI5+EP5+EW5+FD5 | FN5: =IFERROR(FM5/FK5,"") | FO5: =DQ5+DX5+EE5+EL5+ES5+EZ5+FG5 | FP5: =IFERROR(FK5/FJ5/7,"") | HO5: 7 | HP5: =FR5+FY5+GF5+GM5+GT5+HA5+HH5 | HQ5: =IFERROR(HP5/HO5/7,"") | HR5: =FS5+FZ5+GG5+GN5+GU5+HB5+HI5 | HS5: =IFERROR(HR5/HP5,"") | HT5: =FV5+GC5+GJ5+GQ5+GX5+HE5+HL5 | HU5: =IFERROR(HP5/HO5/7,"") | JT5: 7 | JU5: =HW5+ID5+IK5+IR5+IY5+JF5+JM5 | JV5: =IFERROR(JU5/JT5/7,"") | JW5: =HX5+IE5+IL5+IS5+IZ5+JG5+JN5 | JX5: =IFERROR(JW5/JU5,"") | JY5: =IA5+IH5+IO5+IV5+JC5+JJ5+JQ5 | JZ5: =IFERROR(JU5/JT5/7,"") | LY5: 7 | LZ5: =KB5+KI5+KP5+KW5+LD5+LK5+LR5 | MA5: =IFERROR(LZ5/LY5/7,"") | MB5: =KC5+KJ5+KQ5+KX5+LE5+LL5+LS5 | MC5: =IFERROR(MB5/LZ5,"") | MD5: =KF5+KM5+KT5+LA5+LH5+LO5+LV5 | ME5: =IFERROR(LZ5/LY5/7,"") | OD5: 7 | OE5: =MG5+MN5+MU5+NB5+NI5+NP5+NW5 | OF5: =IFERROR(OE5/OD5/7,"") | OG5: =MH5+MO5+MV5+NC5+NJ5+NQ5+NX5 | OH5: =IFERROR(OG5/OE5,"") | OI5: =MK5+MR5+MY5+NF5+NM5+NT5+OA5 | OJ5: =IFERROR(OE5/OD5/7,"") | QI5: 7 | QJ5: =OL5+OS5+OZ5+PG5+PN5+PU5+QB5 | QK5: =IFERROR(QJ5/QI5/7,"") | QL5: =OM5+OT5+PA5+PH5+PO5+PV5+QC5 | QM5: =IFERROR(QL5/QJ5,"") | QN5: =OP5+OW5+PD5+PK5+PR5+PY5+QF5 | QO5: =IFERROR(QJ5/QI5/7,"") | SN5: 7 | SO5: =QQ5+QX5+RE5+RL5+RS5+RZ5+SG5 | SP5: =IFERROR(SO5/SN5/7,"") | SQ5: =QR5+QY5+RF5+RM5+RT5+SA5+SH5 | SR5: =IFERROR(SQ5/SO5,"") | SS5: =QU5+RB5+RI5+RP5+RW5+SD5+SK5 | ST5: =IFERROR(SO5/SN5/7,"") | US5: 7 | UT5: =SV5+TC5+TJ5+TQ5+TX5+UE5+UL5 | UU5: =IFERROR(UT5/US5/7,"") | UV5: =SW5+TD5+TK5+TR5+TY5+UF5+UM5 | UW5: =IFERROR(UV5/UT5,"") | UX5: =SZ5+TG5+TN5+TU5+UB5+UI5+UP5 | UY5: =IFERROR(UT5/US5/7,"") | WX5: 7 | WY5: =VA5+VH5+VO5+VV5+WC5+WJ5+WQ5 | WZ5: =IFERROR(WY5/WX5/7,"") | XA5: =VB5+VI5+VP5+VW5+WD5+WK5+WR5 | XB5: =IFERROR(XA5/WY5,"") | XC5: =VE5+VL5+VS5+VZ5+WG5+WN5+WU5 | XD5: =IFERROR(WY5/WX5/7,"") | ZC5: 7 | ZD5: =XF5+XM5+XT5+YA5+YH5+YO5+YV5 | ZE5: =IFERROR(ZD5/ZC5/7,"") | ZF5: =XG5+XN5+XU5+YB5+YI5+YP5+YW5 | ZG5: =IFERROR(ZF5/ZD5,"") | ZH5: =XJ5+XQ5+XX5+YE5+YL5+YS5+YZ5 | ZI5: =IFERROR(ZD5/ZC5/7,"") | ABH5: 7 | ABI5: =ZK5+ZR5+ZY5+AAF5+AAM5+AAT5+ABA5 | ABJ5: =IFERROR(ABI5/ABH5/7,"") | ABK5: =ZL5+ZS5+ZZ5+AAG5+AAN5+AAU5+ABB5 | ABL5: =IFERROR(ABK5/ABI5,"") | ABM5: =ZO5+ZV5+AAC5+AAJ5+AAQ5+AAX5+ABE5 | ABN5: =IFERROR(ABI5/ABH5/7,"") | ADM5: 7 | ADN5: =ABP5+ABW5+ACD5+ACK5+ACR5+ACY5+ADF5 | ADO5: =IFERROR(ADN5/ADM5/7,"") | ADP5: =ABQ5+ABX5+ACE5+ACL5+ACS5+ACZ5+ADG5 | ADQ5: =IFERROR(ADP5/ADN5,"") | ADR5: =ABT5+ACA5+ACH5+ACO5+ACV5+ADC5+ADJ5 | ADS5: =IFERROR(ADN5/ADM5/7,"") | AFR5: 7 | AFS5: =ADU5+AEB5+AEI5+AEP5+AEW5+AFD5+AFK5 | AFT5: =IFERROR(AFS5/AFR5/7,"") | AFU5: =ADV5+AEC5+AEJ5+AEQ5+AEX5+AFE5+AFL5 | AFV5: =IFERROR(AFU5/AFS5,"") | AFW5: =ADY5+AEF5+AEM5+AET5+AFA5+AFH5+AFO5 | AFX5: =IFERROR(AFS5/AFR5/7,"") | AHW5: 7 | AHX5: =AFZ5+AGG5+AGN5+AGU5+AHB5+AHI5+AHP5 | AHY5: =IFERROR(AHX5/AHW5/7,"") | AHZ5: =AGA5+AGH5+AGO5+AGV5+AHC5+AHJ5+AHQ5 | AIA5: =IFERROR(AHZ5/AHX5,"") | AIB5: =AGD5+AGK5+AGR5+AGY5+AHF5+AHM5+AHT5 | AIC5: =IFERROR(AHX5/AHW5/7,"") | AKB5: 7 | AKC5: =AIE5+AIL5+AIS5+AIZ5+AJG5+AJN5+AJU5 | AKD5: =IFERROR(AKC5/AKB5/7,"") | AKE5: =AIF5+AIM5+AIT5+AJA5+AJH5+AJO5+AJV5 | AKF5: =IFERROR(AKE5/AKC5,"") | AKG5: =AII5+AIP5+AIW5+AJD5+AJK5+AJR5+AJY5 | AKH5: =IFERROR(AKC5/AKB5/7,"") | AMG5: 7 | AMH5: =AKJ5+AKQ5+AKX5+ALE5+ALL5+ALS5+ALZ5 | AMI5: =IFERROR(AMH5/AMG5/7,"") | AMJ5: =AKK5+AKR5+AKY5+ALF5+ALM5+ALT5+AMA5 | AMK5: =IFERROR(AMJ5/AMH5,"") | AML5: =AKN5+AKU5+ALB5+ALI5+ALP5+ALW5+AMD5 | AMM5: =IFERROR(AMH5/AMG5/7,"") | AOL5: 7 | AOM5: =AMO5+AMV5+ANC5+ANJ5+ANQ5+ANX5+AOE5 | AON5: =IFERROR(AOM5/AOL5/7,"") | AOO5: =AMP5+AMW5+AND5+ANK5+ANR5+ANY5+AOF5 | AOP5: =IFERROR(AOO5/AOM5,"") | AOQ5: =AMS5+AMZ5+ANG5+ANN5+ANU5+AOB5+AOI5 | AOR5: =IFERROR(AOM5/AOL5/7,"") | AQQ5: 7 | AQR5: =AOT5+APA5+APH5+APO5+APV5+AQC5+AQJ5 | AQS5: =IFERROR(AQR5/AQQ5/7,"") | AQT5: =AOU5+APB5+API5+APP5+APW5+AQD5+AQK5 | AQU5: =IFERROR(AQT5/AQR5,"") | AQV5: =AOX5+APE5+APL5+APS5+APZ5+AQG5+AQN5 | AQW5: =IFERROR(AQR5/AQQ5/7,"")
A6: 3 | AZ6: 7 | BA6: =C6+J6+Q6+X6+AE6+AL6+AS6 | BB6: =IFERROR(BA6/AZ6/7,"") | BC6: =D6+K6+R6+Y6+AF6+AM6+AT6 | BD6: =IFERROR(BC6/BA6,"") | BE6: =G6+N6+U6+AB6+AI6+AP6+AW6 | BF6: =IFERROR(BA6/AZ6/7,"") | DE6: 7 | DF6: =BH6+BO6+BV6+CC6+CJ6+CQ6+CX6 | DG6: =IFERROR(DF6/DE6/7,"") | DH6: =BI6+BP6+BW6+CD6+CK6+CR6+CY6 | DI6: =IFERROR(DH6/DF6,"") | DJ6: =BL6+BS6+BZ6+CG6+CN6+CU6+DB6 | DK6: =IFERROR(DF6/DE6/7,"") | FJ6: 7 | FK6: =DM6+DT6+EA6+EH6+EO6+EV6+FC6 | FL6: =IFERROR(FK6/FJ6/7,"") | FM6: =DN6+DU6+EB6+EI6+EP6+EW6+FD6 | FN6: =IFERROR(FM6/FK6,"") | FO6: =DQ6+DX6+EE6+EL6+ES6+EZ6+FG6 | FP6: =IFERROR(FK6/FJ6/7,"") | HO6: 7 | HP6: =FR6+FY6+GF6+GM6+GT6+HA6+HH6 | HQ6: =IFERROR(HP6/HO6/7,"") | HR6: =FS6+FZ6+GG6+GN6+GU6+HB6+HI6 | HS6: =IFERROR(HR6/HP6,"") | HT6: =FV6+GC6+GJ6+GQ6+GX6+HE6+HL6 | HU6: =IFERROR(HP6/HO6/7,"") | JT6: 7 | JU6: =HW6+ID6+IK6+IR6+IY6+JF6+JM6 | JV6: =IFERROR(JU6/JT6/7,"") | JW6: =HX6+IE6+IL6+IS6+IZ6+JG6+JN6 | JX6: =IFERROR(JW6/JU6,"") | JY6: =IA6+IH6+IO6+IV6+JC6+JJ6+JQ6 | JZ6: =IFERROR(JU6/JT6/7,"") | LY6: 7 | LZ6: =KB6+KI6+KP6+KW6+LD6+LK6+LR6 | MA6: =IFERROR(LZ6/LY6/7,"") | MB6: =KC6+KJ6+KQ6+KX6+LE6+LL6+LS6 | MC6: =IFERROR(MB6/LZ6,"") | MD6: =KF6+KM6+KT6+LA6+LH6+LO6+LV6 | ME6: =IFERROR(LZ6/LY6/7,"") | OD6: 7 | OE6: =MG6+MN6+MU6+NB6+NI6+NP6+NW6 | OF6: =IFERROR(OE6/OD6/7,"") | OG6: =MH6+MO6+MV6+NC6+NJ6+NQ6+NX6 | OH6: =IFERROR(OG6/OE6,"") | OI6: =MK6+MR6+MY6+NF6+NM6+NT6+OA6 | OJ6: =IFERROR(OE6/OD6/7,"") | QI6: 7 | QJ6: =OL6+OS6+OZ6+PG6+PN6+PU6+QB6 | QK6: =IFERROR(QJ6/QI6/7,"") | QL6: =OM6+OT6+PA6+PH6+PO6+PV6+QC6 | QM6: =IFERROR(QL6/QJ6,"") | QN6: =OP6+OW6+PD6+PK6+PR6+PY6+QF6 | QO6: =IFERROR(QJ6/QI6/7,"") | SN6: 7 | SO6: =QQ6+QX6+RE6+RL6+RS6+RZ6+SG6 | SP6: =IFERROR(SO6/SN6/7,"") | SQ6: =QR6+QY6+RF6+RM6+RT6+SA6+SH6 | SR6: =IFERROR(SQ6/SO6,"") | SS6: =QU6+RB6+RI6+RP6+RW6+SD6+SK6 | ST6: =IFERROR(SO6/SN6/7,"") | US6: 7 | UT6: =SV6+TC6+TJ6+TQ6+TX6+UE6+UL6 | UU6: =IFERROR(UT6/US6/7,"") | UV6: =SW6+TD6+TK6+TR6+TY6+UF6+UM6 | UW6: =IFERROR(UV6/UT6,"") | UX6: =SZ6+TG6+TN6+TU6+UB6+UI6+UP6 | UY6: =IFERROR(UT6/US6/7,"") | WX6: 7 | WY6: =VA6+VH6+VO6+VV6+WC6+WJ6+WQ6 | WZ6: =IFERROR(WY6/WX6/7,"") | XA6: =VB6+VI6+VP6+VW6+WD6+WK6+WR6 | XB6: =IFERROR(XA6/WY6,"") | XC6: =VE6+VL6+VS6+VZ6+WG6+WN6+WU6 | XD6: =IFERROR(WY6/WX6/7,"") | ZC6: 7 | ZD6: =XF6+XM6+XT6+YA6+YH6+YO6+YV6 | ZE6: =IFERROR(ZD6/ZC6/7,"") | ZF6: =XG6+XN6+XU6+YB6+YI6+YP6+YW6 | ZG6: =IFERROR(ZF6/ZD6,"") | ZH6: =XJ6+XQ6+XX6+YE6+YL6+YS6+YZ6 | ZI6: =IFERROR(ZD6/ZC6/7,"") | ABH6: 7 | ABI6: =ZK6+ZR6+ZY6+AAF6+AAM6+AAT6+ABA6 | ABJ6: =IFERROR(ABI6/ABH6/7,"") | ABK6: =ZL6+ZS6+ZZ6+AAG6+AAN6+AAU6+ABB6 | ABL6: =IFERROR(ABK6/ABI6,"") | ABM6: =ZO6+ZV6+AAC6+AAJ6+AAQ6+AAX6+ABE6 | ABN6: =IFERROR(ABI6/ABH6/7,"") | ADM6: 7 | ADN6: =ABP6+ABW6+ACD6+ACK6+ACR6+ACY6+ADF6 | ADO6: =IFERROR(ADN6/ADM6/7,"") | ADP6: =ABQ6+ABX6+ACE6+ACL6+ACS6+ACZ6+ADG6 | ADQ6: =IFERROR(ADP6/ADN6,"") | ADR6: =ABT6+ACA6+ACH6+ACO6+ACV6+ADC6+ADJ6 | ADS6: =IFERROR(ADN6/ADM6/7,"") | AFR6: 7 | AFS6: =ADU6+AEB6+AEI6+AEP6+AEW6+AFD6+AFK6 | AFT6: =IFERROR(AFS6/AFR6/7,"") | AFU6: =ADV6+AEC6+AEJ6+AEQ6+AEX6+AFE6+AFL6 | AFV6: =IFERROR(AFU6/AFS6,"") | AFW6: =ADY6+AEF6+AEM6+AET6+AFA6+AFH6+AFO6 | AFX6: =IFERROR(AFS6/AFR6/7,"") | AHW6: 7 | AHX6: =AFZ6+AGG6+AGN6+AGU6+AHB6+AHI6+AHP6 | AHY6: =IFERROR(AHX6/AHW6/7,"") | AHZ6: =AGA6+AGH6+AGO6+AGV6+AHC6+AHJ6+AHQ6 | AIA6: =IFERROR(AHZ6/AHX6,"") | AIB6: =AGD6+AGK6+AGR6+AGY6+AHF6+AHM6+AHT6 | AIC6: =IFERROR(AHX6/AHW6/7,"") | AKB6: 7 | AKC6: =AIE6+AIL6+AIS6+AIZ6+AJG6+AJN6+AJU6 | AKD6: =IFERROR(AKC6/AKB6/7,"") | AKE6: =AIF6+AIM6+AIT6+AJA6+AJH6+AJO6+AJV6 | AKF6: =IFERROR(AKE6/AKC6,"") | AKG6: =AII6+AIP6+AIW6+AJD6+AJK6+AJR6+AJY6 | AKH6: =IFERROR(AKC6/AKB6/7,"") | AMG6: 7 | AMH6: =AKJ6+AKQ6+AKX6+ALE6+ALL6+ALS6+ALZ6 | AMI6: =IFERROR(AMH6/AMG6/7,"") | AMJ6: =AKK6+AKR6+AKY6+ALF6+ALM6+ALT6+AMA6 | AMK6: =IFERROR(AMJ6/AMH6,"") | AML6: =AKN6+AKU6+ALB6+ALI6+ALP6+ALW6+AMD6 | AMM6: =IFERROR(AMH6/AMG6/7,"") | AOL6: 7 | AOM6: =AMO6+AMV6+ANC6+ANJ6+ANQ6+ANX6+AOE6 | AON6: =IFERROR(AOM6/AOL6/7,"") | AOO6: =AMP6+AMW6+AND6+ANK6+ANR6+ANY6+AOF6 | AOP6: =IFERROR(AOO6/AOM6,"") | AOQ6: =AMS6+AMZ6+ANG6+ANN6+ANU6+AOB6+AOI6 | AOR6: =IFERROR(AOM6/AOL6/7,"") | AQQ6: 7 | AQR6: =AOT6+APA6+APH6+APO6+APV6+AQC6+AQJ6 | AQS6: =IFERROR(AQR6/AQQ6/7,"") | AQT6: =AOU6+APB6+API6+APP6+APW6+AQD6+AQK6 | AQU6: =IFERROR(AQT6/AQR6,"") | AQV6: =AOX6+APE6+APL6+APS6+APZ6+AQG6+AQN6 | AQW6: =IFERROR(AQR6/AQQ6/7,"")
A7: 4 | AZ7: 7 | BA7: =C7+J7+Q7+X7+AE7+AL7+AS7 | BB7: =IFERROR(BA7/AZ7/7,"") | BC7: =D7+K7+R7+Y7+AF7+AM7+AT7 | BD7: =IFERROR(BC7/BA7,"") | BE7: =G7+N7+U7+AB7+AI7+AP7+AW7 | BF7: =IFERROR(BA7/AZ7/7,"") | DE7: 7 | DF7: =BH7+BO7+BV7+CC7+CJ7+CQ7+CX7 | DG7: =IFERROR(DF7/DE7/7,"") | DH7: =BI7+BP7+BW7+CD7+CK7+CR7+CY7 | DI7: =IFERROR(DH7/DF7,"") | DJ7: =BL7+BS7+BZ7+CG7+CN7+CU7+DB7 | DK7: =IFERROR(DF7/DE7/7,"") | FJ7: 7 | FK7: =DM7+DT7+EA7+EH7+EO7+EV7+FC7 | FL7: =IFERROR(FK7/FJ7/7,"") | FM7: =DN7+DU7+EB7+EI7+EP7+EW7+FD7 | FN7: =IFERROR(FM7/FK7,"") | FO7: =DQ7+DX7+EE7+EL7+ES7+EZ7+FG7 | FP7: =IFERROR(FK7/FJ7/7,"") | HO7: 7 | HP7: =FR7+FY7+GF7+GM7+GT7+HA7+HH7 | HQ7: =IFERROR(HP7/HO7/7,"") | HR7: =FS7+FZ7+GG7+GN7+GU7+HB7+HI7 | HS7: =IFERROR(HR7/HP7,"") | HT7: =FV7+GC7+GJ7+GQ7+GX7+HE7+HL7 | HU7: =IFERROR(HP7/HO7/7,"") | JT7: 7 | JU7: =HW7+ID7+IK7+IR7+IY7+JF7+JM7 | JV7: =IFERROR(JU7/JT7/7,"") | JW7: =HX7+IE7+IL7+IS7+IZ7+JG7+JN7 | JX7: =IFERROR(JW7/JU7,"") | JY7: =IA7+IH7+IO7+IV7+JC7+JJ7+JQ7 | JZ7: =IFERROR(JU7/JT7/7,"") | LY7: 7 | LZ7: =KB7+KI7+KP7+KW7+LD7+LK7+LR7 | MA7: =IFERROR(LZ7/LY7/7,"") | MB7: =KC7+KJ7+KQ7+KX7+LE7+LL7+LS7 | MC7: =IFERROR(MB7/LZ7,"") | MD7: =KF7+KM7+KT7+LA7+LH7+LO7+LV7 | ME7: =IFERROR(LZ7/LY7/7,"") | OD7: 7 | OE7: =MG7+MN7+MU7+NB7+NI7+NP7+NW7 | OF7: =IFERROR(OE7/OD7/7,"") | OG7: =MH7+MO7+MV7+NC7+NJ7+NQ7+NX7 | OH7: =IFERROR(OG7/OE7,"") | OI7: =MK7+MR7+MY7+NF7+NM7+NT7+OA7 | OJ7: =IFERROR(OE7/OD7/7,"") | QI7: 7 | QJ7: =OL7+OS7+OZ7+PG7+PN7+PU7+QB7 | QK7: =IFERROR(QJ7/QI7/7,"") | QL7: =OM7+OT7+PA7+PH7+PO7+PV7+QC7 | QM7: =IFERROR(QL7/QJ7,"") | QN7: =OP7+OW7+PD7+PK7+PR7+PY7+QF7 | QO7: =IFERROR(QJ7/QI7/7,"") | SN7: 7 | SO7: =QQ7+QX7+RE7+RL7+RS7+RZ7+SG7 | SP7: =IFERROR(SO7/SN7/7,"") | SQ7: =QR7+QY7+RF7+RM7+RT7+SA7+SH7 | SR7: =IFERROR(SQ7/SO7,"") | SS7: =QU7+RB7+RI7+RP7+RW7+SD7+SK7 | ST7: =IFERROR(SO7/SN7/7,"") | US7: 7 | UT7: =SV7+TC7+TJ7+TQ7+TX7+UE7+UL7 | UU7: =IFERROR(UT7/US7/7,"") | UV7: =SW7+TD7+TK7+TR7+TY7+UF7+UM7 | UW7: =IFERROR(UV7/UT7,"") | UX7: =SZ7+TG7+TN7+TU7+UB7+UI7+UP7 | UY7: =IFERROR(UT7/US7/7,"") | WX7: 7 | WY7: =VA7+VH7+VO7+VV7+WC7+WJ7+WQ7 | WZ7: =IFERROR(WY7/WX7/7,"") | XA7: =VB7+VI7+VP7+VW7+WD7+WK7+WR7 | XB7: =IFERROR(XA7/WY7,"") | XC7: =VE7+VL7+VS7+VZ7+WG7+WN7+WU7 | XD7: =IFERROR(WY7/WX7/7,"") | ZC7: 7 | ZD7: =XF7+XM7+XT7+YA7+YH7+YO7+YV7 | ZE7: =IFERROR(ZD7/ZC7/7,"") | ZF7: =XG7+XN7+XU7+YB7+YI7+YP7+YW7 | ZG7: =IFERROR(ZF7/ZD7,"") | ZH7: =XJ7+XQ7+XX7+YE7+YL7+YS7+YZ7 | ZI7: =IFERROR(ZD7/ZC7/7,"") | ABH7: 7 | ABI7: =ZK7+ZR7+ZY7+AAF7+AAM7+AAT7+ABA7 | ABJ7: =IFERROR(ABI7/ABH7/7,"") | ABK7: =ZL7+ZS7+ZZ7+AAG7+AAN7+AAU7+ABB7 | ABL7: =IFERROR(ABK7/ABI7,"") | ABM7: =ZO7+ZV7+AAC7+AAJ7+AAQ7+AAX7+ABE7 | ABN7: =IFERROR(ABI7/ABH7/7,"") | ADM7: 7 | ADN7: =ABP7+ABW7+ACD7+ACK7+ACR7+ACY7+ADF7 | ADO7: =IFERROR(ADN7/ADM7/7,"") | ADP7: =ABQ7+ABX7+ACE7+ACL7+ACS7+ACZ7+ADG7 | ADQ7: =IFERROR(ADP7/ADN7,"") | ADR7: =ABT7+ACA7+ACH7+ACO7+ACV7+ADC7+ADJ7 | ADS7: =IFERROR(ADN7/ADM7/7,"") | AFR7: 7 | AFS7: =ADU7+AEB7+AEI7+AEP7+AEW7+AFD7+AFK7 | AFT7: =IFERROR(AFS7/AFR7/7,"") | AFU7: =ADV7+AEC7+AEJ7+AEQ7+AEX7+AFE7+AFL7 | AFV7: =IFERROR(AFU7/AFS7,"") | AFW7: =ADY7+AEF7+AEM7+AET7+AFA7+AFH7+AFO7 | AFX7: =IFERROR(AFS7/AFR7/7,"") | AHW7: 7 | AHX7: =AFZ7+AGG7+AGN7+AGU7+AHB7+AHI7+AHP7 | AHY7: =IFERROR(AHX7/AHW7/7,"") | AHZ7: =AGA7+AGH7+AGO7+AGV7+AHC7+AHJ7+AHQ7 | AIA7: =IFERROR(AHZ7/AHX7,"") | AIB7: =AGD7+AGK7+AGR7+AGY7+AHF7+AHM7+AHT7 | AIC7: =IFERROR(AHX7/AHW7/7,"") | AKB7: 7 | AKC7: =AIE7+AIL7+AIS7+AIZ7+AJG7+AJN7+AJU7 | AKD7: =IFERROR(AKC7/AKB7/7,"") | AKE7: =AIF7+AIM7+AIT7+AJA7+AJH7+AJO7+AJV7 | AKF7: =IFERROR(AKE7/AKC7,"") | AKG7: =AII7+AIP7+AIW7+AJD7+AJK7+AJR7+AJY7 | AKH7: =IFERROR(AKC7/AKB7/7,"") | AMG7: 7 | AMH7: =AKJ7+AKQ7+AKX7+ALE7+ALL7+ALS7+ALZ7 | AMI7: =IFERROR(AMH7/AMG7/7,"") | AMJ7: =AKK7+AKR7+AKY7+ALF7+ALM7+ALT7+AMA7 | AMK7: =IFERROR(AMJ7/AMH7,"") | AML7: =AKN7+AKU7+ALB7+ALI7+ALP7+ALW7+AMD7 | AMM7: =IFERROR(AMH7/AMG7/7,"") | AOL7: 7 | AOM7: =AMO7+AMV7+ANC7+ANJ7+ANQ7+ANX7+AOE7 | AON7: =IFERROR(AOM7/AOL7/7,"") | AOO7: =AMP7+AMW7+AND7+ANK7+ANR7+ANY7+AOF7 | AOP7: =IFERROR(AOO7/AOM7,"") | AOQ7: =AMS7+AMZ7+ANG7+ANN7+ANU7+AOB7+AOI7 | AOR7: =IFERROR(AOM7/AOL7/7,"") | AQQ7: 7 | AQR7: =AOT7+APA7+APH7+APO7+APV7+AQC7+AQJ7 | AQS7: =IFERROR(AQR7/AQQ7/7,"") | AQT7: =AOU7+APB7+API7+APP7+APW7+AQD7+AQK7 | AQU7: =IFERROR(AQT7/AQR7,"") | AQV7: =AOX7+APE7+APL7+APS7+APZ7+AQG7+AQN7 | AQW7: =IFERROR(AQR7/AQQ7/7,"")
A8: 5 | AZ8: 7 | BA8: =C8+J8+Q8+X8+AE8+AL8+AS8 | BB8: =IFERROR(BA8/AZ8/7,"") | BC8: =D8+K8+R8+Y8+AF8+AM8+AT8 | BD8: =IFERROR(BC8/BA8,"") | BE8: =G8+N8+U8+AB8+AI8+AP8+AW8 | BF8: =IFERROR(BA8/AZ8/7,"") | DE8: 7 | DF8: =BH8+BO8+BV8+CC8+CJ8+CQ8+CX8 | DG8: =IFERROR(DF8/DE8/7,"") | DH8: =BI8+BP8+BW8+CD8+CK8+CR8+CY8 | DI8: =IFERROR(DH8/DF8,"") | DJ8: =BL8+BS8+BZ8+CG8+CN8+CU8+DB8 | DK8: =IFERROR(DF8/DE8/7,"") | FJ8: 7 | FK8: =DM8+DT8+EA8+EH8+EO8+EV8+FC8 | FL8: =IFERROR(FK8/FJ8/7,"") | FM8: =DN8+DU8+EB8+EI8+EP8+EW8+FD8 | FN8: =IFERROR(FM8/FK8,"") | FO8: =DQ8+DX8+EE8+EL8+ES8+EZ8+FG8 | FP8: =IFERROR(FK8/FJ8/7,"") | HO8: 7 | HP8: =FR8+FY8+GF8+GM8+GT8+HA8+HH8 | HQ8: =IFERROR(HP8/HO8/7,"") | HR8: =FS8+FZ8+GG8+GN8+GU8+HB8+HI8 | HS8: =IFERROR(HR8/HP8,"") | HT8: =FV8+GC8+GJ8+GQ8+GX8+HE8+HL8 | HU8: =IFERROR(HP8/HO8/7,"") | JT8: 7 | JU8: =HW8+ID8+IK8+IR8+IY8+JF8+JM8 | JV8: =IFERROR(JU8/JT8/7,"") | JW8: =HX8+IE8+IL8+IS8+IZ8+JG8+JN8 | JX8: =IFERROR(JW8/JU8,"") | JY8: =IA8+IH8+IO8+IV8+JC8+JJ8+JQ8 | JZ8: =IFERROR(JU8/JT8/7,"") | LY8: 7 | LZ8: =KB8+KI8+KP8+KW8+LD8+LK8+LR8 | MA8: =IFERROR(LZ8/LY8/7,"") | MB8: =KC8+KJ8+KQ8+KX8+LE8+LL8+LS8 | MC8: =IFERROR(MB8/LZ8,"") | MD8: =KF8+KM8+KT8+LA8+LH8+LO8+LV8 | ME8: =IFERROR(LZ8/LY8/7,"") | OD8: 7 | OE8: =MG8+MN8+MU8+NB8+NI8+NP8+NW8 | OF8: =IFERROR(OE8/OD8/7,"") | OG8: =MH8+MO8+MV8+NC8+NJ8+NQ8+NX8 | OH8: =IFERROR(OG8/OE8,"") | OI8: =MK8+MR8+MY8+NF8+NM8+NT8+OA8 | OJ8: =IFERROR(OE8/OD8/7,"") | QI8: 7 | QJ8: =OL8+OS8+OZ8+PG8+PN8+PU8+QB8 | QK8: =IFERROR(QJ8/QI8/7,"") | QL8: =OM8+OT8+PA8+PH8+PO8+PV8+QC8 | QM8: =IFERROR(QL8/QJ8,"") | QN8: =OP8+OW8+PD8+PK8+PR8+PY8+QF8 | QO8: =IFERROR(QJ8/QI8/7,"") | SN8: 7 | SO8: =QQ8+QX8+RE8+RL8+RS8+RZ8+SG8 | SP8: =IFERROR(SO8/SN8/7,"") | SQ8: =QR8+QY8+RF8+RM8+RT8+SA8+SH8 | SR8: =IFERROR(SQ8/SO8,"") | SS8: =QU8+RB8+RI8+RP8+RW8+SD8+SK8 | ST8: =IFERROR(SO8/SN8/7,"") | US8: 7 | UT8: =SV8+TC8+TJ8+TQ8+TX8+UE8+UL8 | UU8: =IFERROR(UT8/US8/7,"") | UV8: =SW8+TD8+TK8+TR8+TY8+UF8+UM8 | UW8: =IFERROR(UV8/UT8,"") | UX8: =SZ8+TG8+TN8+TU8+UB8+UI8+UP8 | UY8: =IFERROR(UT8/US8/7,"") | WX8: 7 | WY8: =VA8+VH8+VO8+VV8+WC8+WJ8+WQ8 | WZ8: =IFERROR(WY8/WX8/7,"") | XA8: =VB8+VI8+VP8+VW8+WD8+WK8+WR8 | XB8: =IFERROR(XA8/WY8,"") | XC8: =VE8+VL8+VS8+VZ8+WG8+WN8+WU8 | XD8: =IFERROR(WY8/WX8/7,"") | ZC8: 7 | ZD8: =XF8+XM8+XT8+YA8+YH8+YO8+YV8 | ZE8: =IFERROR(ZD8/ZC8/7,"") | ZF8: =XG8+XN8+XU8+YB8+YI8+YP8+YW8 | ZG8: =IFERROR(ZF8/ZD8,"") | ZH8: =XJ8+XQ8+XX8+YE8+YL8+YS8+YZ8 | ZI8: =IFERROR(ZD8/ZC8/7,"") | ABH8: 7 | ABI8: =ZK8+ZR8+ZY8+AAF8+AAM8+AAT8+ABA8 | ABJ8: =IFERROR(ABI8/ABH8/7,"") | ABK8: =ZL8+ZS8+ZZ8+AAG8+AAN8+AAU8+ABB8 | ABL8: =IFERROR(ABK8/ABI8,"") | ABM8: =ZO8+ZV8+AAC8+AAJ8+AAQ8+AAX8+ABE8 | ABN8: =IFERROR(ABI8/ABH8/7,"") | ADM8: 7 | ADN8: =ABP8+ABW8+ACD8+ACK8+ACR8+ACY8+ADF8 | ADO8: =IFERROR(ADN8/ADM8/7,"") | ADP8: =ABQ8+ABX8+ACE8+ACL8+ACS8+ACZ8+ADG8 | ADQ8: =IFERROR(ADP8/ADN8,"") | ADR8: =ABT8+ACA8+ACH8+ACO8+ACV8+ADC8+ADJ8 | ADS8: =IFERROR(ADN8/ADM8/7,"") | AFR8: 7 | AFS8: =ADU8+AEB8+AEI8+AEP8+AEW8+AFD8+AFK8 | AFT8: =IFERROR(AFS8/AFR8/7,"") | AFU8: =ADV8+AEC8+AEJ8+AEQ8+AEX8+AFE8+AFL8 | AFV8: =IFERROR(AFU8/AFS8,"") | AFW8: =ADY8+AEF8+AEM8+AET8+AFA8+AFH8+AFO8 | AFX8: =IFERROR(AFS8/AFR8/7,"") | AHW8: 7 | AHX8: =AFZ8+AGG8+AGN8+AGU8+AHB8+AHI8+AHP8 | AHY8: =IFERROR(AHX8/AHW8/7,"") | AHZ8: =AGA8+AGH8+AGO8+AGV8+AHC8+AHJ8+AHQ8 | AIA8: =IFERROR(AHZ8/AHX8,"") | AIB8: =AGD8+AGK8+AGR8+AGY8+AHF8+AHM8+AHT8 | AIC8: =IFERROR(AHX8/AHW8/7,"") | AKB8: 7 | AKC8: =AIE8+AIL8+AIS8+AIZ8+AJG8+AJN8+AJU8 | AKD8: =IFERROR(AKC8/AKB8/7,"") | AKE8: =AIF8+AIM8+AIT8+AJA8+AJH8+AJO8+AJV8 | AKF8: =IFERROR(AKE8/AKC8,"") | AKG8: =AII8+AIP8+AIW8+AJD8+AJK8+AJR8+AJY8 | AKH8: =IFERROR(AKC8/AKB8/7,"") | AMG8: 7 | AMH8: =AKJ8+AKQ8+AKX8+ALE8+ALL8+ALS8+ALZ8 | AMI8: =IFERROR(AMH8/AMG8/7,"") | AMJ8: =AKK8+AKR8+AKY8+ALF8+ALM8+ALT8+AMA8 | AMK8: =IFERROR(AMJ8/AMH8,"") | AML8: =AKN8+AKU8+ALB8+ALI8+ALP8+ALW8+AMD8 | AMM8: =IFERROR(AMH8/AMG8/7,"") | AOL8: 7 | AOM8: =AMO8+AMV8+ANC8+ANJ8+ANQ8+ANX8+AOE8 | AON8: =IFERROR(AOM8/AOL8/7,"") | AOO8: =AMP8+AMW8+AND8+ANK8+ANR8+ANY8+AOF8 | AOP8: =IFERROR(AOO8/AOM8,"") | AOQ8: =AMS8+AMZ8+ANG8+ANN8+ANU8+AOB8+AOI8 | AOR8: =IFERROR(AOM8/AOL8/7,"") | AQQ8: 7 | AQR8: =AOT8+APA8+APH8+APO8+APV8+AQC8+AQJ8 | AQS8: =IFERROR(AQR8/AQQ8/7,"") | AQT8: =AOU8+APB8+API8+APP8+APW8+AQD8+AQK8 | AQU8: =IFERROR(AQT8/AQR8,"") | AQV8: =AOX8+APE8+APL8+APS8+APZ8+AQG8+AQN8 | AQW8: =IFERROR(AQR8/AQQ8/7,"")
A9: 6 | AZ9: 7 | BA9: =C9+J9+Q9+X9+AE9+AL9+AS9 | BB9: =IFERROR(BA9/AZ9/7,"") | BC9: =D9+K9+R9+Y9+AF9+AM9+AT9 | BD9: =IFERROR(BC9/BA9,"") | BE9: =G9+N9+U9+AB9+AI9+AP9+AW9 | BF9: =IFERROR(BA9/AZ9/7,"") | DE9: 7 | DF9: =BH9+BO9+BV9+CC9+CJ9+CQ9+CX9 | DG9: =IFERROR(DF9/DE9/7,"") | DH9: =BI9+BP9+BW9+CD9+CK9+CR9+CY9 | DI9: =IFERROR(DH9/DF9,"") | DJ9: =BL9+BS9+BZ9+CG9+CN9+CU9+DB9 | DK9: =IFERROR(DF9/DE9/7,"") | FJ9: 7 | FK9: =DM9+DT9+EA9+EH9+EO9+EV9+FC9 | FL9: =IFERROR(FK9/FJ9/7,"") | FM9: =DN9+DU9+EB9+EI9+EP9+EW9+FD9 | FN9: =IFERROR(FM9/FK9,"") | FO9: =DQ9+DX9+EE9+EL9+ES9+EZ9+FG9 | FP9: =IFERROR(FK9/FJ9/7,"") | HO9: 7 | HP9: =FR9+FY9+GF9+GM9+GT9+HA9+HH9 | HQ9: =IFERROR(HP9/HO9/7,"") | HR9: =FS9+FZ9+GG9+GN9+GU9+HB9+HI9 | HS9: =IFERROR(HR9/HP9,"") | HT9: =FV9+GC9+GJ9+GQ9+GX9+HE9+HL9 | HU9: =IFERROR(HP9/HO9/7,"") | JT9: 7 | JU9: =HW9+ID9+IK9+IR9+IY9+JF9+JM9 | JV9: =IFERROR(JU9/JT9/7,"") | JW9: =HX9+IE9+IL9+IS9+IZ9+JG9+JN9 | JX9: =IFERROR(JW9/JU9,"") | JY9: =IA9+IH9+IO9+IV9+JC9+JJ9+JQ9 | JZ9: =IFERROR(JU9/JT9/7,"") | LY9: 7 | LZ9: =KB9+KI9+KP9+KW9+LD9+LK9+LR9 | MA9: =IFERROR(LZ9/LY9/7,"") | MB9: =KC9+KJ9+KQ9+KX9+LE9+LL9+LS9 | MC9: =IFERROR(MB9/LZ9,"") | MD9: =KF9+KM9+KT9+LA9+LH9+LO9+LV9 | ME9: =IFERROR(LZ9/LY9/7,"") | OD9: 7 | OE9: =MG9+MN9+MU9+NB9+NI9+NP9+NW9 | OF9: =IFERROR(OE9/OD9/7,"") | OG9: =MH9+MO9+MV9+NC9+NJ9+NQ9+NX9 | OH9: =IFERROR(OG9/OE9,"") | OI9: =MK9+MR9+MY9+NF9+NM9+NT9+OA9 | OJ9: =IFERROR(OE9/OD9/7,"") | QI9: 7 | QJ9: =OL9+OS9+OZ9+PG9+PN9+PU9+QB9 | QK9: =IFERROR(QJ9/QI9/7,"") | QL9: =OM9+OT9+PA9+PH9+PO9+PV9+QC9 | QM9: =IFERROR(QL9/QJ9,"") | QN9: =OP9+OW9+PD9+PK9+PR9+PY9+QF9 | QO9: =IFERROR(QJ9/QI9/7,"") | SN9: 7 | SO9: =QQ9+QX9+RE9+RL9+RS9+RZ9+SG9 | SP9: =IFERROR(SO9/SN9/7,"") | SQ9: =QR9+QY9+RF9+RM9+RT9+SA9+SH9 | SR9: =IFERROR(SQ9/SO9,"") | SS9: =QU9+RB9+RI9+RP9+RW9+SD9+SK9 | ST9: =IFERROR(SO9/SN9/7,"") | US9: 7 | UT9: =SV9+TC9+TJ9+TQ9+TX9+UE9+UL9 | UU9: =IFERROR(UT9/US9/7,"") | UV9: =SW9+TD9+TK9+TR9+TY9+UF9+UM9 | UW9: =IFERROR(UV9/UT9,"") | UX9: =SZ9+TG9+TN9+TU9+UB9+UI9+UP9 | UY9: =IFERROR(UT9/US9/7,"") | WX9: 7 | WY9: =VA9+VH9+VO9+VV9+WC9+WJ9+WQ9 | WZ9: =IFERROR(WY9/WX9/7,"") | XA9: =VB9+VI9+VP9+VW9+WD9+WK9+WR9 | XB9: =IFERROR(XA9/WY9,"") | XC9: =VE9+VL9+VS9+VZ9+WG9+WN9+WU9 | XD9: =IFERROR(WY9/WX9/7,"") | ZC9: 7 | ZD9: =XF9+XM9+XT9+YA9+YH9+YO9+YV9 | ZE9: =IFERROR(ZD9/ZC9/7,"") | ZF9: =XG9+XN9+XU9+YB9+YI9+YP9+YW9 | ZG9: =IFERROR(ZF9/ZD9,"") | ZH9: =XJ9+XQ9+XX9+YE9+YL9+YS9+YZ9 | ZI9: =IFERROR(ZD9/ZC9/7,"") | ABH9: 7 | ABI9: =ZK9+ZR9+ZY9+AAF9+AAM9+AAT9+ABA9 | ABJ9: =IFERROR(ABI9/ABH9/7,"") | ABK9: =ZL9+ZS9+ZZ9+AAG9+AAN9+AAU9+ABB9 | ABL9: =IFERROR(ABK9/ABI9,"") | ABM9: =ZO9+ZV9+AAC9+AAJ9+AAQ9+AAX9+ABE9 | ABN9: =IFERROR(ABI9/ABH9/7,"") | ADM9: 7 | ADN9: =ABP9+ABW9+ACD9+ACK9+ACR9+ACY9+ADF9 | ADO9: =IFERROR(ADN9/ADM9/7,"") | ADP9: =ABQ9+ABX9+ACE9+ACL9+ACS9+ACZ9+ADG9 | ADQ9: =IFERROR(ADP9/ADN9,"") | ADR9: =ABT9+ACA9+ACH9+ACO9+ACV9+ADC9+ADJ9 | ADS9: =IFERROR(ADN9/ADM9/7,"") | AFR9: 7 | AFS9: =ADU9+AEB9+AEI9+AEP9+AEW9+AFD9+AFK9 | AFT9: =IFERROR(AFS9/AFR9/7,"") | AFU9: =ADV9+AEC9+AEJ9+AEQ9+AEX9+AFE9+AFL9 | AFV9: =IFERROR(AFU9/AFS9,"") | AFW9: =ADY9+AEF9+AEM9+AET9+AFA9+AFH9+AFO9 | AFX9: =IFERROR(AFS9/AFR9/7,"") | AHW9: 7 | AHX9: =AFZ9+AGG9+AGN9+AGU9+AHB9+AHI9+AHP9 | AHY9: =IFERROR(AHX9/AHW9/7,"") | AHZ9: =AGA9+AGH9+AGO9+AGV9+AHC9+AHJ9+AHQ9 | AIA9: =IFERROR(AHZ9/AHX9,"") | AIB9: =AGD9+AGK9+AGR9+AGY9+AHF9+AHM9+AHT9 | AIC9: =IFERROR(AHX9/AHW9/7,"") | AKB9: 7 | AKC9: =AIE9+AIL9+AIS9+AIZ9+AJG9+AJN9+AJU9 | AKD9: =IFERROR(AKC9/AKB9/7,"") | AKE9: =AIF9+AIM9+AIT9+AJA9+AJH9+AJO9+AJV9 | AKF9: =IFERROR(AKE9/AKC9,"") | AKG9: =AII9+AIP9+AIW9+AJD9+AJK9+AJR9+AJY9 | AKH9: =IFERROR(AKC9/AKB9/7,"") | AMG9: 7 | AMH9: =AKJ9+AKQ9+AKX9+ALE9+ALL9+ALS9+ALZ9 | AMI9: =IFERROR(AMH9/AMG9/7,"") | AMJ9: =AKK9+AKR9+AKY9+ALF9+ALM9+ALT9+AMA9 | AMK9: =IFERROR(AMJ9/AMH9,"") | AML9: =AKN9+AKU9+ALB9+ALI9+ALP9+ALW9+AMD9 | AMM9: =IFERROR(AMH9/AMG9/7,"") | AOL9: 7 | AOM9: =AMO9+AMV9+ANC9+ANJ9+ANQ9+ANX9+AOE9 | AON9: =IFERROR(AOM9/AOL9/7,"") | AOO9: =AMP9+AMW9+AND9+ANK9+ANR9+ANY9+AOF9 | AOP9: =IFERROR(AOO9/AOM9,"") | AOQ9: =AMS9+AMZ9+ANG9+ANN9+ANU9+AOB9+AOI9 | AOR9: =IFERROR(AOM9/AOL9/7,"") | AQQ9: 7 | AQR9: =AOT9+APA9+APH9+APO9+APV9+AQC9+AQJ9 | AQS9: =IFERROR(AQR9/AQQ9/7,"") | AQT9: =AOU9+APB9+API9+APP9+APW9+AQD9+AQK9 | AQU9: =IFERROR(AQT9/AQR9,"") | AQV9: =AOX9+APE9+APL9+APS9+APZ9+AQG9+AQN9 | AQW9: =IFERROR(AQR9/AQQ9/7,"")
A10: 7 | AZ10: 7 | BA10: =C10+J10+Q10+X10+AE10+AL10+AS10 | BB10: =IFERROR(BA10/AZ10/7,"") | BC10: =D10+K10+R10+Y10+AF10+AM10+AT10 | BD10: =IFERROR(BC10/BA10,"") | BE10: =G10+N10+U10+AB10+AI10+AP10+AW10 | BF10: =IFERROR(BA10/AZ10/7,"") | DE10: 7 | DF10: =BH10+BO10+BV10+CC10+CJ10+CQ10+CX10 | DG10: =IFERROR(DF10/DE10/7,"") | DH10: =BI10+BP10+BW10+CD10+CK10+CR10+CY10 | DI10: =IFERROR(DH10/DF10,"") | DJ10: =BL10+BS10+BZ10+CG10+CN10+CU10+DB10 | DK10: =IFERROR(DF10/DE10/7,"") | FJ10: 7 | FK10: =DM10+DT10+EA10+EH10+EO10+EV10+FC10 | FL10: =IFERROR(FK10/FJ10/7,"") | FM10: =DN10+DU10+EB10+EI10+EP10+EW10+FD10 | FN10: =IFERROR(FM10/FK10,"") | FO10: =DQ10+DX10+EE10+EL10+ES10+EZ10+FG10 | FP10: =IFERROR(FK10/FJ10/7,"") | HO10: 7 | HP10: =FR10+FY10+GF10+GM10+GT10+HA10+HH10 | HQ10: =IFERROR(HP10/HO10/7,"") | HR10: =FS10+FZ10+GG10+GN10+GU10+HB10+HI10 | HS10: =IFERROR(HR10/HP10,"") | HT10: =FV10+GC10+GJ10+GQ10+GX10+HE10+HL10 | HU10: =IFERROR(HP10/HO10/7,"") | JT10: 7 | JU10: =HW10+ID10+IK10+IR10+IY10+JF10+JM10 | JV10: =IFERROR(JU10/JT10/7,"") | JW10: =HX10+IE10+IL10+IS10+IZ10+JG10+JN10 | JX10: =IFERROR(JW10/JU10,"") | JY10: =IA10+IH10+IO10+IV10+JC10+JJ10+JQ10 | JZ10: =IFERROR(JU10/JT10/7,"") | LY10: 7 | LZ10: =KB10+KI10+KP10+KW10+LD10+LK10+LR10 | MA10: =IFERROR(LZ10/LY10/7,"") | MB10: =KC10+KJ10+KQ10+KX10+LE10+LL10+LS10 | MC10: =IFERROR(MB10/LZ10,"") | MD10: =KF10+KM10+KT10+LA10+LH10+LO10+LV10 | ME10: =IFERROR(LZ10/LY10/7,"") | OD10: 7 | OE10: =MG10+MN10+MU10+NB10+NI10+NP10+NW10 | OF10: =IFERROR(OE10/OD10/7,"") | OG10: =MH10+MO10+MV10+NC10+NJ10+NQ10+NX10 | OH10: =IFERROR(OG10/OE10,"") | OI10: =MK10+MR10+MY10+NF10+NM10+NT10+OA10 | OJ10: =IFERROR(OE10/OD10/7,"") | QI10: 7 | QJ10: =OL10+OS10+OZ10+PG10+PN10+PU10+QB10 | QK10: =IFERROR(QJ10/QI10/7,"") | QL10: =OM10+OT10+PA10+PH10+PO10+PV10+QC10 | QM10: =IFERROR(QL10/QJ10,"") | QN10: =OP10+OW10+PD10+PK10+PR10+PY10+QF10 | QO10: =IFERROR(QJ10/QI10/7,"") | SN10: 7 | SO10: =QQ10+QX10+RE10+RL10+RS10+RZ10+SG10 | SP10: =IFERROR(SO10/SN10/7,"") | SQ10: =QR10+QY10+RF10+RM10+RT10+SA10+SH10 | SR10: =IFERROR(SQ10/SO10,"") | SS10: =QU10+RB10+RI10+RP10+RW10+SD10+SK10 | ST10: =IFERROR(SO10/SN10/7,"") | US10: 7 | UT10: =SV10+TC10+TJ10+TQ10+TX10+UE10+UL10 | UU10: =IFERROR(UT10/US10/7,"") | UV10: =SW10+TD10+TK10+TR10+TY10+UF10+UM10 | UW10: =IFERROR(UV10/UT10,"") | UX10: =SZ10+TG10+TN10+TU10+UB10+UI10+UP10 | UY10: =IFERROR(UT10/US10/7,"") | WX10: 7 | WY10: =VA10+VH10+VO10+VV10+WC10+WJ10+WQ10 | WZ10: =IFERROR(WY10/WX10/7,"") | XA10: =VB10+VI10+VP10+VW10+WD10+WK10+WR10 | XB10: =IFERROR(XA10/WY10,"") | XC10: =VE10+VL10+VS10+VZ10+WG10+WN10+WU10 | XD10: =IFERROR(WY10/WX10/7,"") | ZC10: 7 | ZD10: =XF10+XM10+XT10+YA10+YH10+YO10+YV10 | ZE10: =IFERROR(ZD10/ZC10/7,"") | ZF10: =XG10+XN10+XU10+YB10+YI10+YP10+YW10 | ZG10: =IFERROR(ZF10/ZD10,"") | ZH10: =XJ10+XQ10+XX10+YE10+YL10+YS10+YZ10 | ZI10: =IFERROR(ZD10/ZC10/7,"") | ABH10: 7 | ABI10: =ZK10+ZR10+ZY10+AAF10+AAM10+AAT10+ABA10 | ABJ10: =IFERROR(ABI10/ABH10/7,"") | ABK10: =ZL10+ZS10+ZZ10+AAG10+AAN10+AAU10+ABB10 | ABL10: =IFERROR(ABK10/ABI10,"") | ABM10: =ZO10+ZV10+AAC10+AAJ10+AAQ10+AAX10+ABE10 | ABN10: =IFERROR(ABI10/ABH10/7,"") | ADM10: 7 | ADN10: =ABP10+ABW10+ACD10+ACK10+ACR10+ACY10+ADF10 | ADO10: =IFERROR(ADN10/ADM10/7,"") | ADP10: =ABQ10+ABX10+ACE10+ACL10+ACS10+ACZ10+ADG10 | ADQ10: =IFERROR(ADP10/ADN10,"") | ADR10: =ABT10+ACA10+ACH10+ACO10+ACV10+ADC10+ADJ10 | ADS10: =IFERROR(ADN10/ADM10/7,"") | AFR10: 7 | AFS10: =ADU10+AEB10+AEI10+AEP10+AEW10+AFD10+AFK10 | AFT10: =IFERROR(AFS10/AFR10/7,"") | AFU10: =ADV10+AEC10+AEJ10+AEQ10+AEX10+AFE10+AFL10 | AFV10: =IFERROR(AFU10/AFS10,"") | AFW10: =ADY10+AEF10+AEM10+AET10+AFA10+AFH10+AFO10 | AFX10: =IFERROR(AFS10/AFR10/7,"") | AHW10: 7 | AHX10: =AFZ10+AGG10+AGN10+AGU10+AHB10+AHI10+AHP10 | AHY10: =IFERROR(AHX10/AHW10/7,"") | AHZ10: =AGA10+AGH10+AGO10+AGV10+AHC10+AHJ10+AHQ10 | AIA10: =IFERROR(AHZ10/AHX10,"") | AIB10: =AGD10+AGK10+AGR10+AGY10+AHF10+AHM10+AHT10 | AIC10: =IFERROR(AHX10/AHW10/7,"") | AKB10: 7 | AKC10: =AIE10+AIL10+AIS10+AIZ10+AJG10+AJN10+AJU10 | AKD10: =IFERROR(AKC10/AKB10/7,"") | AKE10: =AIF10+AIM10+AIT10+AJA10+AJH10+AJO10+AJV10 | AKF10: =IFERROR(AKE10/AKC10,"") | AKG10: =AII10+AIP10+AIW10+AJD10+AJK10+AJR10+AJY10 | AKH10: =IFERROR(AKC10/AKB10/7,"") | AMG10: 7 | AMH10: =AKJ10+AKQ10+AKX10+ALE10+ALL10+ALS10+ALZ10 | AMI10: =IFERROR(AMH10/AMG10/7,"") | AMJ10: =AKK10+AKR10+AKY10+ALF10+ALM10+ALT10+AMA10 | AMK10: =IFERROR(AMJ10/AMH10,"") | AML10: =AKN10+AKU10+ALB10+ALI10+ALP10+ALW10+AMD10 | AMM10: =IFERROR(AMH10/AMG10/7,"") | AOL10: 7 | AOM10: =AMO10+AMV10+ANC10+ANJ10+ANQ10+ANX10+AOE10 | AON10: =IFERROR(AOM10/AOL10/7,"") | AOO10: =AMP10+AMW10+AND10+ANK10+ANR10+ANY10+AOF10 | AOP10: =IFERROR(AOO10/AOM10,"") | AOQ10: =AMS10+AMZ10+ANG10+ANN10+ANU10+AOB10+AOI10 | AOR10: =IFERROR(AOM10/AOL10/7,"") | AQQ10: 7 | AQR10: =AOT10+APA10+APH10+APO10+APV10+AQC10+AQJ10 | AQS10: =IFERROR(AQR10/AQQ10/7,"") | AQT10: =AOU10+APB10+API10+APP10+APW10+AQD10+AQK10 | AQU10: =IFERROR(AQT10/AQR10,"") | AQV10: =AOX10+APE10+APL10+APS10+APZ10+AQG10+AQN10 | AQW10: =IFERROR(AQR10/AQQ10/7,"")
A11: 8 | AZ11: 7 | BA11: =C11+J11+Q11+X11+AE11+AL11+AS11 | BB11: =IFERROR(BA11/AZ11/7,"") | BC11: =D11+K11+R11+Y11+AF11+AM11+AT11 | BD11: =IFERROR(BC11/BA11,"") | BE11: =G11+N11+U11+AB11+AI11+AP11+AW11 | BF11: =IFERROR(BA11/AZ11/7,"") | DE11: 7 | DF11: =BH11+BO11+BV11+CC11+CJ11+CQ11+CX11 | DG11: =IFERROR(DF11/DE11/7,"") | DH11: =BI11+BP11+BW11+CD11+CK11+CR11+CY11 | DI11: =IFERROR(DH11/DF11,"") | DJ11: =BL11+BS11+BZ11+CG11+CN11+CU11+DB11 | DK11: =IFERROR(DF11/DE11/7,"") | FJ11: 7 | FK11: =DM11+DT11+EA11+EH11+EO11+EV11+FC11 | FL11: =IFERROR(FK11/FJ11/7,"") | FM11: =DN11+DU11+EB11+EI11+EP11+EW11+FD11 | FN11: =IFERROR(FM11/FK11,"") | FO11: =DQ11+DX11+EE11+EL11+ES11+EZ11+FG11 | FP11: =IFERROR(FK11/FJ11/7,"") | HO11: 7 | HP11: =FR11+FY11+GF11+GM11+GT11+HA11+HH11 | HQ11: =IFERROR(HP11/HO11/7,"") | HR11: =FS11+FZ11+GG11+GN11+GU11+HB11+HI11 | HS11: =IFERROR(HR11/HP11,"") | HT11: =FV11+GC11+GJ11+GQ11+GX11+HE11+HL11 | HU11: =IFERROR(HP11/HO11/7,"") | JT11: 7 | JU11: =HW11+ID11+IK11+IR11+IY11+JF11+JM11 | JV11: =IFERROR(JU11/JT11/7,"") | JW11: =HX11+IE11+IL11+IS11+IZ11+JG11+JN11 | JX11: =IFERROR(JW11/JU11,"") | JY11: =IA11+IH11+IO11+IV11+JC11+JJ11+JQ11 | JZ11: =IFERROR(JU11/JT11/7,"") | LY11: 7 | LZ11: =KB11+KI11+KP11+KW11+LD11+LK11+LR11 | MA11: =IFERROR(LZ11/LY11/7,"") | MB11: =KC11+KJ11+KQ11+KX11+LE11+LL11+LS11 | MC11: =IFERROR(MB11/LZ11,"") | MD11: =KF11+KM11+KT11+LA11+LH11+LO11+LV11 | ME11: =IFERROR(LZ11/LY11/7,"") | OD11: 7 | OE11: =MG11+MN11+MU11+NB11+NI11+NP11+NW11 | OF11: =IFERROR(OE11/OD11/7,"") | OG11: =MH11+MO11+MV11+NC11+NJ11+NQ11+NX11 | OH11: =IFERROR(OG11/OE11,"") | OI11: =MK11+MR11+MY11+NF11+NM11+NT11+OA11 | OJ11: =IFERROR(OE11/OD11/7,"") | QI11: 7 | QJ11: =OL11+OS11+OZ11+PG11+PN11+PU11+QB11 | QK11: =IFERROR(QJ11/QI11/7,"") | QL11: =OM11+OT11+PA11+PH11+PO11+PV11+QC11 | QM11: =IFERROR(QL11/QJ11,"") | QN11: =OP11+OW11+PD11+PK11+PR11+PY11+QF11 | QO11: =IFERROR(QJ11/QI11/7,"") | SN11: 7 | SO11: =QQ11+QX11+RE11+RL11+RS11+RZ11+SG11 | SP11: =IFERROR(SO11/SN11/7,"") | SQ11: =QR11+QY11+RF11+RM11+RT11+SA11+SH11 | SR11: =IFERROR(SQ11/SO11,"") | SS11: =QU11+RB11+RI11+RP11+RW11+SD11+SK11 | ST11: =IFERROR(SO11/SN11/7,"") | US11: 7 | UT11: =SV11+TC11+TJ11+TQ11+TX11+UE11+UL11 | UU11: =IFERROR(UT11/US11/7,"") | UV11: =SW11+TD11+TK11+TR11+TY11+UF11+UM11 | UW11: =IFERROR(UV11/UT11,"") | UX11: =SZ11+TG11+TN11+TU11+UB11+UI11+UP11 | UY11: =IFERROR(UT11/US11/7,"") | WX11: 7 | WY11: =VA11+VH11+VO11+VV11+WC11+WJ11+WQ11 | WZ11: =IFERROR(WY11/WX11/7,"") | XA11: =VB11+VI11+VP11+VW11+WD11+WK11+WR11 | XB11: =IFERROR(XA11/WY11,"") | XC11: =VE11+VL11+VS11+VZ11+WG11+WN11+WU11 | XD11: =IFERROR(WY11/WX11/7,"") | ZC11: 7 | ZD11: =XF11+XM11+XT11+YA11+YH11+YO11+YV11 | ZE11: =IFERROR(ZD11/ZC11/7,"") | ZF11: =XG11+XN11+XU11+YB11+YI11+YP11+YW11 | ZG11: =IFERROR(ZF11/ZD11,"") | ZH11: =XJ11+XQ11+XX11+YE11+YL11+YS11+YZ11 | ZI11: =IFERROR(ZD11/ZC11/7,"") | ABH11: 7 | ABI11: =ZK11+ZR11+ZY11+AAF11+AAM11+AAT11+ABA11 | ABJ11: =IFERROR(ABI11/ABH11/7,"") | ABK11: =ZL11+ZS11+ZZ11+AAG11+AAN11+AAU11+ABB11 | ABL11: =IFERROR(ABK11/ABI11,"") | ABM11: =ZO11+ZV11+AAC11+AAJ11+AAQ11+AAX11+ABE11 | ABN11: =IFERROR(ABI11/ABH11/7,"") | ADM11: 7 | ADN11: =ABP11+ABW11+ACD11+ACK11+ACR11+ACY11+ADF11 | ADO11: =IFERROR(ADN11/ADM11/7,"") | ADP11: =ABQ11+ABX11+ACE11+ACL11+ACS11+ACZ11+ADG11 | ADQ11: =IFERROR(ADP11/ADN11,"") | ADR11: =ABT11+ACA11+ACH11+ACO11+ACV11+ADC11+ADJ11 | ADS11: =IFERROR(ADN11/ADM11/7,"") | AFR11: 7 | AFS11: =ADU11+AEB11+AEI11+AEP11+AEW11+AFD11+AFK11 | AFT11: =IFERROR(AFS11/AFR11/7,"") | AFU11: =ADV11+AEC11+AEJ11+AEQ11+AEX11+AFE11+AFL11 | AFV11: =IFERROR(AFU11/AFS11,"") | AFW11: =ADY11+AEF11+AEM11+AET11+AFA11+AFH11+AFO11 | AFX11: =IFERROR(AFS11/AFR11/7,"") | AHW11: 7 | AHX11: =AFZ11+AGG11+AGN11+AGU11+AHB11+AHI11+AHP11 | AHY11: =IFERROR(AHX11/AHW11/7,"") | AHZ11: =AGA11+AGH11+AGO11+AGV11+AHC11+AHJ11+AHQ11 | AIA11: =IFERROR(AHZ11/AHX11,"") | AIB11: =AGD11+AGK11+AGR11+AGY11+AHF11+AHM11+AHT11 | AIC11: =IFERROR(AHX11/AHW11/7,"") | AKB11: 7 | AKC11: =AIE11+AIL11+AIS11+AIZ11+AJG11+AJN11+AJU11 | AKD11: =IFERROR(AKC11/AKB11/7,"") | AKE11: =AIF11+AIM11+AIT11+AJA11+AJH11+AJO11+AJV11 | AKF11: =IFERROR(AKE11/AKC11,"") | AKG11: =AII11+AIP11+AIW11+AJD11+AJK11+AJR11+AJY11 | AKH11: =IFERROR(AKC11/AKB11/7,"") | AMG11: 7 | AMH11: =AKJ11+AKQ11+AKX11+ALE11+ALL11+ALS11+ALZ11 | AMI11: =IFERROR(AMH11/AMG11/7,"") | AMJ11: =AKK11+AKR11+AKY11+ALF11+ALM11+ALT11+AMA11 | AMK11: =IFERROR(AMJ11/AMH11,"") | AML11: =AKN11+AKU11+ALB11+ALI11+ALP11+ALW11+AMD11 | AMM11: =IFERROR(AMH11/AMG11/7,"") | AOL11: 7 | AOM11: =AMO11+AMV11+ANC11+ANJ11+ANQ11+ANX11+AOE11 | AON11: =IFERROR(AOM11/AOL11/7,"") | AOO11: =AMP11+AMW11+AND11+ANK11+ANR11+ANY11+AOF11 | AOP11: =IFERROR(AOO11/AOM11,"") | AOQ11: =AMS11+AMZ11+ANG11+ANN11+ANU11+AOB11+AOI11 | AOR11: =IFERROR(AOM11/AOL11/7,"") | AQQ11: 7 | AQR11: =AOT11+APA11+APH11+APO11+APV11+AQC11+AQJ11 | AQS11: =IFERROR(AQR11/AQQ11/7,"") | AQT11: =AOU11+APB11+API11+APP11+APW11+AQD11+AQK11 | AQU11: =IFERROR(AQT11/AQR11,"") | AQV11: =AOX11+APE11+APL11+APS11+APZ11+AQG11+AQN11 | AQW11: =IFERROR(AQR11/AQQ11/7,"")
